Workbook

Sheet Monthly Spending Template
A1: Income | I1: Total Income: | K1: =D13 -> 0
I2: Type of Split | K2: 50/30/20 | M2: <- (Select which)
I3: Needs | K3: =IF(K2="50/30/20",(K1*0.5), IF(K2="70/20/10",(K1*0.7))) -> 0
A4: Starbucks Pay | I4: Wants | K4: =IF(K2="50/30/20",(K1*0.3), IF(K2="70/20/10",(K1*0.2))) -> 0
A5: W1 | C5: 0 | I5: Savings | K5: =IF(K2="50/30/20",(K1*0.2), IF(K2="70/20/10",(K1*0.1))) -> 0
A6: W2 | C6: 0 | F6: NEEDS | J6: WANTS | N6: Savings/Investments
D7: =SUM(C5:C6) -> 0 | N7: 401K
A8: Rec. | F8: Dates | H8: $ | I8: Checklist | L8: Actual | N8: W1 | O8: 0
A9: W1 | C9: 0 | F9: 25st | G9: Rent | H9: 650 | I9: FALSE | J9: 2nd | K9: HBO Max | L9: 5.39 | M9: FALSE | N9: W2 | O9: 0 | R9: Total Overview
A10: W2 | C10: 0 | J10: 21st | K10: Gym | L10: 40.04 | M10: FALSE | P10: =SUM(O8,O9) -> 0
D11: =SUM(C9:C10) -> 0 | N11: Savings Acct
A12: Misc | C12: =B17 | D12: 0 | J12: 30th | K12: Apple Music | L12: 6.48 | M12: FALSE | N12: W1 | O12: 0 | R12: Needs Leftover
A13: Total: | D13: =SUM(D7,D11,D12,C12) -> 0 | N13: W2 | R13: Wants Leftover
F14: Groceries | H14: =S40 -> 0 | J14: Dinning Out | P14: =SUM(O12,O13) -> 0 | R14: Savings Leftovers | T14: =AG26
F15: Gas | H15: =Q40 -> 0 | J15: Haircut | L15: 0 | N15: Roth IRA | R15: Total: | T15: =SUM(T12,T13,T14) -> 0
B16: Checking acct | F16: Credit Payment | H16: 200 | J16: Other | L16: =R40 -> 0 | N16: W1 | O16: 0
A17: Leftover from Last Month | J17: Shopping | L17: =V40 -> 0 | N17: W2 | O17: 0
P18: =SUM(O16:O17) -> 0
F30: Budgeted Money | H30: =K3 -> 0 | J30: Budgeted Money | L30: =K4 -> 0
F31: Total | H31: =SUM(H14:I16)+(H9*I9) -> 200 | J31: Total | L31: =SUM(L14:M17)+((L9*M9)+(L10*M10)+(L11*M11)+(L12*M12)) -> 0
F32: Leftover | H32: =SUM(H30-H31) -> -200 | J32: Leftover | L32: =L30-L31 -> 0 | N32: Total: | P32: =SUM(P10,P14,P18) -> 0
E35: Monthly Transactions | P35: Monthly Total | U35: =SUM(I41:I86) -> 0
A36: Options
A37: Subscriptions
A38: Gas | P38: Subscriptions | Q38: Gas | R38: Other | S38: Groceries | T38: Dining out | U38: Rent | V38: Shopping
A39: Other | E39: Date | G39: Category | I39: Amount | J39: Notes
A40: Groceries | P40: =SUMIF(G41:H87,"Subscriptions",I41:I87) -> 0 | Q40: =SUMIF(G41:H87,"Gas",I41:I87) -> 0 | R40: =SUMIF(G41:H87,"Other",I41:I87) -> 0 | S40: =SUMIF(G41:H87,"Groceries",I41:I87) -> 0 | T40: =SUMIF(G41:H87,"Dining Out",I41:I87) -> 0 | U40: =SUMIF(G41:H87,"Rent",I41:I87) -> 0 | V40: =SUMIF(G41:H87,"Shopping",I41:I87) -> 0
A41: Dining out
A42: Rent | P42: =SUM((L9*M9)+(L10*M10)+(L11*M11)+(L12*M12)) -> 0
A43: Shopping
Q46: School Refund
P47: Extra:
P48: Payment

Sheet Yearly Overview
C2: Yearly Budget Planner
E5: Jan. | F5: Feb. | G5: Mar | H5: Apr | I5: May | J5: Jun | K5: Jul | L5: Aug | M5: Sept | N5: Oct | O5: Nov | P5: Dec
C7: Total Expenses | E7: =Jan!U35 -> 0 | F7: =Feb!U35 -> 0 | G7: =Mar!U35 -> 0 | H7: =Apr!U35 -> 0 | I7: =May!U35 -> 0 | J7: =Jun!U35 -> 0 | K7: =Jul!U35 -> 0 | L7: =Aug!U35 -> 1731.88 | M7: =Sep!U35 -> 163.15 | N7: =Oct!U35 -> 0 | O7: =Nov!U35 -> 0 | P7: =Dec!U35 -> 0
C8: Cash (Short/Extra) | E8: =Jan!T15 -> 0 | F8: =Feb!T15 -> 0 | G8: =Mar!T15 -> 0 | H8: =Apr!T15 -> 0 | I8: =May!T15 -> 0 | J8: =Jun!T15 -> 0 | K8: =Jul!T15 -> 0 | L8: =Aug!C21 -> 869.196 | M8: =Sep!T15 -> 0 | N8: =Oct!T15 -> 0 | O8: =Nov!T15 -> 0 | P8: =Dec!T15 -> 0

Sheet Jan
A1: Income | I1: Total Income: | K1: =D13 -> 0
I2: Type of Split | K2: 50/30/20 | M2: <- (Select which)
I3: Needs | K3: =IF(K2="50/30/20",(K1*0.5), IF(K2="70/20/10",(K1*0.7))) -> 0
A4: Starbucks Pay | I4: Wants | K4: =IF(K2="50/30/20",(K1*0.3), IF(K2="70/20/10",(K1*0.2))) -> 0
A5: W1 | C5: 0 | I5: Savings | K5: =IF(K2="50/30/20",(K1*0.2), IF(K2="70/20/10",(K1*0.1))) -> 0
A6: W2 | C6: 0 | F6: NEEDS | J6: WANTS | N6: Savings/Investments
D7: =SUM(C5:C6) -> 0 | N7: 401K
A8: Rec. | F8: Dates | H8: $ | I8: Checklist | L8: Actual | N8: W1 | O8: 0
A9: W1 | C9: 0 | F9: 25st | G9: Rent | H9: 650 | I9: FALSE | J9: 2nd | K9: HBO Max | L9: 5.39 | M9: FALSE | N9: W2 | O9: 0 | R9: Total Overview
A10: W2 | C10: 0 | J10: 21st | K10: Gym | L10: 40.04 | M10: FALSE | P10: =SUM(O8,O9) -> 0
D11: =SUM(C9:C10) -> 0 | N11: Savings Acct
A12: Misc | C12: =B17 | D12: 0 | J12: 30th | K12: Apple Music | L12: 6.48 | M12: FALSE | N12: W1 | O12: 0 | R12: Needs Leftover
A13: Total: | D13: =SUM(D7,D11,D12,C12) -> 0 | N13: W2 | R13: Wants Leftover
F14: Groceries | H14: =S40 -> 0 | J14: Dinning Out | P14: =SUM(O12,O13) -> 0 | R14: Savings Leftovers | T14: =AG26
F15: Gas | H15: =Q40 -> 0 | J15: Haircut | L15: 0 | N15: Roth IRA | R15: Total: | T15: =SUM(T12,T13,T14) -> 0
B16: Checking acct | F16: Credit Payment | H16: 200 | J16: Other | L16: =R40 -> 0 | N16: W1 | O16: 0
A17: Leftover from Last Month | J17: Shopping | L17: =V40 -> 0 | N17: W2 | O17: 0
P18: =SUM(O16:O17) -> 0
F30: Budgeted Money | H30: =K3 -> 0 | J30: Budgeted Money | L30: =K4 -> 0
F31: Total | H31: =SUM(H14:I16)+(H9*I9) -> 200 | J31: Total | L31: =SUM(L14:M17)+((L9*M9)+(L10*M10)+(L11*M11)+(L12*M12)) -> 0
F32: Leftover | H32: =SUM(H30-H31) -> -200 | J32: Leftover | L32: =L30-L31 -> 0 | N32: Total: | P32: =SUM(P10,P14,P18) -> 0
E35: Monthly Transactions | P35: Monthly Total | U35: =SUM(I41:I86) -> 0
A36: Options
A37: Subscriptions
A38: Gas | P38: Subscriptions | Q38: Gas | R38: Other | S38: Groceries | T38: Dining out | U38: Rent | V38: Shopping
A39: Other | E39: Date | G39: Category | I39: Amount | J39: Notes
A40: Groceries | P40: =SUMIF(G41:H87,"Subscriptions",I41:I87) -> 0 | Q40: =SUMIF(G41:H87,"Gas",I41:I87) -> 0 | R40: =SUMIF(G41:H87,"Other",I41:I87) -> 0 | S40: =SUMIF(G41:H87,"Groceries",I41:I87) -> 0 | T40: =SUMIF(G41:H87,"Dining Out",I41:I87) -> 0 | U40: =SUMIF(G41:H87,"Rent",I41:I87) -> 0 | V40: =SUMIF(G41:H87,"Shopping",I41:I87) -> 0
A41: Dining out
A42: Rent | P42: =SUM((L9*M9)+(L10*M10)+(L11*M11)+(L12*M12)) -> 0
A43: Shopping
Q46: School Refund
P47: Extra:
P48: Payment

Sheet Feb
A1: Income | I1: Total Income: | K1: =D13 -> 0
I2: Type of Split | K2: 50/30/20 | M2: <- (Select which)
I3: Needs | K3: =IF(K2="50/30/20",(K1*0.5), IF(K2="70/20/10",(K1*0.7))) -> 0
A4: Starbucks Pay | I4: Wants | K4: =IF(K2="50/30/20",(K1*0.3), IF(K2="70/20/10",(K1*0.2))) -> 0
A5: W1 | C5: 0 | I5: Savings | K5: =IF(K2="50/30/20",(K1*0.2), IF(K2="70/20/10",(K1*0.1))) -> 0
A6: W2 | C6: 0 | F6: NEEDS | J6: WANTS | N6: Savings/Investments
D7: =SUM(C5:C6) -> 0 | N7: 401K
A8: Rec. | F8: Dates | H8: $ | I8: Checklist | L8: Actual | N8: W1 | O8: 0
A9: W1 | C9: 0 | F9: 25st | G9: Rent | H9: 650 | I9: FALSE | J9: 2nd | K9: HBO Max | L9: 5.39 | M9: FALSE | N9: W2 | O9: 0 | R9: Total Overview
A10: W2 | C10: 0 | J10: 21st | K10: Gym | L10: 40.04 | M10: FALSE | P10: =SUM(O8,O9) -> 0
D11: =SUM(C9:C10) -> 0 | N11: Savings Acct
A12: Misc | C12: =B16 | D12: 0 | J12: 30th | K12: Apple Music | L12: 6.48 | M12: FALSE | N12: W1 | O12: 0 | R12: Needs Leftover
A13: Total: | D13: =SUM(D7,D11,D12,C12) -> 0 | N13: W2 | R13: Wants Leftover
F14: Groceries | H14: =S40 -> 0 | J14: Dinning Out | P14: =SUM(O12,O13) -> 0 | R14: Savings Leftovers | T14: =AG26
B15: Checking Acct | F15: Gas | H15: =Q40 -> 0 | J15: Haircut | L15: 0 | N15: Roth IRA | R15: Total: | T15: =SUM(T12,T13,T14) -> 0
A16: Leftover from Last Month | F16: Credit Payment | H16: 200 | J16: Other | L16: =R40 -> 0 | N16: W1 | O16: 0
J17: Shopping | L17: =V40 -> 0 | N17: W2 | O17: 0
P18: =SUM(O16:O17) -> 0
F30: Budgeted Money | H30: =K3 -> 0 | J30: Budgeted Money | L30: =K4 -> 0
F31: Total | H31: =SUM(H14:I16)+(H9*I9) -> 200 | J31: Total | L31: =SUM(L14:M17)+((L9*M9)+(L10*M10)+(L11*M11)+(L12*M12)) -> 0
F32: Leftover | H32: =SUM(H30-H31) -> -200 | J32: Leftover | L32: =L30-L31 -> 0 | N32: Total: | P32: =SUM(P10,P14,P18) -> 0
E35: Monthly Transactions | P35: Monthly Total | U35: =SUM(I41:I86) -> 0
A36: Options
A37: Subscriptions
A38: Gas | P38: Subscriptions | Q38: Gas | R38: Other | S38: Groceries | T38: Dining out | U38: Rent | V38: Shopping
A39: Other | E39: Date | G39: Category | I39: Amount | J39: Notes
A40: Groceries | P40: =SUMIF(G41:H87,"Subscriptions",I41:I87) -> 0 | Q40: =SUMIF(G41:H87,"Gas",I41:I87) -> 0 | R40: =SUMIF(G41:H87,"Other",I41:I87) -> 0 | S40: =SUMIF(G41:H87,"Groceries",I41:I87) -> 0 | T40: =SUMIF(G41:H87,"Dining Out",I41:I87) -> 0 | U40: =SUMIF(G41:H87,"Rent",I41:I87) -> 0 | V40: =SUMIF(G41:H87,"Shopping",I41:I87) -> 0
A41: Dining out
A42: Rent | P42: =SUM((L9*M9)+(L10*M10)+(L11*M11)+(L12*M12)) -> 0
A43: Shopping
Q46: School Refund
P47: Extra:
P48: Payment

Sheet Mar
A1: Income | I1: Total Income: | K1: =D13 -> 0
I2: Type of Split | K2: 50/30/20 | M2: <- (Select which)
I3: Needs | K3: =IF(K2="50/30/20",(K1*0.5), IF(K2="70/20/10",(K1*0.7))) -> 0
A4: Starbucks Pay | I4: Wants | K4: =IF(K2="50/30/20",(K1*0.3), IF(K2="70/20/10",(K1*0.2))) -> 0
A5: W1 | C5: 0 | I5: Savings | K5: =IF(K2="50/30/20",(K1*0.2), IF(K2="70/20/10",(K1*0.1))) -> 0
A6: W2 | C6: 0 | F6: NEEDS | J6: WANTS | N6: Savings/Investments
D7: =SUM(C5:C6) -> 0 | N7: 401K
A8: Rec. | F8: Dates | H8: $ | I8: Checklist | L8: Actual | N8: W1 | O8: 0
A9: W1 | C9: 0 | F9: 25st | G9: Rent | H9: 650 | I9: FALSE | J9: 2nd | K9: HBO Max | L9: 5.39 | M9: FALSE | N9: W2 | O9: 0 | R9: Total Overview
A10: W2 | C10: 0 | J10: 21st | K10: Gym | L10: 40.04 | M10: FALSE | P10: =SUM(O8,O9) -> 0
D11: =SUM(C9:C10) -> 0 | N11: Savings Acct
A12: Misc | C12: =B18 | D12: 0 | J12: 30th | K12: Apple Music | L12: 6.48 | M12: FALSE | N12: W1 | O12: 0 | R12: Needs Leftover
A13: Total: | D13: =SUM(D7,D11,D12,C12) -> 0 | N13: W2 | R13: Wants Leftover
F14: Groceries | H14: =S40 -> 0 | J14: Dinning Out | P14: =SUM(O12,O13) -> 0 | R14: Savings Leftovers | T14: =AG26
F15: Gas | H15: =Q40 -> 0 | J15: Haircut | L15: 0 | N15: Roth IRA | R15: Total: | T15: =SUM(T12,T13,T14) -> 0
F16: Credit Payment | H16: 200 | J16: Other | L16: =R40 -> 0 | N16: W1 | O16: 0
B17: Checking Acct | J17: Shopping | L17: =V40 -> 0 | N17: W2 | O17: 0
A18: Leftover from Last Month | P18: =SUM(O16:O17) -> 0
F30: Budgeted Money | H30: =K3 -> 0 | J30: Budgeted Money | L30: =K4 -> 0
F31: Total | H31: =SUM(H14:I16)+(H9*I9) -> 200 | J31: Total | L31: =SUM(L14:M17)+((L9*M9)+(L10*M10)+(L11*M11)+(L12*M12)) -> 0
F32: Leftover | H32: =SUM(H30-H31) -> -200 | J32: Leftover | L32: =L30-L31 -> 0 | N32: Total: | P32: =SUM(P10,P14,P18) -> 0
E35: Monthly Transactions | P35: Monthly Total | U35: =SUM(I41:I86) -> 0
A36: Options
A37: Subscriptions
A38: Gas | P38: Subscriptions | Q38: Gas | R38: Other | S38: Groceries | T38: Dining out | U38: Rent | V38: Shopping
A39: Other | E39: Date | G39: Category | I39: Amount | J39: Notes
A40: Groceries | P40: =SUMIF(G41:H87,"Subscriptions",I41:I87) -> 0 | Q40: =SUMIF(G41:H87,"Gas",I41:I87) -> 0 | R40: =SUMIF(G41:H87,"Other",I41:I87) -> 0 | S40: =SUMIF(G41:H87,"Groceries",I41:I87) -> 0 | T40: =SUMIF(G41:H87,"Dining Out",I41:I87) -> 0 | U40: =SUMIF(G41:H87,"Rent",I41:I87) -> 0 | V40: =SUMIF(G41:H87,"Shopping",I41:I87) -> 0
A41: Dining out
A42: Rent | P42: =SUM((L9*M9)+(L10*M10)+(L11*M11)+(L12*M12)) -> 0
A43: Shopping
Q46: School Refund
P47: Extra:
P48: Payment

Sheet Apr
A1: Income | I1: Total Income: | K1: =D13 -> 0
I2: Type of Split | K2: 50/30/20 | M2: <- (Select which)
I3: Needs | K3: =IF(K2="50/30/20",(K1*0.5), IF(K2="70/20/10",(K1*0.7))) -> 0
A4: Starbucks Pay | I4: Wants | K4: =IF(K2="50/30/20",(K1*0.3), IF(K2="70/20/10",(K1*0.2))) -> 0
A5: W1 | C5: 0 | I5: Savings | K5: =IF(K2="50/30/20",(K1*0.2), IF(K2="70/20/10",(K1*0.1))) -> 0
A6: W2 | C6: 0 | F6: NEEDS | J6: WANTS | N6: Savings/Investments
D7: =SUM(C5:C6) -> 0 | N7: 401K
A8: Rec. | F8: Dates | H8: $ | I8: Checklist | L8: Actual | N8: W1 | O8: 0
A9: W1 | C9: 0 | F9: 25st | G9: Rent | H9: 650 | I9: FALSE | J9: 2nd | K9: HBO Max | L9: 5.39 | M9: FALSE | N9: W2 | O9: 0 | R9: Total Overview
A10: W2 | C10: 0 | J10: 21st | K10: Gym | L10: 40.04 | M10: FALSE | P10: =SUM(O8,O9) -> 0
D11: =SUM(C9:C10) -> 0 | N11: Savings Acct
A12: Misc | C12: =B18 | D12: 0 | J12: 30th | K12: Apple Music | L12: 6.48 | M12: FALSE | N12: W1 | O12: 0 | R12: Needs Leftover
A13: Total: | D13: =SUM(D7,D11,D12,C12) -> 0 | N13: W2 | R13: Wants Leftover
F14: Groceries | H14: =S40 -> 0 | J14: Dinning Out | P14: =SUM(O12,O13) -> 0 | R14: Savings Leftovers | T14: =AG26
F15: Gas | H15: =Q40 -> 0 | J15: Haircut | L15: 0 | N15: Roth IRA | R15: Total: | T15: =SUM(T12,T13,T14) -> 0
F16: Credit Payment | H16: 200 | J16: Other | L16: =R40 -> 0 | N16: W1 | O16: 0
B17: Checking Acct | J17: Shopping | L17: =V40 -> 0 | N17: W2 | O17: 0
A18: Leftover from Last Month | P18: =SUM(O16:O17) -> 0
F30: Budgeted Money | H30: =K3 -> 0 | J30: Budgeted Money | L30: =K4 -> 0
F31: Total | H31: =SUM(H14:I16)+(H9*I9) -> 200 | J31: Total | L31: =SUM(L14:M17)+((L9*M9)+(L10*M10)+(L11*M11)+(L12*M12)) -> 0
F32: Leftover | H32: =SUM(H30-H31) -> -200 | J32: Leftover | L32: =L30-L31 -> 0 | N32: Total: | P32: =SUM(P10,P14,P18) -> 0
E35: Monthly Transactions | P35: Monthly Total | U35: =SUM(I41:I86) -> 0
A36: Options
A37: Subscriptions
A38: Gas | P38: Subscriptions | Q38: Gas | R38: Other | S38: Groceries | T38: Dining out | U38: Rent | V38: Shopping
A39: Other | E39: Date | G39: Category | I39: Amount | J39: Notes
A40: Groceries | P40: =SUMIF(G41:H87,"Subscriptions",I41:I87) -> 0 | Q40: =SUMIF(G41:H87,"Gas",I41:I87) -> 0 | R40: =SUMIF(G41:H87,"Other",I41:I87) -> 0 | S40: =SUMIF(G41:H87,"Groceries",I41:I87) -> 0 | T40: =SUMIF(G41:H87,"Dining Out",I41:I87) -> 0 | U40: =SUMIF(G41:H87,"Rent",I41:I87) -> 0 | V40: =SUMIF(G41:H87,"Shopping",I41:I87) -> 0
A41: Dining out
A42: Rent | P42: =SUM((L9*M9)+(L10*M10)+(L11*M11)+(L12*M12)) -> 0
A43: Shopping
Q46: School Refund
P47: Extra:
P48: Payment

Sheet May
A1: Income | I1: Total Income: | K1: =D13 -> 0
I2: Type of Split | K2: 50/30/20 | M2: <- (Select which)
I3: Needs | K3: =IF(K2="50/30/20",(K1*0.5), IF(K2="70/20/10",(K1*0.7))) -> 0
A4: Starbucks Pay | I4: Wants | K4: =IF(K2="50/30/20",(K1*0.3), IF(K2="70/20/10",(K1*0.2))) -> 0
A5: W1 | C5: 0 | I5: Savings | K5: =IF(K2="50/30/20",(K1*0.2), IF(K2="70/20/10",(K1*0.1))) -> 0
A6: W2 | C6: 0 | F6: NEEDS | J6: WANTS | N6: Savings/Investments
D7: =SUM(C5:C6) -> 0 | N7: 401K
A8: Rec. | F8: Dates | H8: $ | I8: Checklist | L8: Actual | N8: W1 | O8: 0
A9: W1 | C9: 0 | F9: 25st | G9: Rent | H9: 650 | I9: FALSE | J9: 2nd | K9: HBO Max | L9: 5.39 | M9: FALSE | N9: W2 | O9: 0 | R9: Total Overview
A10: W2 | C10: 0 | J10: 21st | K10: Gym | L10: 40.04 | M10: FALSE | P10: =SUM(O8,O9) -> 0
D11: =SUM(C9:C10) -> 0 | N11: Savings Acct
A12: Misc | D12: 0 | J12: 30th | K12: Apple Music | L12: 6.48 | M12: FALSE | N12: W1 | O12: 0 | R12: Needs Leftover
A13: Total: | D13: =SUM(D7,D11,D12,C12) -> 0 | N13: W2 | R13: Wants Leftover
F14: Groceries | H14: =S40 -> 0 | J14: Dinning Out | P14: =SUM(O12,O13) -> 0 | R14: Savings Leftovers | T14: =AG26
F15: Gas | H15: =Q40 -> 0 | J15: Haircut | L15: 0 | N15: Roth IRA | R15: Total: | T15: =SUM(T12,T13,T14) -> 0
F16: Credit Payment | H16: 200 | J16: Other | L16: =R40 -> 0 | N16: W1 | O16: 0
B17: Checking Acct | J17: Shopping | L17: =V40 -> 0 | N17: W2 | O17: 0
A18: Leftover from Last Month | B18: =C12 | P18: =SUM(O16:O17) -> 0
F30: Budgeted Money | H30: =K3 -> 0 | J30: Budgeted Money | L30: =K4 -> 0
F31: Total | H31: =SUM(H14:I16)+(H9*I9) -> 200 | J31: Total | L31: =SUM(L14:M17)+((L9*M9)+(L10*M10)+(L11*M11)+(L12*M12)) -> 0
F32: Leftover | H32: =SUM(H30-H31) -> -200 | J32: Leftover | L32: =L30-L31 -> 0 | N32: Total: | P32: =SUM(P10,P14,P18) -> 0
E35: Monthly Transactions | P35: Monthly Total | U35: =SUM(I41:I86) -> 0
A36: Options
A37: Subscriptions
A38: Gas | P38: Subscriptions | Q38: Gas | R38: Other | S38: Groceries | T38: Dining out | U38: Rent | V38: Shopping
A39: Other | E39: Date | G39: Category | I39: Amount | J39: Notes
A40: Groceries | P40: =SUMIF(G41:H87,"Subscriptions",I41:I87) -> 0 | Q40: =SUMIF(G41:H87,"Gas",I41:I87) -> 0 | R40: =SUMIF(G41:H87,"Other",I41:I87) -> 0 | S40: =SUMIF(G41:H87,"Groceries",I41:I87) -> 0 | T40: =SUMIF(G41:H87,"Dining Out",I41:I87) -> 0 | U40: =SUMIF(G41:H87,"Rent",I41:I87) -> 0 | V40: =SUMIF(G41:H87,"Shopping",I41:I87) -> 0
A41: Dining out
A42: Rent | P42: =SUM((L9*M9)+(L10*M10)+(L11*M11)+(L12*M12)) -> 0
A43: Shopping
Q46: School Refund
P47: Extra:
P48: Payment

Sheet Jun
A1: Income | I1: Total Income: | K1: =D13 -> 0
I2: Type of Split | K2: 50/30/20 | M2: <- (Select which)
I3: Needs | K3: =IF(K2="50/30/20",(K1*0.5), IF(K2="70/20/10",(K1*0.7))) -> 0
A4: Starbucks Pay | I4: Wants | K4: =IF(K2="50/30/20",(K1*0.3), IF(K2="70/20/10",(K1*0.2))) -> 0
A5: W1 | C5: 0 | I5: Savings | K5: =IF(K2="50/30/20",(K1*0.2), IF(K2="70/20/10",(K1*0.1))) -> 0
A6: W2 | C6: 0 | F6: NEEDS | J6: WANTS | N6: Savings/Investments
D7: =SUM(C5:C6) -> 0 | N7: 401K
A8: Rec. | F8: Dates | H8: $ | I8: Checklist | L8: Actual | N8: W1 | O8: 0
A9: W1 | C9: 0 | F9: 25st | G9: Rent | H9: 650 | I9: FALSE | J9: 2nd | K9: HBO Max | L9: 5.39 | M9: FALSE | N9: W2 | O9: 0 | R9: Total Overview
A10: W2 | C10: 0 | J10: 21st | K10: Gym | L10: 40.04 | M10: FALSE | P10: =SUM(O8,O9) -> 0
D11: =SUM(C9:C10) -> 0 | N11: Savings Acct
A12: Misc | C12: =B20 | D12: 0 | J12: 30th | K12: Apple Music | L12: 6.48 | M12: FALSE | N12: W1 | O12: 0 | R12: Needs Leftover
A13: Total: | D13: =SUM(D7,D11,D12,C12) -> 0 | N13: W2 | R13: Wants Leftover
F14: Groceries | H14: =S40 -> 0 | J14: Dinning Out | P14: =SUM(O12,O13) -> 0 | R14: Savings Leftovers | T14: =AG26
F15: Gas | H15: =Q40 -> 0 | J15: Haircut | L15: 0 | N15: Roth IRA | R15: Total: | T15: =SUM(T12,T13,T14) -> 0
F16: Credit Payment | H16: 200 | J16: Other | L16: =R40 -> 0 | N16: W1 | O16: 0
J17: Shopping | L17: =V40 -> 0 | N17: W2 | O17: 0
P18: =SUM(O16:O17) -> 0
B19: Checking Acct
A20: Leftover from Last Month
F30: Budgeted Money | H30: =K3 -> 0 | J30: Budgeted Money | L30: =K4 -> 0
F31: Total | H31: =SUM(H14:I16)+(H9*I9) -> 200 | J31: Total | L31: =SUM(L14:M17)+((L9*M9)+(L10*M10)+(L11*M11)+(L12*M12)) -> 0
F32: Leftover | H32: =SUM(H30-H31) -> -200 | J32: Leftover | L32: =L30-L31 -> 0 | N32: Total: | P32: =SUM(P10,P14,P18) -> 0
E35: Monthly Transactions | P35: Monthly Total | U35: =SUM(I41:I86) -> 0
A36: Options
A37: Subscriptions
A38: Gas | P38: Subscriptions | Q38: Gas | R38: Other | S38: Groceries | T38: Dining out | U38: Rent | V38: Shopping
A39: Other | E39: Date | G39: Category | I39: Amount | J39: Notes
A40: Groceries | P40: =SUMIF(G41:H87,"Subscriptions",I41:I87) -> 0 | Q40: =SUMIF(G41:H87,"Gas",I41:I87) -> 0 | R40: =SUMIF(G41:H87,"Other",I41:I87) -> 0 | S40: =SUMIF(G41:H87,"Groceries",I41:I87) -> 0 | T40: =SUMIF(G41:H87,"Dining Out",I41:I87) -> 0 | U40: =SUMIF(G41:H87,"Rent",I41:I87) -> 0 | V40: =SUMIF(G41:H87,"Shopping",I41:I87) -> 0
A41: Dining out
A42: Rent | P42: =SUM((L9*M9)+(L10*M10)+(L11*M11)+(L12*M12)) -> 0
A43: Shopping
Q46: School Refund
P47: Extra:
P48: Payment

Sheet Jul
A1: Income | I1: Total Income: | K1: =D13 -> 0
I2: Type of Split | K2: 50/30/20 | M2: <- (Select which)
I3: Needs | K3: =IF(K2="50/30/20",(K1*0.5), IF(K2="70/20/10",(K1*0.7))) -> 0
A4: Starbucks Pay | I4: Wants | K4: =IF(K2="50/30/20",(K1*0.3), IF(K2="70/20/10",(K1*0.2))) -> 0
A5: W1 | C5: 0 | I5: Savings | K5: =IF(K2="50/30/20",(K1*0.2), IF(K2="70/20/10",(K1*0.1))) -> 0
A6: W2 | C6: 0 | F6: NEEDS | J6: WANTS | N6: Savings/Investments
D7: =SUM(C5:C6) -> 0 | N7: 401K
A8: Rec. | F8: Dates | H8: $ | I8: Checklist | L8: Actual | N8: W1 | O8: 0
A9: W1 | C9: 0 | F9: 25st | G9: Rent | H9: 650 | I9: FALSE | J9: 2nd | K9: HBO Max | L9: 5.39 | M9: FALSE | N9: W2 | O9: 0 | R9: Total Overview
A10: W2 | C10: 0 | J10: 21st | K10: Gym | L10: 40.04 | M10: FALSE | P10: =SUM(O8,O9) -> 0
D11: =SUM(C9:C10) -> 0 | N11: Savings Acct
A12: Misc | C12: =B18 | D12: 0 | J12: 30th | K12: Apple Music | L12: 6.48 | M12: FALSE | N12: W1 | O12: 0 | R12: Needs Leftover
A13: Total: | D13: =SUM(D7,D11,D12,C12) -> 0 | N13: W2 | R13: Wants Leftover
F14: Groceries | H14: =S40 -> 0 | J14: Dinning Out | P14: =SUM(O12,O13) -> 0 | R14: Savings Leftovers | T14: =AG26
F15: Gas | H15: =Q40 -> 0 | J15: Haircut | L15: 0 | N15: Roth IRA | R15: Total: | T15: =SUM(T12,T13,T14) -> 0
F16: Credit Payment | H16: 200 | J16: Other | L16: =R40 -> 0 | N16: W1 | O16: 0
B17: Checking Acct | J17: Shopping | L17: =V40 -> 0 | N17: W2 | O17: 0
A18: Leftover from Last Month | P18: =SUM(O16:O17) -> 0
F30: Budgeted Money | H30: =K3 -> 0 | J30: Budgeted Money | L30: =K4 -> 0
F31: Total | H31: =SUM(H14:I16)+(H9*I9) -> 200 | J31: Total | L31: =SUM(L14:M17)+((L9*M9)+(L10*M10)+(L11*M11)+(L12*M12)) -> 0
F32: Leftover | H32: =SUM(H30-H31) -> -200 | J32: Leftover | L32: =L30-L31 -> 0 | N32: Total: | P32: =SUM(P10,P14,P18) -> 0
E35: Monthly Transactions | P35: Monthly Total | U35: =SUM(I41:I86) -> 0
A36: Options
A37: Subscriptions
A38: Gas | P38: Subscriptions | Q38: Gas | R38: Other | S38: Groceries | T38: Dining out | U38: Rent | V38: Shopping
A39: Other | E39: Date | G39: Category | I39: Amount | J39: Notes
A40: Groceries | P40: =SUMIF(G41:H87,"Subscriptions",I41:I87) -> 0 | Q40: =SUMIF(G41:H87,"Gas",I41:I87) -> 0 | R40: =SUMIF(G41:H87,"Other",I41:I87) -> 0 | S40: =SUMIF(G41:H87,"Groceries",I41:I87) -> 0 | T40: =SUMIF(G41:H87,"Dining Out",I41:I87) -> 0 | U40: =SUMIF(G41:H87,"Rent",I41:I87) -> 0 | V40: =SUMIF(G41:H87,"Shopping",I41:I87) -> 0
A41: Dining out
A42: Rent | P42: =SUM((L9*M9)+(L10*M10)+(L11*M11)+(L12*M12)) -> 0
A43: Shopping
Q46: School Refund
P47: Extra:
P48: Payment

Sheet Aug
A1: Income | I1: Total Income: | K1: =D13 -> 2654.27
I2: Type of Split | K2: 50/30/20 | M2: <- (Select which)
I3: Needs | K3: =IF(K2="50/30/20",(K1*0.5), IF(K2="70/20/10",(K1*0.7))) -> 1327.135
A4: Starbucks Pay | I4: Wants | K4: =IF(K2="50/30/20",(K1*0.3), IF(K2="70/20/10",(K1*0.2))) -> 796.281
A5: W1 | C5: 1243.06 | I5: Savings | K5: =IF(K2="50/30/20",(K1*0.2), IF(K2="70/20/10",(K1*0.1))) -> 530.854
A6: W2 | C6: 1276.72 | F6: NEEDS | J6: WANTS | N6: Savings/Investments
D7: =SUM(C5:C6) -> 2519.78 | N7: 401K
A8: Rec. | F8: Dates | H8: $ | I8: Checklist | L8: Actual | N8: W1 | O8: 0
A9: W1 | C9: 66.49 | F9: 25st | G9: Rent | H9: 650 | I9: TRUE | J9: 2nd | K9: HBO Max | L9: 5.39 | M9: TRUE | N9: W2 | O9: 150
A10: W2 | C10: 0 | J10: 21st | K10: Gym | L10: 40.04 | M10: TRUE | P10: =SUM(O8,O9) -> 150
D11: =SUM(C9:C10) -> 66.49 | N11: Savings Acct
A12: Misc | C12: =B26 | D12: =26+26+16 -> 68 | J12: 30th | K12: Apple Music | L12: 6.48 | M12: TRUE | N12: W1 | O12: 0
A13: Total: | D13: =SUM(D7,D11,D12,C12) -> 2654.27 | N13: W2 | O13: 527.65
F14: Groceries | H14: =S40 -> 70 | J14: Dinning Out | L14: =T40 -> 168.91 | P14: =SUM(O12,O13) -> 527.65
A15: Total Overview | F15: Gas | H15: =Q40 -> 61.61 | J15: Haircut | L15: 0 | N15: Roth IRA
F16: Credit Payment | H16: 200 | J16: Other | L16: =R40 -> 482.41 | N16: W1 | O16: 0
J17: Shopping | L17: =V40 -> 247.03 | N17: W2 | O17: 0
A18: Needs Leftover | C18: =H32 -> 345.525 | P18: =SUM(O16:O17) -> 0
A19: Wants Leftover | C19: =L32 -> -153.979
A20: Savings Leftovers | C20: =P32 -> 677.65
A21: Total: | C21: =SUM(C18,C19,C20) -> 869.196
B25: Checking Acct
A26: Leftover from Last Month
F30: Budgeted Money | H30: =K3 -> 1327.135 | J30: Budgeted Money | L30: =K4 -> 796.281
F31: Total | H31: =SUM(H14:I16)+(H9*I9) -> 981.61 | J31: Total | L31: =SUM(L14:M17)+((L9*M9)+(L10*M10)+(L11*M11)+(L12*M12)) -> 950.26
F32: Leftover | H32: =SUM(H30-H31) -> 345.525 | J32: Leftover | L32: =L30-L31 -> -153.979 | N32: Total: | P32: =SUM(P10,P14,P18) -> 677.65
E35: Monthly Transactions | P35: Monthly Total | U35: =SUM(I41:I86) -> 1731.88
A36: Options
A37: Subscriptions
A38: Gas | P38: Subscriptions | Q38: Gas | R38: Other | S38: Groceries | T38: Dining out | U38: Rent | V38: Shopping
A39: Other | E39: Date | G39: Category | I39: Amount | J39: Notes
A40: Groceries | P40: =SUMIF(G41:H87,"Subscriptions",I41:I87) -> 51.92 | Q40: =SUMIF(G41:H87,"Gas",I41:I87) -> 61.61 | R40: =SUMIF(G41:H87,"Other",I41:I87) -> 482.41 | S40: =SUMIF(G41:H87,"Groceries",I41:I87) -> 70 | T40: =SUMIF(G41:H87,"Dining Out",I41:I87) -> 168.91 | U40: =SUMIF(G41:H87,"Rent",I41:I87) -> 650 | V40: =SUMIF(G41:H87,"Shopping",I41:I87) -> 247.03
A41: Dining out | E41: 45870 | G41: Subscriptions | I41: 6.48 | J41: Apple Music
A42: Rent | E42: 45871 | G42: Other | I42: 4.95 | P42: =SUM((L9*M9)+(L10*M10)+(L11*M11)+(L12*M12)) -> 51.91
A43: Shopping | E43: 45872 | G43: Dining out | I43: 5.11
E44: 45875 | G44: Gas | I44: 21.36
E45: 45876 | G45: Shopping | I45: 103.92 | J45: Lululemon for Jackie
E46: 45876 | G46: Dining out | I46: 13.63 | J46: Japanese Food | Q46: School Refund
E47: 45877 | G47: Subscriptions | I47: 40.04 | J47: Gym (need to downgrade) | P47: Extra: | Q47: 2143.11 | S47: Leftover | T47: =Q47-(Q48+Q49) -> 1721.65
E48: 45877 | G48: Other | I48: 5.39 | P48: Payment | Q48: 354.36
...

Sheet Sep
A1: Income | I1: Total Income: | K1: =D13 -> 2197.536
I2: Type of Split | K2: 50/30/20 | M2: <- (Select which)
I3: Needs | K3: =IF(K2="50/30/20",(K1*0.5), IF(K2="70/20/10",(K1*0.7))) -> 1098.768
A4: Starbucks Pay | I4: Wants | K4: =IF(K2="50/30/20",(K1*0.3), IF(K2="70/20/10",(K1*0.2))) -> 659.2608
A5: W1 | C5: 1193.34 | I5: Savings | K5: =IF(K2="50/30/20",(K1*0.2), IF(K2="70/20/10",(K1*0.1))) -> 439.5072
A6: W2 | C6: 0 | F6: NEEDS | J6: WANTS | N6: Savings/Investments
D7: =SUM(C5:C6) -> 1193.34
A8: Rec. | F8: Dates | H8: $ | I8: Checklist | L8: Actual | N8: 401K
A9: W1 | C9: 135 | F9: 25st | G9: Rent | H9: 650 | I9: FALSE | J9: 2nd | K9: HBO Max | L9: 5.39 | M9: FALSE | N9: W1 | R9: Total Overview
A10: W2 | C10: 0 | J10: 21st | K10: Gym | L10: 40.04 | M10: FALSE | N10: W2 | O10: 0
D11: =SUM(C9:C10) -> 135 | P11: =SUM(O9,O10) -> 0
A12: Misc | C12: =B19 -> 869.196 | D12: 0 | J12: 30th | K12: Apple Music | L12: 6.48 | M12: TRUE | N12: Savings Acct | R12: Needs Leftover
A13: Total: | D13: =SUM(D7,D11,D12,C12) -> 2197.536 | N13: W1 | O13: 265.67 | R13: Wants Leftover
F14: Groceries | H14: =S40 -> 0 | J14: Dinning Out | L14: =T40 -> 51.54 | N14: W2 | R14: Savings Leftovers | T14: =AG26
F15: Gas | H15: =Q40 -> 32.24 | J15: Haircut | L15: 0 | P15: =SUM(O13,O14) -> 265.67 | R15: Total: | T15: =SUM(T12,T13,T14) -> 0
F16: Credit Payment | H16: 200 | J16: Other | L16: =R40 -> 55.04 | N16: Roth IRA
J17: Shopping | L17: =V40 -> 24.33 | N17: W1 | O17: 100
B18: Checking Acct | N18: W2 | O18: 0
A19: Leftover from Last Month | B19: =Aug!C21 -> 869.196 | P19: =SUM(O17:O18) -> 100
F30: Budgeted Money | H30: =K3 -> 1098.768 | J30: Budgeted Money | L30: =K4 -> 659.2608
F31: Total | H31: =SUM(H14:I16)+(H9*I9) -> 232.24 | J31: Total | L31: =SUM(L14:M17)+((L9*M9)+(L10*M10)+(L11*M11)+(L12*M12)) -> 137.39
F32: Leftover | H32: =SUM(H30-H31) -> 866.528 | J32: Leftover | L32: =L30-L31 -> 521.8708 | N32: Total: | P32: =SUM(P10,P14,P18) -> 0
E35: Monthly Transactions | P35: Monthly Total | U35: =SUM(I41:I86) -> 163.15
A36: Options
A37: Subscriptions
A38: Gas | P38: Subscriptions | Q38: Gas | R38: Other | S38: Groceries | T38: Dining out | U38: Rent | V38: Shopping
A39: Other | E39: Date | G39: Category | I39: Amount | J39: Notes
A40: Groceries | P40: =SUMIF(G41:H87,"Subscriptions",I41:I87) -> 0 | Q40: =SUMIF(G41:H87,"Gas",I41:I87) -> 32.24 | R40: =SUMIF(G41:H87,"Other",I41:I87) -> 55.04 | S40: =SUMIF(G41:H87,"Groceries",I41:I87) -> 0 | T40: =SUMIF(G41:H87,"Dining Out",I41:I87) -> 51.54 | U40: =SUMIF(G41:H87,"Rent",I41:I87) -> 0 | V40: =SUMIF(G41:H87,"Shopping",I41:I87) -> 24.33
A41: Dining out | E41: 45901 | G41: Shopping | I41: 24.33 | J41: Petco
A42: Rent | E42: 45902 | G42: Other | I42: 55.04 | J42: Gym | P42: =SUM((L9*M9)+(L10*M10)+(L11*M11)+(L12*M12)) -> 6.48
A43: Shopping | E43: 45902 | G43: Dining out | I43: 2.61 | J43: Starbucks
E44: 45902 | G44: Dining out | I44: 9.77 | J44: Chickflia
E45: 45902 | G45: Dining out | I45: 2.76 | J45: Starbucks
E46: 45902 | G46: Dining out | I46: 7.53 | J46: starbucks | Q46: School Refund
E47: 45903 | G47: Dining out | I47: 21.16 | J47: BBQ | P47: Extra:
E48: 45903 | G48: Dining out | I48: 7.71 | J48: Coffee | P48: Payment
E49: 45903 | G49: Gas | I49: 32.24

Sheet Oct
A1: Income | I1: Total Income: | K1: =D13 -> 0
I2: Type of Split | K2: 50/30/20 | M2: <- (Select which)
I3: Needs | K3: =IF(K2="50/30/20",(K1*0.5), IF(K2="70/20/10",(K1*0.7))) -> 0
A4: Starbucks Pay | I4: Wants | K4: =IF(K2="50/30/20",(K1*0.3), IF(K2="70/20/10",(K1*0.2))) -> 0
A5: W1 | C5: 0 | I5: Savings | K5: =IF(K2="50/30/20",(K1*0.2), IF(K2="70/20/10",(K1*0.1))) -> 0
A6: W2 | C6: 0 | F6: NEEDS | J6: WANTS | N6: Savings/Investments
D7: =SUM(C5:C6) -> 0 | N7: 401K
A8: Rec. | F8: Dates | H8: $ | I8: Checklist | L8: Actual | N8: W1 | O8: 0
A9: W1 | C9: 0 | F9: 25st | G9: Rent | H9: 650 | I9: FALSE | J9: 2nd | K9: HBO Max | L9: 5.39 | M9: FALSE | N9: W2 | O9: 0 | R9: Total Overview
A10: W2 | C10: 0 | J10: 21st | K10: Gym | L10: 40.04 | M10: FALSE | P10: =SUM(O8,O9) -> 0
D11: =SUM(C9:C10) -> 0 | N11: Savings Acct
A12: Misc | C12: =B20 | D12: 0 | J12: 30th | K12: Apple Music | L12: 6.48 | M12: FALSE | N12: W1 | O12: 0 | R12: Needs Leftover
A13: Total: | D13: =SUM(D7,D11,D12,C12) -> 0 | N13: W2 | R13: Wants Leftover
F14: Groceries | H14: =S40 -> 0 | J14: Dinning Out | P14: =SUM(O12,O13) -> 0 | R14: Savings Leftovers | T14: =AG26
F15: Gas | H15: =Q40 -> 0 | J15: Haircut | L15: 0 | N15: Roth IRA | R15: Total: | T15: =SUM(T12,T13,T14) -> 0
F16: Credit Payment | H16: 200 | J16: Other | L16: =R40 -> 0 | N16: W1 | O16: 0
J17: Shopping | L17: =V40 -> 0 | N17: W2 | O17: 0
P18: =SUM(O16:O17) -> 0
B19: Checking Acct
A20: Leftover from Last Month
F30: Budgeted Money | H30: =K3 -> 0 | J30: Budgeted Money | L30: =K4 -> 0
F31: Total | H31: =SUM(H14:I16)+(H9*I9) -> 200 | J31: Total | L31: =SUM(L14:M17)+((L9*M9)+(L10*M10)+(L11*M11)+(L12*M12)) -> 0
F32: Leftover | H32: =SUM(H30-H31) -> -200 | J32: Leftover | L32: =L30-L31 -> 0 | N32: Total: | P32: =SUM(P10,P14,P18) -> 0
E35: Monthly Transactions | P35: Monthly Total | U35: =SUM(I41:I86) -> 0
A36: Options
A37: Subscriptions
A38: Gas | P38: Subscriptions | Q38: Gas | R38: Other | S38: Groceries | T38: Dining out | U38: Rent | V38: Shopping
A39: Other | E39: Date | G39: Category | I39: Amount | J39: Notes
A40: Groceries | P40: =SUMIF(G41:H87,"Subscriptions",I41:I87) -> 0 | Q40: =SUMIF(G41:H87,"Gas",I41:I87) -> 0 | R40: =SUMIF(G41:H87,"Other",I41:I87) -> 0 | S40: =SUMIF(G41:H87,"Groceries",I41:I87) -> 0 | T40: =SUMIF(G41:H87,"Dining Out",I41:I87) -> 0 | U40: =SUMIF(G41:H87,"Rent",I41:I87) -> 0 | V40: =SUMIF(G41:H87,"Shopping",I41:I87) -> 0
A41: Dining out
A42: Rent | P42: =SUM((L9*M9)+(L10*M10)+(L11*M11)+(L12*M12)) -> 0
A43: Shopping
Q46: School Refund
P47: Extra:
P48: Payment

Sheet Nov
A1: Income | I1: Total Income: | K1: =D13 -> 0
I2: Type of Split | K2: 50/30/20 | M2: <- (Select which)
I3: Needs | K3: =IF(K2="50/30/20",(K1*0.5), IF(K2="70/20/10",(K1*0.7))) -> 0
A4: Starbucks Pay | I4: Wants | K4: =IF(K2="50/30/20",(K1*0.3), IF(K2="70/20/10",(K1*0.2))) -> 0
A5: W1 | C5: 0 | I5: Savings | K5: =IF(K2="50/30/20",(K1*0.2), IF(K2="70/20/10",(K1*0.1))) -> 0
A6: W2 | C6: 0 | F6: NEEDS | J6: WANTS | N6: Savings/Investments
D7: =SUM(C5:C6) -> 0 | N7: 401K
A8: Rec. | F8: Dates | H8: $ | I8: Checklist | L8: Actual | N8: W1 | O8: 0
A9: W1 | C9: 0 | F9: 25st | G9: Rent | H9: 650 | I9: FALSE | J9: 2nd | K9: HBO Max | L9: 5.39 | M9: FALSE | N9: W2 | O9: 0 | R9: Total Overview
A10: W2 | C10: 0 | J10: 21st | K10: Gym | L10: 40.04 | M10: FALSE | P10: =SUM(O8,O9) -> 0
D11: =SUM(C9:C10) -> 0 | N11: Savings Acct
A12: Misc | D12: 0 | J12: 30th | K12: Apple Music | L12: 6.48 | M12: FALSE | N12: W1 | O12: 0 | R12: Needs Leftover
A13: Total: | D13: =SUM(D7,D11,D12,C12) -> 0 | N13: W2 | R13: Wants Leftover
F14: Groceries | H14: =S40 -> 0 | J14: Dinning Out | P14: =SUM(O12,O13) -> 0 | R14: Savings Leftovers | T14: =AG26
F15: Gas | H15: =Q40 -> 0 | J15: Haircut | L15: 0 | N15: Roth IRA | R15: Total: | T15: =SUM(T12,T13,T14) -> 0
F16: Credit Payment | H16: 200 | J16: Other | L16: =R40 -> 0 | N16: W1 | O16: 0
J17: Shopping | L17: =V40 -> 0 | N17: W2 | O17: 0
B18: Checking Acct | P18: =SUM(O16:O17) -> 0
A19: Leftover from Last Month | B19: =C12
F30: Budgeted Money | H30: =K3 -> 0 | J30: Budgeted Money | L30: =K4 -> 0
F31: Total | H31: =SUM(H14:I16)+(H9*I9) -> 200 | J31: Total | L31: =SUM(L14:M17)+((L9*M9)+(L10*M10)+(L11*M11)+(L12*M12)) -> 0
F32: Leftover | H32: =SUM(H30-H31) -> -200 | J32: Leftover | L32: =L30-L31 -> 0 | N32: Total: | P32: =SUM(P10,P14,P18) -> 0
E35: Monthly Transactions | P35: Monthly Total | U35: =SUM(I41:I86) -> 0
A36: Options
A37: Subscriptions
A38: Gas | P38: Subscriptions | Q38: Gas | R38: Other | S38: Groceries | T38: Dining out | U38: Rent | V38: Shopping
A39: Other | E39: Date | G39: Category | I39: Amount | J39: Notes
A40: Groceries | P40: =SUMIF(G41:H87,"Subscriptions",I41:I87) -> 0 | Q40: =SUMIF(G41:H87,"Gas",I41:I87) -> 0 | R40: =SUMIF(G41:H87,"Other",I41:I87) -> 0 | S40: =SUMIF(G41:H87,"Groceries",I41:I87) -> 0 | T40: =SUMIF(G41:H87,"Dining Out",I41:I87) -> 0 | U40: =SUMIF(G41:H87,"Rent",I41:I87) -> 0 | V40: =SUMIF(G41:H87,"Shopping",I41:I87) -> 0
A41: Dining out
A42: Rent | P42: =SUM((L9*M9)+(L10*M10)+(L11*M11)+(L12*M12)) -> 0
A43: Shopping
Q46: School Refund
P47: Extra:
P48: Payment

Sheet Dec
A1: Income | I1: Total Income: | K1: =D13 -> 0
I2: Type of Split | K2: 50/30/20 | M2: <- (Select which)
I3: Needs | K3: =IF(K2="50/30/20",(K1*0.5), IF(K2="70/20/10",(K1*0.7))) -> 0
A4: Starbucks Pay | I4: Wants | K4: =IF(K2="50/30/20",(K1*0.3), IF(K2="70/20/10",(K1*0.2))) -> 0
A5: W1 | C5: 0 | I5: Savings | K5: =IF(K2="50/30/20",(K1*0.2), IF(K2="70/20/10",(K1*0.1))) -> 0
A6: W2 | C6: 0 | F6: NEEDS | J6: WANTS | N6: Savings/Investments
D7: =SUM(C5:C6) -> 0 | N7: 401K
A8: Rec. | F8: Dates | H8: $ | I8: Checklist | L8: Actual | N8: W1 | O8: 0
A9: W1 | C9: 0 | F9: 25st | G9: Rent | H9: 650 | I9: FALSE | J9: 2nd | K9: HBO Max | L9: 5.39 | M9: FALSE | N9: W2 | O9: 0 | R9: Total Overview
A10: W2 | C10: 0 | J10: 21st | K10: Gym | L10: 40.04 | M10: FALSE | P10: =SUM(O8,O9) -> 0
D11: =SUM(C9:C10) -> 0 | N11: Savings Acct
A12: Misc | D12: 0 | J12: 30th | K12: Apple Music | L12: 6.48 | M12: FALSE | N12: W1 | O12: 0 | R12: Needs Leftover
A13: Total: | D13: =SUM(D7,D11,D12,C12) -> 0 | N13: W2 | R13: Wants Leftover
F14: Groceries | H14: =S40 -> 0 | J14: Dinning Out | P14: =SUM(O12,O13) -> 0 | R14: Savings Leftovers | T14: =AG26
F15: Gas | H15: =Q40 -> 0 | J15: Haircut | L15: 0 | N15: Roth IRA | R15: Total: | T15: =SUM(T12,T13,T14) -> 0
F16: Credit Payment | H16: 200 | J16: Other | L16: =R40 -> 0 | N16: W1 | O16: 0
J17: Shopping | L17: =V40 -> 0 | N17: W2 | O17: 0
B18: Checking Acct | P18: =SUM(O16:O17) -> 0
A19: Leftover from Last Month | B19: =C12
F30: Budgeted Money | H30: =K3 -> 0 | J30: Budgeted Money | L30: =K4 -> 0
F31: Total | H31: =SUM(H14:I16)+(H9*I9) -> 200 | J31: Total | L31: =SUM(L14:M17)+((L9*M9)+(L10*M10)+(L11*M11)+(L12*M12)) -> 0
F32: Leftover | H32: =SUM(H30-H31) -> -200 | J32: Leftover | L32: =L30-L31 -> 0 | N32: Total: | P32: =SUM(P10,P14,P18) -> 0
E35: Monthly Transactions | P35: Monthly Total | U35: =SUM(I41:I86) -> 0
A36: Options
A37: Subscriptions
A38: Gas | P38: Subscriptions | Q38: Gas | R38: Other | S38: Groceries | T38: Dining out | U38: Rent | V38: Shopping
A39: Other | E39: Date | G39: Category | I39: Amount | J39: Notes
A40: Groceries | P40: =SUMIF(G41:H87,"Subscriptions",I41:I87) -> 0 | Q40: =SUMIF(G41:H87,"Gas",I41:I87) -> 0 | R40: =SUMIF(G41:H87,"Other",I41:I87) -> 0 | S40: =SUMIF(G41:H87,"Groceries",I41:I87) -> 0 | T40: =SUMIF(G41:H87,"Dining Out",I41:I87) -> 0 | U40: =SUMIF(G41:H87,"Rent",I41:I87) -> 0 | V40: =SUMIF(G41:H87,"Shopping",I41:I87) -> 0
A41: Dining out
A42: Rent | P42: =SUM((L9*M9)+(L10*M10)+(L11*M11)+(L12*M12)) -> 0
A43: Shopping
Q46: School Refund
P47: Extra:
P48: Payment
