Workbook

Sheet Monthly Spending Template
B1: MONTHLY BUDGET TEMPLATE
B5: Total Income | D5: Total Spent | F5: Leftover | H5: Savings Rate | J5: Bills Paid | Q5: Spending Breakdown | U5: Budgeted | V5: Actual
B6: =SUM(IncomeTbl_MonthlySpendingTemplate[Amount]) -> 0 | D6: =R6+R7 -> 0 | F6: =B6-D6 -> 0 | H6: =IFERROR(R8/B6,0) -> 0 | J6: =COUNTIF(BillsTbl_MonthlySpendingTemplate[Paid?],TRUE())&" / "&COUNTA(BillsTbl_MonthlySpendingTemplate[Bill Name]) -> 0 / 0 | Q6: Needs Actual | R6: =O31+O27+O25+O29 -> 0 | T6: Needs | U6: =C33 -> 0 | V6: =R6 -> 0
Q7: Wants Actual | R7: =O26+O28+O24+O30 -> 0 | T7: Wants | U7: =C34 -> 0 | V7: =R7 -> 0
Q8: Savings Actual | R8: =SUM(SavingsTbl_MonthlySpendingTemplate[Amount]) -> 0 | T8: Savings | U8: =C35 -> 0 | V8: =R8 -> 0
Q9: Total Spent | R9: =R6+R7 -> 0
B22: Income | I22: Transactions Log | N22: Category Totals
B23: Source | C23: Amount | I23: Date | J23: Category | K23: Amount | L23: Notes | N23: Category | O23: Total
N24: Subscriptions | O24: =SUMIFS(BillsTbl_MonthlySpendingTemplate[Actual],BillsTbl_MonthlySpendingTemplate[Category],"Subscriptions")+SUMIFS(TxnTbl_MonthlySpendingTemplate[Amount],TxnTbl_MonthlySpendingTemplate[Category],"Subscriptions") -> 0
N25: Gas | O25: =SUMIFS(BillsTbl_MonthlySpendingTemplate[Actual],BillsTbl_MonthlySpendingTemplate[Category],"Gas")+SUMIFS(TxnTbl_MonthlySpendingTemplate[Amount],TxnTbl_MonthlySpendingTemplate[Category],"Gas") -> 0
N26: Other | O26: =SUMIFS(BillsTbl_MonthlySpendingTemplate[Actual],BillsTbl_MonthlySpendingTemplate[Category],"Other")+SUMIFS(TxnTbl_MonthlySpendingTemplate[Amount],TxnTbl_MonthlySpendingTemplate[Category],"Other") -> 0
N27: Groceries | O27: =SUMIFS(BillsTbl_MonthlySpendingTemplate[Actual],BillsTbl_MonthlySpendingTemplate[Category],"Groceries")+SUMIFS(TxnTbl_MonthlySpendingTemplate[Amount],TxnTbl_MonthlySpendingTemplate[Category],"Groceries") -> 0
N28: Dining out | O28: =SUMIFS(BillsTbl_MonthlySpendingTemplate[Actual],BillsTbl_MonthlySpendingTemplate[Category],"Dining out")+SUMIFS(TxnTbl_MonthlySpendingTemplate[Amount],TxnTbl_MonthlySpendingTemplate[Category],"Dining out") -> 0
N29: Rent | O29: =SUMIFS(BillsTbl_MonthlySpendingTemplate[Actual],BillsTbl_MonthlySpendingTemplate[Category],"Rent")+SUMIFS(TxnTbl_MonthlySpendingTemplate[Amount],TxnTbl_MonthlySpendingTemplate[Category],"Rent") -> 0
N30: Shopping | O30: =SUMIFS(BillsTbl_MonthlySpendingTemplate[Actual],BillsTbl_MonthlySpendingTemplate[Category],"Shopping")+SUMIFS(TxnTbl_MonthlySpendingTemplate[Amount],TxnTbl_MonthlySpendingTemplate[Category],"Shopping") -> 0
N31: Credit Card | O31: =SUMIFS(BillsTbl_MonthlySpendingTemplate[Actual],BillsTbl_MonthlySpendingTemplate[Category],"Credit Card")+SUMIFS(TxnTbl_MonthlySpendingTemplate[Amount],TxnTbl_MonthlySpendingTemplate[Category],"Credit Card") -> 0
B32: Budget Split | C32: 50/30/20
B33: Needs Target | C33: =IF(C32="50/30/20",B6*0.5,IF(C32="70/20/10",B6*0.7,0)) -> 0
B34: Wants Target | C34: =IF(C32="50/30/20",B6*0.3,IF(C32="70/20/10",B6*0.2,0)) -> 0
B35: Savings Target | C35: =IF(C32="50/30/20",B6*0.2,IF(C32="70/20/10",B6*0.1,0)) -> 0
B37: Recurring Bills
B38: Bill Name | C38: Category | D38: Amount | E38: Paid? | F38: Actual
F39: =IF(E39=TRUE(),D39,0) -> 0
F40: =IF(E40=TRUE(),D40,0) -> 0
F41: =IF(E41=TRUE(),D41,0) -> 0
F42: =IF(E42=TRUE(),D42,0) -> 0
F43: =IF(E43=TRUE(),D43,0) -> 0
F44: =IF(E44=TRUE(),D44,0) -> 0
F45: =IF(E45=TRUE(),D45,0) -> 0
F46: =IF(E46=TRUE(),D46,0) -> 0
F47: =IF(E47=TRUE(),D47,0) -> 0
F48: =IF(E48=TRUE(),D48,0) -> 0
F49: =IF(E49=TRUE(),D49,0) -> 0
F50: =IF(E50=TRUE(),D50,0) -> 0
B53: Savings & Investments
B54: Account | C54: Amount

Sheet Yearly Overview
C2: Yearly Budget Dashboard
C6: Total Income (YTD) | F6: Total Spent (YTD) | I6: Avg Savings Rate | L6: Net Position (YTD)
C7: =SUM(E11:P11) -> 4851.81 | F7: =SUM(E15:P15) -> 2306.9 | I7: =IFERROR(AVERAGE(E17:P17),0) -> 0.035142109 | L7: =SUM(E16:P16) -> 2544.91
C10: Monthly Summary | E10: Jan. | F10: Feb. | G10: Mar | H10: Apr | I10: May | J10: Jun | K10: Jul | L10: Aug | M10: Sept | N10: Oct | O10: Nov | P10: Dec
C11: Total Income | E11: =Jan!B6 -> 0 | F11: =Feb!B6 -> 0 | G11: =Mar!B6 -> 0 | H11: =Apr!B6 -> 0 | I11: =May!B6 -> 0 | J11: =Jun!B6 -> 0 | K11: =Jul!B6 -> 0 | L11: =Aug!B6 -> 2654.27 | M11: =Sep!B6 -> 2197.54 | N11: =Oct!B6 -> 0 | O11: =Nov!B6 -> 0 | P11: =Dec!B6 -> 0
C12: Needs Actual | E12: =Jan!R6 -> 0 | F12: =Feb!R6 -> 0 | G12: =Mar!R6 -> 0 | H12: =Apr!R6 -> 0 | I12: =May!R6 -> 0 | J12: =Jun!R6 -> 0 | K12: =Jul!R6 -> 0 | L12: =Aug!R6 -> 981.61 | M12: =Sep!R6 -> 232.24 | N12: =Oct!R6 -> 0 | O12: =Nov!R6 -> 0 | P12: =Dec!R6 -> 0
C13: Wants Actual | E13: =Jan!R7 -> 0 | F13: =Feb!R7 -> 0 | G13: =Mar!R7 -> 0 | H13: =Apr!R7 -> 0 | I13: =May!R7 -> 0 | J13: =Jun!R7 -> 0 | K13: =Jul!R7 -> 0 | L13: =Aug!R7 -> 955.66 | M13: =Sep!R7 -> 137.39 | N13: =Oct!R7 -> 0 | O13: =Nov!R7 -> 0 | P13: =Dec!R7 -> 0
C14: Savings Actual | E14: =Jan!R8 -> 0 | F14: =Feb!R8 -> 0 | G14: =Mar!R8 -> 0 | H14: =Apr!R8 -> 0 | I14: =May!R8 -> 0 | J14: =Jun!R8 -> 0 | K14: =Jul!R8 -> 0 | L14: =Aug!R8 -> 677.65 | M14: =Sep!R8 -> 365.67 | N14: =Oct!R8 -> 0 | O14: =Nov!R8 -> 0 | P14: =Dec!R8 -> 0
C15: Total Expenses | E15: =Jan!R9 -> 0 | F15: =Feb!R9 -> 0 | G15: =Mar!R9 -> 0 | H15: =Apr!R9 -> 0 | I15: =May!R9 -> 0 | J15: =Jun!R9 -> 0 | K15: =Jul!R9 -> 0 | L15: =Aug!R9 -> 1937.27 | M15: =Sep!R9 -> 369.63 | N15: =Oct!R9 -> 0 | O15: =Nov!R9 -> 0 | P15: =Dec!R9 -> 0
C16: Cash Short/Extra | E16: =Jan!F6 -> 0 | F16: =Feb!F6 -> 0 | G16: =Mar!F6 -> 0 | H16: =Apr!F6 -> 0 | I16: =May!F6 -> 0 | J16: =Jun!F6 -> 0 | K16: =Jul!F6 -> 0 | L16: =Aug!F6 -> 717 | M16: =Sep!F6 -> 1827.91 | N16: =Oct!F6 -> 0 | O16: =Nov!F6 -> 0 | P16: =Dec!F6 -> 0
C17: Savings Rate % | E17: =Jan!H6 -> 0 | F17: =Feb!H6 -> 0 | G17: =Mar!H6 -> 0 | H17: =Apr!H6 -> 0 | I17: =May!H6 -> 0 | J17: =Jun!H6 -> 0 | K17: =Jul!H6 -> 0 | L17: =Aug!H6 -> 0.2553056 | M17: =Sep!H6 -> 0.1663997 | N17: =Oct!H6 -> 0 | O17: =Nov!H6 -> 0 | P17: =Dec!H6 -> 0
C20: Spending by Category
C21: Category | E21: Jan. | F21: Feb. | G21: Mar | H21: Apr | I21: May | J21: Jun | K21: Jul | L21: Aug | M21: Sept | N21: Oct | O21: Nov | P21: Dec | Q21: Avg/Active Mo. | R21: YTD Total
C22: Subscriptions | E22: =Jan!O24 -> 0 | F22: =Feb!O24 -> 0 | G22: =Mar!O24 -> 0 | H22: =Apr!O24 -> 0 | I22: =May!O24 -> 0 | J22: =Jun!O24 -> 0 | K22: =Jul!O24 -> 0 | L22: =Aug!O24 -> 57.31 | M22: =Sep!O24 -> 6.48 | N22: =Oct!O24 -> 0 | O22: =Nov!O24 -> 0 | P22: =Dec!O24 -> 0 | Q22: =IFERROR(AVERAGEIF(E22:P22,"<>0"),0) -> 31.895 | R22: =SUM(E22:P22) -> 63.79
C23: Gas | E23: =Jan!O25 -> 0 | F23: =Feb!O25 -> 0 | G23: =Mar!O25 -> 0 | H23: =Apr!O25 -> 0 | I23: =May!O25 -> 0 | J23: =Jun!O25 -> 0 | K23: =Jul!O25 -> 0 | L23: =Aug!O25 -> 61.61 | M23: =Sep!O25 -> 32.24 | N23: =Oct!O25 -> 0 | O23: =Nov!O25 -> 0 | P23: =Dec!O25 -> 0 | Q23: =IFERROR(AVERAGEIF(E23:P23,"<>0"),0) -> 46.925 | R23: =SUM(E23:P23) -> 93.85
C24: Other | E24: =Jan!O26 -> 0 | F24: =Feb!O26 -> 0 | G24: =Mar!O26 -> 0 | H24: =Apr!O26 -> 0 | I24: =May!O26 -> 0 | J24: =Jun!O26 -> 0 | K24: =Jul!O26 -> 0 | L24: =Aug!O26 -> 482.41 | M24: =Sep!O26 -> 55.04 | N24: =Oct!O26 -> 0 | O24: =Nov!O26 -> 0 | P24: =Dec!O26 -> 0 | Q24: =IFERROR(AVERAGEIF(E24:P24,"<>0"),0) -> 268.725 | R24: =SUM(E24:P24) -> 537.45
C25: Groceries | E25: =Jan!O27 -> 0 | F25: =Feb!O27 -> 0 | G25: =Mar!O27 -> 0 | H25: =Apr!O27 -> 0 | I25: =May!O27 -> 0 | J25: =Jun!O27 -> 0 | K25: =Jul!O27 -> 0 | L25: =Aug!O27 -> 70 | M25: =Sep!O27 -> 0 | N25: =Oct!O27 -> 0 | O25: =Nov!O27 -> 0 | P25: =Dec!O27 -> 0 | Q25: =IFERROR(AVERAGEIF(E25:P25,"<>0"),0) -> 70 | R25: =SUM(E25:P25) -> 70
C26: Dining out | E26: =Jan!O28 -> 0 | F26: =Feb!O28 -> 0 | G26: =Mar!O28 -> 0 | H26: =Apr!O28 -> 0 | I26: =May!O28 -> 0 | J26: =Jun!O28 -> 0 | K26: =Jul!O28 -> 0 | L26: =Aug!O28 -> 168.91 | M26: =Sep!O28 -> 51.54 | N26: =Oct!O28 -> 0 | O26: =Nov!O28 -> 0 | P26: =Dec!O28 -> 0 | Q26: =IFERROR(AVERAGEIF(E26:P26,"<>0"),0) -> 110.225 | R26: =SUM(E26:P26) -> 220.45
C27: Rent | E27: =Jan!O29 -> 0 | F27: =Feb!O29 -> 0 | G27: =Mar!O29 -> 0 | H27: =Apr!O29 -> 0 | I27: =May!O29 -> 0 | J27: =Jun!O29 -> 0 | K27: =Jul!O29 -> 0 | L27: =Aug!O29 -> 650 | M27: =Sep!O29 -> 0 | N27: =Oct!O29 -> 0 | O27: =Nov!O29 -> 0 | P27: =Dec!O29 -> 0 | Q27: =IFERROR(AVERAGEIF(E27:P27,"<>0"),0) -> 650 | R27: =SUM(E27:P27) -> 650
C28: Shopping | E28: =Jan!O30 -> 0 | F28: =Feb!O30 -> 0 | G28: =Mar!O30 -> 0 | H28: =Apr!O30 -> 0 | I28: =May!O30 -> 0 | J28: =Jun!O30 -> 0 | K28: =Jul!O30 -> 0 | L28: =Aug!O30 -> 247.03 | M28: =Sep!O30 -> 24.33 | N28: =Oct!O30 -> 0 | O28: =Nov!O30 -> 0 | P28: =Dec!O30 -> 0 | Q28: =IFERROR(AVERAGEIF(E28:P28,"<>0"),0) -> 135.68 | R28: =SUM(E28:P28) -> 271.36
C29: Credit Card | E29: =Jan!O31 -> 0 | F29: =Feb!O31 -> 0 | G29: =Mar!O31 -> 0 | H29: =Apr!O31 -> 0 | I29: =May!O31 -> 0 | J29: =Jun!O31 -> 0 | K29: =Jul!O31 -> 0 | L29: =Aug!O31 -> 200 | M29: =Sep!O31 -> 200 | N29: =Oct!O31 -> 0 | O29: =Nov!O31 -> 0 | P29: =Dec!O31 -> 0 | Q29: =IFERROR(AVERAGEIF(E29:P29,"<>0"),0) -> 200 | R29: =SUM(E29:P29) -> 400

Sheet Jan
B1: JANUARY
B5: Total Income | D5: Total Spent | F5: Leftover | H5: Savings Rate | J5: Bills Paid | Q5: Spending Breakdown | U5: Budgeted | V5: Actual
B6: =SUM(IncomeTbl_Jan[Amount]) -> 0 | D6: =R6+R7 -> 0 | F6: =B6-D6 -> 0 | H6: =IFERROR(R8/B6,0) -> 0 | J6: =COUNTIF(BillsTbl_Jan[Paid?],TRUE())&" / "&COUNTA(BillsTbl_Jan[Bill Name]) -> 0 / 0 | Q6: Needs Actual | R6: =O31+O27+O25+O29 -> 0 | T6: Needs | U6: =C33 -> 0 | V6: =R6 -> 0
Q7: Wants Actual | R7: =O26+O28+O24+O30 -> 0 | T7: Wants | U7: =C34 -> 0 | V7: =R7 -> 0
Q8: Savings Actual | R8: =SUM(SavingsTbl_Jan[Amount]) -> 0 | T8: Savings | U8: =C35 -> 0 | V8: =R8 -> 0
Q9: Total Spent | R9: =R6+R7 -> 0
B22: Income | I22: Transactions Log | N22: Category Totals
B23: Source | C23: Amount | I23: Date | J23: Category | K23: Amount | L23: Notes | N23: Category | O23: Total
N24: Subscriptions | O24: =SUMIFS(BillsTbl_Jan[Actual],BillsTbl_Jan[Category],"Subscriptions")+SUMIFS(TxnTbl_Jan[Amount],TxnTbl_Jan[Category],"Subscriptions") -> 0
N25: Gas | O25: =SUMIFS(BillsTbl_Jan[Actual],BillsTbl_Jan[Category],"Gas")+SUMIFS(TxnTbl_Jan[Amount],TxnTbl_Jan[Category],"Gas") -> 0
N26: Other | O26: =SUMIFS(BillsTbl_Jan[Actual],BillsTbl_Jan[Category],"Other")+SUMIFS(TxnTbl_Jan[Amount],TxnTbl_Jan[Category],"Other") -> 0
N27: Groceries | O27: =SUMIFS(BillsTbl_Jan[Actual],BillsTbl_Jan[Category],"Groceries")+SUMIFS(TxnTbl_Jan[Amount],TxnTbl_Jan[Category],"Groceries") -> 0
N28: Dining out | O28: =SUMIFS(BillsTbl_Jan[Actual],BillsTbl_Jan[Category],"Dining out")+SUMIFS(TxnTbl_Jan[Amount],TxnTbl_Jan[Category],"Dining out") -> 0
N29: Rent | O29: =SUMIFS(BillsTbl_Jan[Actual],BillsTbl_Jan[Category],"Rent")+SUMIFS(TxnTbl_Jan[Amount],TxnTbl_Jan[Category],"Rent") -> 0
N30: Shopping | O30: =SUMIFS(BillsTbl_Jan[Actual],BillsTbl_Jan[Category],"Shopping")+SUMIFS(TxnTbl_Jan[Amount],TxnTbl_Jan[Category],"Shopping") -> 0
N31: Credit Card | O31: =SUMIFS(BillsTbl_Jan[Actual],BillsTbl_Jan[Category],"Credit Card")+SUMIFS(TxnTbl_Jan[Amount],TxnTbl_Jan[Category],"Credit Card") -> 0
B32: Budget Split | C32: 50/30/20
B33: Needs Target | C33: =IF(C32="50/30/20",B6*0.5,IF(C32="70/20/10",B6*0.7,0)) -> 0
B34: Wants Target | C34: =IF(C32="50/30/20",B6*0.3,IF(C32="70/20/10",B6*0.2,0)) -> 0
B35: Savings Target | C35: =IF(C32="50/30/20",B6*0.2,IF(C32="70/20/10",B6*0.1,0)) -> 0
B37: Recurring Bills
B38: Bill Name | C38: Category | D38: Amount | E38: Paid? | F38: Actual
F39: =IF(E39=TRUE(),D39,0) -> 0
F40: =IF(E40=TRUE(),D40,0) -> 0
F41: =IF(E41=TRUE(),D41,0) -> 0
F42: =IF(E42=TRUE(),D42,0) -> 0
F43: =IF(E43=TRUE(),D43,0) -> 0
F44: =IF(E44=TRUE(),D44,0) -> 0
F45: =IF(E45=TRUE(),D45,0) -> 0
F46: =IF(E46=TRUE(),D46,0) -> 0
F47: =IF(E47=TRUE(),D47,0) -> 0
F48: =IF(E48=TRUE(),D48,0) -> 0
F49: =IF(E49=TRUE(),D49,0) -> 0
F50: =IF(E50=TRUE(),D50,0) -> 0
B53: Savings & Investments
B54: Account | C54: Amount

Sheet Feb
B1: FEBRUARY
B5: Total Income | D5: Total Spent | F5: Leftover | H5: Savings Rate | J5: Bills Paid | Q5: Spending Breakdown | U5: Budgeted | V5: Actual
B6: =SUM(IncomeTbl_Feb[Amount]) -> 0 | D6: =R6+R7 -> 0 | F6: =B6-D6 -> 0 | H6: =IFERROR(R8/B6,0) -> 0 | J6: =COUNTIF(BillsTbl_Feb[Paid?],TRUE())&" / "&COUNTA(BillsTbl_Feb[Bill Name]) -> 0 / 0 | Q6: Needs Actual | R6: =O31+O27+O25+O29 -> 0 | T6: Needs | U6: =C33 -> 0 | V6: =R6 -> 0
Q7: Wants Actual | R7: =O26+O28+O24+O30 -> 0 | T7: Wants | U7: =C34 -> 0 | V7: =R7 -> 0
Q8: Savings Actual | R8: =SUM(SavingsTbl_Feb[Amount]) -> 0 | T8: Savings | U8: =C35 -> 0 | V8: =R8 -> 0
Q9: Total Spent | R9: =R6+R7 -> 0
B22: Income | I22: Transactions Log | N22: Category Totals
B23: Source | C23: Amount | I23: Date | J23: Category | K23: Amount | L23: Notes | N23: Category | O23: Total
N24: Subscriptions | O24: =SUMIFS(BillsTbl_Feb[Actual],BillsTbl_Feb[Category],"Subscriptions")+SUMIFS(TxnTbl_Feb[Amount],TxnTbl_Feb[Category],"Subscriptions") -> 0
N25: Gas | O25: =SUMIFS(BillsTbl_Feb[Actual],BillsTbl_Feb[Category],"Gas")+SUMIFS(TxnTbl_Feb[Amount],TxnTbl_Feb[Category],"Gas") -> 0
N26: Other | O26: =SUMIFS(BillsTbl_Feb[Actual],BillsTbl_Feb[Category],"Other")+SUMIFS(TxnTbl_Feb[Amount],TxnTbl_Feb[Category],"Other") -> 0
N27: Groceries | O27: =SUMIFS(BillsTbl_Feb[Actual],BillsTbl_Feb[Category],"Groceries")+SUMIFS(TxnTbl_Feb[Amount],TxnTbl_Feb[Category],"Groceries") -> 0
N28: Dining out | O28: =SUMIFS(BillsTbl_Feb[Actual],BillsTbl_Feb[Category],"Dining out")+SUMIFS(TxnTbl_Feb[Amount],TxnTbl_Feb[Category],"Dining out") -> 0
N29: Rent | O29: =SUMIFS(BillsTbl_Feb[Actual],BillsTbl_Feb[Category],"Rent")+SUMIFS(TxnTbl_Feb[Amount],TxnTbl_Feb[Category],"Rent") -> 0
N30: Shopping | O30: =SUMIFS(BillsTbl_Feb[Actual],BillsTbl_Feb[Category],"Shopping")+SUMIFS(TxnTbl_Feb[Amount],TxnTbl_Feb[Category],"Shopping") -> 0
N31: Credit Card | O31: =SUMIFS(BillsTbl_Feb[Actual],BillsTbl_Feb[Category],"Credit Card")+SUMIFS(TxnTbl_Feb[Amount],TxnTbl_Feb[Category],"Credit Card") -> 0
B32: Budget Split | C32: 50/30/20
B33: Needs Target | C33: =IF(C32="50/30/20",B6*0.5,IF(C32="70/20/10",B6*0.7,0)) -> 0
B34: Wants Target | C34: =IF(C32="50/30/20",B6*0.3,IF(C32="70/20/10",B6*0.2,0)) -> 0
B35: Savings Target | C35: =IF(C32="50/30/20",B6*0.2,IF(C32="70/20/10",B6*0.1,0)) -> 0
B37: Recurring Bills
B38: Bill Name | C38: Category | D38: Amount | E38: Paid? | F38: Actual
F39: =IF(E39=TRUE(),D39,0) -> 0
F40: =IF(E40=TRUE(),D40,0) -> 0
F41: =IF(E41=TRUE(),D41,0) -> 0
F42: =IF(E42=TRUE(),D42,0) -> 0
F43: =IF(E43=TRUE(),D43,0) -> 0
F44: =IF(E44=TRUE(),D44,0) -> 0
F45: =IF(E45=TRUE(),D45,0) -> 0
F46: =IF(E46=TRUE(),D46,0) -> 0
F47: =IF(E47=TRUE(),D47,0) -> 0
F48: =IF(E48=TRUE(),D48,0) -> 0
F49: =IF(E49=TRUE(),D49,0) -> 0
F50: =IF(E50=TRUE(),D50,0) -> 0
B53: Savings & Investments
B54: Account | C54: Amount

Sheet Mar
B1: MARCH
B5: Total Income | D5: Total Spent | F5: Leftover | H5: Savings Rate | J5: Bills Paid | Q5: Spending Breakdown | U5: Budgeted | V5: Actual
B6: =SUM(IncomeTbl_Mar[Amount]) -> 0 | D6: =R6+R7 -> 0 | F6: =B6-D6 -> 0 | H6: =IFERROR(R8/B6,0) -> 0 | J6: =COUNTIF(BillsTbl_Mar[Paid?],TRUE())&" / "&COUNTA(BillsTbl_Mar[Bill Name]) -> 0 / 0 | Q6: Needs Actual | R6: =O31+O27+O25+O29 -> 0 | T6: Needs | U6: =C33 -> 0 | V6: =R6 -> 0
Q7: Wants Actual | R7: =O26+O28+O24+O30 -> 0 | T7: Wants | U7: =C34 -> 0 | V7: =R7 -> 0
Q8: Savings Actual | R8: =SUM(SavingsTbl_Mar[Amount]) -> 0 | T8: Savings | U8: =C35 -> 0 | V8: =R8 -> 0
Q9: Total Spent | R9: =R6+R7 -> 0
B22: Income | I22: Transactions Log | N22: Category Totals
B23: Source | C23: Amount | I23: Date | J23: Category | K23: Amount | L23: Notes | N23: Category | O23: Total
N24: Subscriptions | O24: =SUMIFS(BillsTbl_Mar[Actual],BillsTbl_Mar[Category],"Subscriptions")+SUMIFS(TxnTbl_Mar[Amount],TxnTbl_Mar[Category],"Subscriptions") -> 0
N25: Gas | O25: =SUMIFS(BillsTbl_Mar[Actual],BillsTbl_Mar[Category],"Gas")+SUMIFS(TxnTbl_Mar[Amount],TxnTbl_Mar[Category],"Gas") -> 0
N26: Other | O26: =SUMIFS(BillsTbl_Mar[Actual],BillsTbl_Mar[Category],"Other")+SUMIFS(TxnTbl_Mar[Amount],TxnTbl_Mar[Category],"Other") -> 0
N27: Groceries | O27: =SUMIFS(BillsTbl_Mar[Actual],BillsTbl_Mar[Category],"Groceries")+SUMIFS(TxnTbl_Mar[Amount],TxnTbl_Mar[Category],"Groceries") -> 0
N28: Dining out | O28: =SUMIFS(BillsTbl_Mar[Actual],BillsTbl_Mar[Category],"Dining out")+SUMIFS(TxnTbl_Mar[Amount],TxnTbl_Mar[Category],"Dining out") -> 0
N29: Rent | O29: =SUMIFS(BillsTbl_Mar[Actual],BillsTbl_Mar[Category],"Rent")+SUMIFS(TxnTbl_Mar[Amount],TxnTbl_Mar[Category],"Rent") -> 0
N30: Shopping | O30: =SUMIFS(BillsTbl_Mar[Actual],BillsTbl_Mar[Category],"Shopping")+SUMIFS(TxnTbl_Mar[Amount],TxnTbl_Mar[Category],"Shopping") -> 0
N31: Credit Card | O31: =SUMIFS(BillsTbl_Mar[Actual],BillsTbl_Mar[Category],"Credit Card")+SUMIFS(TxnTbl_Mar[Amount],TxnTbl_Mar[Category],"Credit Card") -> 0
B32: Budget Split | C32: 50/30/20
B33: Needs Target | C33: =IF(C32="50/30/20",B6*0.5,IF(C32="70/20/10",B6*0.7,0)) -> 0
B34: Wants Target | C34: =IF(C32="50/30/20",B6*0.3,IF(C32="70/20/10",B6*0.2,0)) -> 0
B35: Savings Target | C35: =IF(C32="50/30/20",B6*0.2,IF(C32="70/20/10",B6*0.1,0)) -> 0
B37: Recurring Bills
B38: Bill Name | C38: Category | D38: Amount | E38: Paid? | F38: Actual
F39: =IF(E39=TRUE(),D39,0) -> 0
F40: =IF(E40=TRUE(),D40,0) -> 0
F41: =IF(E41=TRUE(),D41,0) -> 0
F42: =IF(E42=TRUE(),D42,0) -> 0
F43: =IF(E43=TRUE(),D43,0) -> 0
F44: =IF(E44=TRUE(),D44,0) -> 0
F45: =IF(E45=TRUE(),D45,0) -> 0
F46: =IF(E46=TRUE(),D46,0) -> 0
F47: =IF(E47=TRUE(),D47,0) -> 0
F48: =IF(E48=TRUE(),D48,0) -> 0
F49: =IF(E49=TRUE(),D49,0) -> 0
F50: =IF(E50=TRUE(),D50,0) -> 0
B53: Savings & Investments
B54: Account | C54: Amount

Sheet Apr
B1: APRIL
B5: Total Income | D5: Total Spent | F5: Leftover | H5: Savings Rate | J5: Bills Paid | Q5: Spending Breakdown | U5: Budgeted | V5: Actual
B6: =SUM(IncomeTbl_Apr[Amount]) -> 0 | D6: =R6+R7 -> 0 | F6: =B6-D6 -> 0 | H6: =IFERROR(R8/B6,0) -> 0 | J6: =COUNTIF(BillsTbl_Apr[Paid?],TRUE())&" / "&COUNTA(BillsTbl_Apr[Bill Name]) -> 0 / 0 | Q6: Needs Actual | R6: =O31+O27+O25+O29 -> 0 | T6: Needs | U6: =C33 -> 0 | V6: =R6 -> 0
Q7: Wants Actual | R7: =O26+O28+O24+O30 -> 0 | T7: Wants | U7: =C34 -> 0 | V7: =R7 -> 0
Q8: Savings Actual | R8: =SUM(SavingsTbl_Apr[Amount]) -> 0 | T8: Savings | U8: =C35 -> 0 | V8: =R8 -> 0
Q9: Total Spent | R9: =R6+R7 -> 0
B22: Income | I22: Transactions Log | N22: Category Totals
B23: Source | C23: Amount | I23: Date | J23: Category | K23: Amount | L23: Notes | N23: Category | O23: Total
N24: Subscriptions | O24: =SUMIFS(BillsTbl_Apr[Actual],BillsTbl_Apr[Category],"Subscriptions")+SUMIFS(TxnTbl_Apr[Amount],TxnTbl_Apr[Category],"Subscriptions") -> 0
N25: Gas | O25: =SUMIFS(BillsTbl_Apr[Actual],BillsTbl_Apr[Category],"Gas")+SUMIFS(TxnTbl_Apr[Amount],TxnTbl_Apr[Category],"Gas") -> 0
N26: Other | O26: =SUMIFS(BillsTbl_Apr[Actual],BillsTbl_Apr[Category],"Other")+SUMIFS(TxnTbl_Apr[Amount],TxnTbl_Apr[Category],"Other") -> 0
N27: Groceries | O27: =SUMIFS(BillsTbl_Apr[Actual],BillsTbl_Apr[Category],"Groceries")+SUMIFS(TxnTbl_Apr[Amount],TxnTbl_Apr[Category],"Groceries") -> 0
N28: Dining out | O28: =SUMIFS(BillsTbl_Apr[Actual],BillsTbl_Apr[Category],"Dining out")+SUMIFS(TxnTbl_Apr[Amount],TxnTbl_Apr[Category],"Dining out") -> 0
N29: Rent | O29: =SUMIFS(BillsTbl_Apr[Actual],BillsTbl_Apr[Category],"Rent")+SUMIFS(TxnTbl_Apr[Amount],TxnTbl_Apr[Category],"Rent") -> 0
N30: Shopping | O30: =SUMIFS(BillsTbl_Apr[Actual],BillsTbl_Apr[Category],"Shopping")+SUMIFS(TxnTbl_Apr[Amount],TxnTbl_Apr[Category],"Shopping") -> 0
N31: Credit Card | O31: =SUMIFS(BillsTbl_Apr[Actual],BillsTbl_Apr[Category],"Credit Card")+SUMIFS(TxnTbl_Apr[Amount],TxnTbl_Apr[Category],"Credit Card") -> 0
B32: Budget Split | C32: 50/30/20
B33: Needs Target | C33: =IF(C32="50/30/20",B6*0.5,IF(C32="70/20/10",B6*0.7,0)) -> 0
B34: Wants Target | C34: =IF(C32="50/30/20",B6*0.3,IF(C32="70/20/10",B6*0.2,0)) -> 0
B35: Savings Target | C35: =IF(C32="50/30/20",B6*0.2,IF(C32="70/20/10",B6*0.1,0)) -> 0
B37: Recurring Bills
B38: Bill Name | C38: Category | D38: Amount | E38: Paid? | F38: Actual
F39: =IF(E39=TRUE(),D39,0) -> 0
F40: =IF(E40=TRUE(),D40,0) -> 0
F41: =IF(E41=TRUE(),D41,0) -> 0
F42: =IF(E42=TRUE(),D42,0) -> 0
F43: =IF(E43=TRUE(),D43,0) -> 0
F44: =IF(E44=TRUE(),D44,0) -> 0
F45: =IF(E45=TRUE(),D45,0) -> 0
F46: =IF(E46=TRUE(),D46,0) -> 0
F47: =IF(E47=TRUE(),D47,0) -> 0
F48: =IF(E48=TRUE(),D48,0) -> 0
F49: =IF(E49=TRUE(),D49,0) -> 0
F50: =IF(E50=TRUE(),D50,0) -> 0
B53: Savings & Investments
B54: Account | C54: Amount

Sheet May
B1: MAY
B5: Total Income | D5: Total Spent | F5: Leftover | H5: Savings Rate | J5: Bills Paid | Q5: Spending Breakdown | U5: Budgeted | V5: Actual
B6: =SUM(IncomeTbl_May[Amount]) -> 0 | D6: =R6+R7 -> 0 | F6: =B6-D6 -> 0 | H6: =IFERROR(R8/B6,0) -> 0 | J6: =COUNTIF(BillsTbl_May[Paid?],TRUE())&" / "&COUNTA(BillsTbl_May[Bill Name]) -> 0 / 0 | Q6: Needs Actual | R6: =O31+O27+O25+O29 -> 0 | T6: Needs | U6: =C33 -> 0 | V6: =R6 -> 0
Q7: Wants Actual | R7: =O26+O28+O24+O30 -> 0 | T7: Wants | U7: =C34 -> 0 | V7: =R7 -> 0
Q8: Savings Actual | R8: =SUM(SavingsTbl_May[Amount]) -> 0 | T8: Savings | U8: =C35 -> 0 | V8: =R8 -> 0
Q9: Total Spent | R9: =R6+R7 -> 0
B22: Income | I22: Transactions Log | N22: Category Totals
B23: Source | C23: Amount | I23: Date | J23: Category | K23: Amount | L23: Notes | N23: Category | O23: Total
N24: Subscriptions | O24: =SUMIFS(BillsTbl_May[Actual],BillsTbl_May[Category],"Subscriptions")+SUMIFS(TxnTbl_May[Amount],TxnTbl_May[Category],"Subscriptions") -> 0
N25: Gas | O25: =SUMIFS(BillsTbl_May[Actual],BillsTbl_May[Category],"Gas")+SUMIFS(TxnTbl_May[Amount],TxnTbl_May[Category],"Gas") -> 0
N26: Other | O26: =SUMIFS(BillsTbl_May[Actual],BillsTbl_May[Category],"Other")+SUMIFS(TxnTbl_May[Amount],TxnTbl_May[Category],"Other") -> 0
N27: Groceries | O27: =SUMIFS(BillsTbl_May[Actual],BillsTbl_May[Category],"Groceries")+SUMIFS(TxnTbl_May[Amount],TxnTbl_May[Category],"Groceries") -> 0
N28: Dining out | O28: =SUMIFS(BillsTbl_May[Actual],BillsTbl_May[Category],"Dining out")+SUMIFS(TxnTbl_May[Amount],TxnTbl_May[Category],"Dining out") -> 0
N29: Rent | O29: =SUMIFS(BillsTbl_May[Actual],BillsTbl_May[Category],"Rent")+SUMIFS(TxnTbl_May[Amount],TxnTbl_May[Category],"Rent") -> 0
N30: Shopping | O30: =SUMIFS(BillsTbl_May[Actual],BillsTbl_May[Category],"Shopping")+SUMIFS(TxnTbl_May[Amount],TxnTbl_May[Category],"Shopping") -> 0
N31: Credit Card | O31: =SUMIFS(BillsTbl_May[Actual],BillsTbl_May[Category],"Credit Card")+SUMIFS(TxnTbl_May[Amount],TxnTbl_May[Category],"Credit Card") -> 0
B32: Budget Split | C32: 50/30/20
B33: Needs Target | C33: =IF(C32="50/30/20",B6*0.5,IF(C32="70/20/10",B6*0.7,0)) -> 0
B34: Wants Target | C34: =IF(C32="50/30/20",B6*0.3,IF(C32="70/20/10",B6*0.2,0)) -> 0
B35: Savings Target | C35: =IF(C32="50/30/20",B6*0.2,IF(C32="70/20/10",B6*0.1,0)) -> 0
B37: Recurring Bills
B38: Bill Name | C38: Category | D38: Amount | E38: Paid? | F38: Actual
F39: =IF(E39=TRUE(),D39,0) -> 0
F40: =IF(E40=TRUE(),D40,0) -> 0
F41: =IF(E41=TRUE(),D41,0) -> 0
F42: =IF(E42=TRUE(),D42,0) -> 0
F43: =IF(E43=TRUE(),D43,0) -> 0
F44: =IF(E44=TRUE(),D44,0) -> 0
F45: =IF(E45=TRUE(),D45,0) -> 0
F46: =IF(E46=TRUE(),D46,0) -> 0
F47: =IF(E47=TRUE(),D47,0) -> 0
F48: =IF(E48=TRUE(),D48,0) -> 0
F49: =IF(E49=TRUE(),D49,0) -> 0
F50: =IF(E50=TRUE(),D50,0) -> 0
B53: Savings & Investments
B54: Account | C54: Amount

Sheet Jun
B1: JUNE
B5: Total Income | D5: Total Spent | F5: Leftover | H5: Savings Rate | J5: Bills Paid | Q5: Spending Breakdown | U5: Budgeted | V5: Actual
B6: =SUM(IncomeTbl_Jun[Amount]) -> 0 | D6: =R6+R7 -> 0 | F6: =B6-D6 -> 0 | H6: =IFERROR(R8/B6,0) -> 0 | J6: =COUNTIF(BillsTbl_Jun[Paid?],TRUE())&" / "&COUNTA(BillsTbl_Jun[Bill Name]) -> 0 / 0 | Q6: Needs Actual | R6: =O31+O27+O25+O29 -> 0 | T6: Needs | U6: =C33 -> 0 | V6: =R6 -> 0
Q7: Wants Actual | R7: =O26+O28+O24+O30 -> 0 | T7: Wants | U7: =C34 -> 0 | V7: =R7 -> 0
Q8: Savings Actual | R8: =SUM(SavingsTbl_Jun[Amount]) -> 0 | T8: Savings | U8: =C35 -> 0 | V8: =R8 -> 0
Q9: Total Spent | R9: =R6+R7 -> 0
B22: Income | I22: Transactions Log | N22: Category Totals
B23: Source | C23: Amount | I23: Date | J23: Category | K23: Amount | L23: Notes | N23: Category | O23: Total
N24: Subscriptions | O24: =SUMIFS(BillsTbl_Jun[Actual],BillsTbl_Jun[Category],"Subscriptions")+SUMIFS(TxnTbl_Jun[Amount],TxnTbl_Jun[Category],"Subscriptions") -> 0
N25: Gas | O25: =SUMIFS(BillsTbl_Jun[Actual],BillsTbl_Jun[Category],"Gas")+SUMIFS(TxnTbl_Jun[Amount],TxnTbl_Jun[Category],"Gas") -> 0
N26: Other | O26: =SUMIFS(BillsTbl_Jun[Actual],BillsTbl_Jun[Category],"Other")+SUMIFS(TxnTbl_Jun[Amount],TxnTbl_Jun[Category],"Other") -> 0
N27: Groceries | O27: =SUMIFS(BillsTbl_Jun[Actual],BillsTbl_Jun[Category],"Groceries")+SUMIFS(TxnTbl_Jun[Amount],TxnTbl_Jun[Category],"Groceries") -> 0
N28: Dining out | O28: =SUMIFS(BillsTbl_Jun[Actual],BillsTbl_Jun[Category],"Dining out")+SUMIFS(TxnTbl_Jun[Amount],TxnTbl_Jun[Category],"Dining out") -> 0
N29: Rent | O29: =SUMIFS(BillsTbl_Jun[Actual],BillsTbl_Jun[Category],"Rent")+SUMIFS(TxnTbl_Jun[Amount],TxnTbl_Jun[Category],"Rent") -> 0
N30: Shopping | O30: =SUMIFS(BillsTbl_Jun[Actual],BillsTbl_Jun[Category],"Shopping")+SUMIFS(TxnTbl_Jun[Amount],TxnTbl_Jun[Category],"Shopping") -> 0
N31: Credit Card | O31: =SUMIFS(BillsTbl_Jun[Actual],BillsTbl_Jun[Category],"Credit Card")+SUMIFS(TxnTbl_Jun[Amount],TxnTbl_Jun[Category],"Credit Card") -> 0
B32: Budget Split | C32: 50/30/20
B33: Needs Target | C33: =IF(C32="50/30/20",B6*0.5,IF(C32="70/20/10",B6*0.7,0)) -> 0
B34: Wants Target | C34: =IF(C32="50/30/20",B6*0.3,IF(C32="70/20/10",B6*0.2,0)) -> 0
B35: Savings Target | C35: =IF(C32="50/30/20",B6*0.2,IF(C32="70/20/10",B6*0.1,0)) -> 0
B37: Recurring Bills
B38: Bill Name | C38: Category | D38: Amount | E38: Paid? | F38: Actual
F39: =IF(E39=TRUE(),D39,0) -> 0
F40: =IF(E40=TRUE(),D40,0) -> 0
F41: =IF(E41=TRUE(),D41,0) -> 0
F42: =IF(E42=TRUE(),D42,0) -> 0
F43: =IF(E43=TRUE(),D43,0) -> 0
F44: =IF(E44=TRUE(),D44,0) -> 0
F45: =IF(E45=TRUE(),D45,0) -> 0
F46: =IF(E46=TRUE(),D46,0) -> 0
F47: =IF(E47=TRUE(),D47,0) -> 0
F48: =IF(E48=TRUE(),D48,0) -> 0
F49: =IF(E49=TRUE(),D49,0) -> 0
F50: =IF(E50=TRUE(),D50,0) -> 0
B53: Savings & Investments
B54: Account | C54: Amount

Sheet Jul
B1: JULY
B5: Total Income | D5: Total Spent | F5: Leftover | H5: Savings Rate | J5: Bills Paid | Q5: Spending Breakdown | U5: Budgeted | V5: Actual
B6: =SUM(IncomeTbl_Jul[Amount]) -> 0 | D6: =R6+R7 -> 0 | F6: =B6-D6 -> 0 | H6: =IFERROR(R8/B6,0) -> 0 | J6: =COUNTIF(BillsTbl_Jul[Paid?],TRUE())&" / "&COUNTA(BillsTbl_Jul[Bill Name]) -> 0 / 0 | Q6: Needs Actual | R6: =O31+O27+O25+O29 -> 0 | T6: Needs | U6: =C33 -> 0 | V6: =R6 -> 0
Q7: Wants Actual | R7: =O26+O28+O24+O30 -> 0 | T7: Wants | U7: =C34 -> 0 | V7: =R7 -> 0
Q8: Savings Actual | R8: =SUM(SavingsTbl_Jul[Amount]) -> 0 | T8: Savings | U8: =C35 -> 0 | V8: =R8 -> 0
Q9: Total Spent | R9: =R6+R7 -> 0
B22: Income | I22: Transactions Log | N22: Category Totals
B23: Source | C23: Amount | I23: Date | J23: Category | K23: Amount | L23: Notes | N23: Category | O23: Total
N24: Subscriptions | O24: =SUMIFS(BillsTbl_Jul[Actual],BillsTbl_Jul[Category],"Subscriptions")+SUMIFS(TxnTbl_Jul[Amount],TxnTbl_Jul[Category],"Subscriptions") -> 0
N25: Gas | O25: =SUMIFS(BillsTbl_Jul[Actual],BillsTbl_Jul[Category],"Gas")+SUMIFS(TxnTbl_Jul[Amount],TxnTbl_Jul[Category],"Gas") -> 0
N26: Other | O26: =SUMIFS(BillsTbl_Jul[Actual],BillsTbl_Jul[Category],"Other")+SUMIFS(TxnTbl_Jul[Amount],TxnTbl_Jul[Category],"Other") -> 0
N27: Groceries | O27: =SUMIFS(BillsTbl_Jul[Actual],BillsTbl_Jul[Category],"Groceries")+SUMIFS(TxnTbl_Jul[Amount],TxnTbl_Jul[Category],"Groceries") -> 0
N28: Dining out | O28: =SUMIFS(BillsTbl_Jul[Actual],BillsTbl_Jul[Category],"Dining out")+SUMIFS(TxnTbl_Jul[Amount],TxnTbl_Jul[Category],"Dining out") -> 0
N29: Rent | O29: =SUMIFS(BillsTbl_Jul[Actual],BillsTbl_Jul[Category],"Rent")+SUMIFS(TxnTbl_Jul[Amount],TxnTbl_Jul[Category],"Rent") -> 0
N30: Shopping | O30: =SUMIFS(BillsTbl_Jul[Actual],BillsTbl_Jul[Category],"Shopping")+SUMIFS(TxnTbl_Jul[Amount],TxnTbl_Jul[Category],"Shopping") -> 0
N31: Credit Card | O31: =SUMIFS(BillsTbl_Jul[Actual],BillsTbl_Jul[Category],"Credit Card")+SUMIFS(TxnTbl_Jul[Amount],TxnTbl_Jul[Category],"Credit Card") -> 0
B32: Budget Split | C32: 50/30/20
B33: Needs Target | C33: =IF(C32="50/30/20",B6*0.5,IF(C32="70/20/10",B6*0.7,0)) -> 0
B34: Wants Target | C34: =IF(C32="50/30/20",B6*0.3,IF(C32="70/20/10",B6*0.2,0)) -> 0
B35: Savings Target | C35: =IF(C32="50/30/20",B6*0.2,IF(C32="70/20/10",B6*0.1,0)) -> 0
B37: Recurring Bills
B38: Bill Name | C38: Category | D38: Amount | E38: Paid? | F38: Actual
F39: =IF(E39=TRUE(),D39,0) -> 0
F40: =IF(E40=TRUE(),D40,0) -> 0
F41: =IF(E41=TRUE(),D41,0) -> 0
F42: =IF(E42=TRUE(),D42,0) -> 0
F43: =IF(E43=TRUE(),D43,0) -> 0
F44: =IF(E44=TRUE(),D44,0) -> 0
F45: =IF(E45=TRUE(),D45,0) -> 0
F46: =IF(E46=TRUE(),D46,0) -> 0
F47: =IF(E47=TRUE(),D47,0) -> 0
F48: =IF(E48=TRUE(),D48,0) -> 0
F49: =IF(E49=TRUE(),D49,0) -> 0
F50: =IF(E50=TRUE(),D50,0) -> 0
B53: Savings & Investments
B54: Account | C54: Amount

Sheet Aug
B1: AUGUST
B5: Total Income | D5: Total Spent | F5: Leftover | H5: Savings Rate | J5: Bills Paid | Q5: Spending Breakdown | U5: Budgeted | V5: Actual
B6: =SUM(IncomeTbl_Aug[Amount]) -> 2654.27 | D6: =R6+R7 -> 1937.27 | F6: =B6-D6 -> 717 | H6: =IFERROR(R8/B6,0) -> 0.2553056 | J6: =COUNTIF(BillsTbl_Aug[Paid?],TRUE())&" / "&COUNTA(BillsTbl_Aug[Bill Name]) -> 6 / 6 | Q6: Needs Actual | R6: =O31+O27+O25+O29 -> 981.61 | T6: Needs | U6: =C33 -> 1327.135 | V6: =R6 -> 981.61
Q7: Wants Actual | R7: =O26+O28+O24+O30 -> 955.66 | T7: Wants | U7: =C34 -> 796.281 | V7: =R7 -> 955.66
Q8: Savings Actual | R8: =SUM(SavingsTbl_Aug[Amount]) -> 677.65 | T8: Savings | U8: =C35 -> 530.854 | V8: =R8 -> 677.65
Q9: Total Spent | R9: =R6+R7 -> 1937.27
B22: Income | I22: Transactions Log | N22: Category Totals
B23: Source | C23: Amount | I23: Date | J23: Category | K23: Amount | L23: Notes | N23: Category | O23: Total
B24: Starbucks Pay (W1) | C24: 1243.06 | I24: 45871 | J24: Other | K24: 4.95 | N24: Subscriptions | O24: =SUMIFS(BillsTbl_Aug[Actual],BillsTbl_Aug[Category],"Subscriptions")+SUMIFS(TxnTbl_Aug[Amount],TxnTbl_Aug[Category],"Subscriptions") -> 57.31
B25: Starbucks Pay (W2) | C25: 1276.72 | I25: 45872 | J25: Dining out | K25: 5.11 | N25: Gas | O25: =SUMIFS(BillsTbl_Aug[Actual],BillsTbl_Aug[Category],"Gas")+SUMIFS(TxnTbl_Aug[Amount],TxnTbl_Aug[Category],"Gas") -> 61.61
B26: Recurring | C26: 66.49 | I26: 45875 | J26: Gas | K26: 21.36 | N26: Other | O26: =SUMIFS(BillsTbl_Aug[Actual],BillsTbl_Aug[Category],"Other")+SUMIFS(TxnTbl_Aug[Amount],TxnTbl_Aug[Category],"Other") -> 482.41
B27: Misc | C27: 68 | I27: 45876 | J27: Shopping | K27: 103.92 | L27: Lululemon for Jackie | N27: Groceries | O27: =SUMIFS(BillsTbl_Aug[Actual],BillsTbl_Aug[Category],"Groceries")+SUMIFS(TxnTbl_Aug[Amount],TxnTbl_Aug[Category],"Groceries") -> 70
I28: 45876 | J28: Dining out | K28: 13.63 | L28: Japanese Food | N28: Dining out | O28: =SUMIFS(BillsTbl_Aug[Actual],BillsTbl_Aug[Category],"Dining out")+SUMIFS(TxnTbl_Aug[Amount],TxnTbl_Aug[Category],"Dining out") -> 168.91
I29: 45877 | J29: Other | K29: 5.39 | N29: Rent | O29: =SUMIFS(BillsTbl_Aug[Actual],BillsTbl_Aug[Category],"Rent")+SUMIFS(TxnTbl_Aug[Amount],TxnTbl_Aug[Category],"Rent") -> 650
I30: 45877 | J30: Dining out | K30: 10 | L30: Bakery | N30: Shopping | O30: =SUMIFS(BillsTbl_Aug[Actual],BillsTbl_Aug[Category],"Shopping")+SUMIFS(TxnTbl_Aug[Amount],TxnTbl_Aug[Category],"Shopping") -> 247.03
I31: 45877 | J31: Dining out | K31: 8.66 | L31: Lemonade | N31: Credit Card | O31: =SUMIFS(BillsTbl_Aug[Actual],BillsTbl_Aug[Category],"Credit Card")+SUMIFS(TxnTbl_Aug[Amount],TxnTbl_Aug[Category],"Credit Card") -> 200
B32: Budget Split | C32: 50/30/20 | I32: 45878 | J32: Dining out | K32: 2.61
B33: Needs Target | C33: =IF(C32="50/30/20",B6*0.5,IF(C32="70/20/10",B6*0.7,0)) -> 1327.135 | I33: 45879 | J33: Other | K33: 10.81
B34: Wants Target | C34: =IF(C32="50/30/20",B6*0.3,IF(C32="70/20/10",B6*0.2,0)) -> 796.281 | I34: 45880 | J34: Dining out | K34: 1.46 | L34: Whataburger
B35: Savings Target | C35: =IF(C32="50/30/20",B6*0.2,IF(C32="70/20/10",B6*0.1,0)) -> 530.854 | I35: 45880 | J35: Dining out | K35: 6.23 | L35: Snacks
I36: 45883 | J36: Dining out | K36: 9.16 | L36: Starbucks
B37: Recurring Bills | I37: 45884 | J37: Other | K37: 15 | L37: Luna's Shots
B38: Bill Name | C38: Category | D38: Amount | E38: Paid? | F38: Actual | I38: 45886 | J38: Dining out | K38: 5.41 | L38: McDonalds
B39: Rent | C39: Rent | D39: 650 | E39: =TRUE() -> TRUE | F39: =IF(E39=TRUE(),D39,0) -> 650 | I39: 45888 | J39: Gas | K39: 10
B40: Credit Card Payment | C40: Credit Card | D40: 200 | E40: =TRUE() -> TRUE | F40: =IF(E40=TRUE(),D40,0) -> 200 | I40: 45889 | J40: Groceries | K40: 70 | L40: Sent to Arianna
B41: HBO Max | C41: Subscriptions | D41: 5.39 | E41: =TRUE() -> TRUE | F41: =IF(E41=TRUE(),D41,0) -> 5.39 | I41: 45891 | J41: Shopping | K41: 19.03
B42: Gym (need to downgrade) | C42: Subscriptions | D42: 40.04 | E42: =TRUE() -> TRUE | F42: =IF(E42=TRUE(),D42,0) -> 40.04 | I42: 45890 | J42: Dining out | K42: 2 | L42: Starbucks
B43: Apple Music | C43: Subscriptions | D43: 6.48 | E43: =TRUE() -> TRUE | F43: =IF(E43=TRUE(),D43,0) -> 6.48 | I43: 45891 | J43: Shopping | K43: 19.03 | L43: Walmart
B44: Ring Camera Membership | C44: Subscriptions | D44: 5.4 | E44: =TRUE() -> TRUE | F44: =IF(E44=TRUE(),D44,0) -> 5.4 | I44: 45891 | J44: Gas | K44: 30.25
F45: =IF(E45=TRUE(),D45,0) -> 0 | I45: 45892 | J45: Other | K45: 330.64 | L45: Jackie's Laptop
F46: =IF(E46=TRUE(),D46,0) -> 0 | I46: 45892 | J46: Shopping | K46: 18.16 | L46: Target
F47: =IF(E47=TRUE(),D47,0) -> 0 | I47: 45892 | J47: Shopping | K47: 22 | L47: Walmart
F48: =IF(E48=TRUE(),D48,0) -> 0 | I48: 45893 | J48: Dining out | K48: 2 | L48: Starbucks
F49: =IF(E49=TRUE(),D49,0) -> 0 | I49: 45893 | J49: Dining out | K49: 16.54 | L49: Dairy Queen
F50: =IF(E50=TRUE(),D50,0) -> 0 | I50: 45894 | J50: Dining out | K50: 10.81 | L50: Whataburger
I51: 45895 | J51: Dining out | K51: 6.47 | L51: Sonic
I52: 45895 | J52: Dining out | K52: 9.18 | L52: Sonic
B53: Savings & Investments | I53: 45895 | J53: Other | K53: 34.64 | L53: Textbook (1)
B54: Account | C54: Amount | I54: 45896 | J54: Dining out | K54: 9.93 | L54: Coffee
B55: 401K | C55: 150 | I55: 45897 | J55: Other | K55: 32.46 | L55: Textbook (2)
...

Sheet Sep
B1: SEPTEMBER
B5: Total Income | D5: Total Spent | F5: Leftover | H5: Savings Rate | J5: Bills Paid | Q5: Spending Breakdown | U5: Budgeted | V5: Actual
B6: =SUM(IncomeTbl_Sep[Amount]) -> 2197.54 | D6: =R6+R7 -> 369.63 | F6: =B6-D6 -> 1827.91 | H6: =IFERROR(R8/B6,0) -> 0.1663997 | J6: =COUNTIF(BillsTbl_Sep[Paid?],TRUE())&" / "&COUNTA(BillsTbl_Sep[Bill Name]) -> 2 / 5 | Q6: Needs Actual | R6: =O31+O27+O25+O29 -> 232.24 | T6: Needs | U6: =C33 -> 1098.77 | V6: =R6 -> 232.24
Q7: Wants Actual | R7: =O26+O28+O24+O30 -> 137.39 | T7: Wants | U7: =C34 -> 659.262 | V7: =R7 -> 137.39
Q8: Savings Actual | R8: =SUM(SavingsTbl_Sep[Amount]) -> 365.67 | T8: Savings | U8: =C35 -> 439.508 | V8: =R8 -> 365.67
Q9: Total Spent | R9: =R6+R7 -> 369.63
B22: Income | I22: Transactions Log | N22: Category Totals
B23: Source | C23: Amount | I23: Date | J23: Category | K23: Amount | L23: Notes | N23: Category | O23: Total
B24: Starbucks Pay | C24: 1193.34 | I24: 45901 | J24: Shopping | K24: 24.33 | L24: Petco | N24: Subscriptions | O24: =SUMIFS(BillsTbl_Sep[Actual],BillsTbl_Sep[Category],"Subscriptions")+SUMIFS(TxnTbl_Sep[Amount],TxnTbl_Sep[Category],"Subscriptions") -> 6.48
B25: Recurring | C25: 135 | I25: 45902 | J25: Other | K25: 55.04 | L25: Gym | N25: Gas | O25: =SUMIFS(BillsTbl_Sep[Actual],BillsTbl_Sep[Category],"Gas")+SUMIFS(TxnTbl_Sep[Amount],TxnTbl_Sep[Category],"Gas") -> 32.24
B26: Leftover from August | C26: 869.2 | I26: 45902 | J26: Dining out | K26: 2.61 | L26: Starbucks | N26: Other | O26: =SUMIFS(BillsTbl_Sep[Actual],BillsTbl_Sep[Category],"Other")+SUMIFS(TxnTbl_Sep[Amount],TxnTbl_Sep[Category],"Other") -> 55.04
I27: 45902 | J27: Dining out | K27: 9.77 | L27: Chickfila | N27: Groceries | O27: =SUMIFS(BillsTbl_Sep[Actual],BillsTbl_Sep[Category],"Groceries")+SUMIFS(TxnTbl_Sep[Amount],TxnTbl_Sep[Category],"Groceries") -> 0
I28: 45902 | J28: Dining out | K28: 2.76 | L28: Starbucks | N28: Dining out | O28: =SUMIFS(BillsTbl_Sep[Actual],BillsTbl_Sep[Category],"Dining out")+SUMIFS(TxnTbl_Sep[Amount],TxnTbl_Sep[Category],"Dining out") -> 51.54
I29: 45902 | J29: Dining out | K29: 7.53 | L29: Starbucks | N29: Rent | O29: =SUMIFS(BillsTbl_Sep[Actual],BillsTbl_Sep[Category],"Rent")+SUMIFS(TxnTbl_Sep[Amount],TxnTbl_Sep[Category],"Rent") -> 0
I30: 45903 | J30: Dining out | K30: 21.16 | L30: BBQ | N30: Shopping | O30: =SUMIFS(BillsTbl_Sep[Actual],BillsTbl_Sep[Category],"Shopping")+SUMIFS(TxnTbl_Sep[Amount],TxnTbl_Sep[Category],"Shopping") -> 24.33
I31: 45903 | J31: Dining out | K31: 7.71 | L31: Coffee | N31: Credit Card | O31: =SUMIFS(BillsTbl_Sep[Actual],BillsTbl_Sep[Category],"Credit Card")+SUMIFS(TxnTbl_Sep[Amount],TxnTbl_Sep[Category],"Credit Card") -> 200
B32: Budget Split | C32: 50/30/20 | I32: 45903 | J32: Gas | K32: 32.24
B33: Needs Target | C33: =IF(C32="50/30/20",B6*0.5,IF(C32="70/20/10",B6*0.7,0)) -> 1098.77
B34: Wants Target | C34: =IF(C32="50/30/20",B6*0.3,IF(C32="70/20/10",B6*0.2,0)) -> 659.262
B35: Savings Target | C35: =IF(C32="50/30/20",B6*0.2,IF(C32="70/20/10",B6*0.1,0)) -> 439.508
B37: Recurring Bills
B38: Bill Name | C38: Category | D38: Amount | E38: Paid? | F38: Actual
B39: Rent | C39: Rent | D39: 650 | E39: =FALSE() -> FALSE | F39: =IF(E39=TRUE(),D39,0) -> 0
B40: Credit Card Payment | C40: Credit Card | D40: 200 | E40: =TRUE() -> TRUE | F40: =IF(E40=TRUE(),D40,0) -> 200
B41: HBO Max | C41: Subscriptions | D41: 5.39 | E41: =FALSE() -> FALSE | F41: =IF(E41=TRUE(),D41,0) -> 0
B42: Gym | C42: Subscriptions | D42: 40.04 | E42: =FALSE() -> FALSE | F42: =IF(E42=TRUE(),D42,0) -> 0
B43: Apple Music | C43: Subscriptions | D43: 6.48 | E43: =TRUE() -> TRUE | F43: =IF(E43=TRUE(),D43,0) -> 6.48
F44: =IF(E44=TRUE(),D44,0) -> 0
F45: =IF(E45=TRUE(),D45,0) -> 0
F46: =IF(E46=TRUE(),D46,0) -> 0
F47: =IF(E47=TRUE(),D47,0) -> 0
F48: =IF(E48=TRUE(),D48,0) -> 0
F49: =IF(E49=TRUE(),D49,0) -> 0
F50: =IF(E50=TRUE(),D50,0) -> 0
B53: Savings & Investments
B54: Account | C54: Amount
B55: Savings Account | C55: 265.67
B56: Roth IRA | C56: 100

Sheet Oct
B1: OCTOBER
B5: Total Income | D5: Total Spent | F5: Leftover | H5: Savings Rate | J5: Bills Paid | Q5: Spending Breakdown | U5: Budgeted | V5: Actual
B6: =SUM(IncomeTbl_Oct[Amount]) -> 0 | D6: =R6+R7 -> 0 | F6: =B6-D6 -> 0 | H6: =IFERROR(R8/B6,0) -> 0 | J6: =COUNTIF(BillsTbl_Oct[Paid?],TRUE())&" / "&COUNTA(BillsTbl_Oct[Bill Name]) -> 0 / 0 | Q6: Needs Actual | R6: =O31+O27+O25+O29 -> 0 | T6: Needs | U6: =C33 -> 0 | V6: =R6 -> 0
Q7: Wants Actual | R7: =O26+O28+O24+O30 -> 0 | T7: Wants | U7: =C34 -> 0 | V7: =R7 -> 0
Q8: Savings Actual | R8: =SUM(SavingsTbl_Oct[Amount]) -> 0 | T8: Savings | U8: =C35 -> 0 | V8: =R8 -> 0
Q9: Total Spent | R9: =R6+R7 -> 0
B22: Income | I22: Transactions Log | N22: Category Totals
B23: Source | C23: Amount | I23: Date | J23: Category | K23: Amount | L23: Notes | N23: Category | O23: Total
N24: Subscriptions | O24: =SUMIFS(BillsTbl_Oct[Actual],BillsTbl_Oct[Category],"Subscriptions")+SUMIFS(TxnTbl_Oct[Amount],TxnTbl_Oct[Category],"Subscriptions") -> 0
N25: Gas | O25: =SUMIFS(BillsTbl_Oct[Actual],BillsTbl_Oct[Category],"Gas")+SUMIFS(TxnTbl_Oct[Amount],TxnTbl_Oct[Category],"Gas") -> 0
N26: Other | O26: =SUMIFS(BillsTbl_Oct[Actual],BillsTbl_Oct[Category],"Other")+SUMIFS(TxnTbl_Oct[Amount],TxnTbl_Oct[Category],"Other") -> 0
N27: Groceries | O27: =SUMIFS(BillsTbl_Oct[Actual],BillsTbl_Oct[Category],"Groceries")+SUMIFS(TxnTbl_Oct[Amount],TxnTbl_Oct[Category],"Groceries") -> 0
N28: Dining out | O28: =SUMIFS(BillsTbl_Oct[Actual],BillsTbl_Oct[Category],"Dining out")+SUMIFS(TxnTbl_Oct[Amount],TxnTbl_Oct[Category],"Dining out") -> 0
N29: Rent | O29: =SUMIFS(BillsTbl_Oct[Actual],BillsTbl_Oct[Category],"Rent")+SUMIFS(TxnTbl_Oct[Amount],TxnTbl_Oct[Category],"Rent") -> 0
N30: Shopping | O30: =SUMIFS(BillsTbl_Oct[Actual],BillsTbl_Oct[Category],"Shopping")+SUMIFS(TxnTbl_Oct[Amount],TxnTbl_Oct[Category],"Shopping") -> 0
N31: Credit Card | O31: =SUMIFS(BillsTbl_Oct[Actual],BillsTbl_Oct[Category],"Credit Card")+SUMIFS(TxnTbl_Oct[Amount],TxnTbl_Oct[Category],"Credit Card") -> 0
B32: Budget Split | C32: 50/30/20
B33: Needs Target | C33: =IF(C32="50/30/20",B6*0.5,IF(C32="70/20/10",B6*0.7,0)) -> 0
B34: Wants Target | C34: =IF(C32="50/30/20",B6*0.3,IF(C32="70/20/10",B6*0.2,0)) -> 0
B35: Savings Target | C35: =IF(C32="50/30/20",B6*0.2,IF(C32="70/20/10",B6*0.1,0)) -> 0
B37: Recurring Bills
B38: Bill Name | C38: Category | D38: Amount | E38: Paid? | F38: Actual
F39: =IF(E39=TRUE(),D39,0) -> 0
F40: =IF(E40=TRUE(),D40,0) -> 0
F41: =IF(E41=TRUE(),D41,0) -> 0
F42: =IF(E42=TRUE(),D42,0) -> 0
F43: =IF(E43=TRUE(),D43,0) -> 0
F44: =IF(E44=TRUE(),D44,0) -> 0
F45: =IF(E45=TRUE(),D45,0) -> 0
F46: =IF(E46=TRUE(),D46,0) -> 0
F47: =IF(E47=TRUE(),D47,0) -> 0
F48: =IF(E48=TRUE(),D48,0) -> 0
F49: =IF(E49=TRUE(),D49,0) -> 0
F50: =IF(E50=TRUE(),D50,0) -> 0
B53: Savings & Investments
B54: Account | C54: Amount

Sheet Nov
B1: NOVEMBER
B5: Total Income | D5: Total Spent | F5: Leftover | H5: Savings Rate | J5: Bills Paid | Q5: Spending Breakdown | U5: Budgeted | V5: Actual
B6: =SUM(IncomeTbl_Nov[Amount]) -> 0 | D6: =R6+R7 -> 0 | F6: =B6-D6 -> 0 | H6: =IFERROR(R8/B6,0) -> 0 | J6: =COUNTIF(BillsTbl_Nov[Paid?],TRUE())&" / "&COUNTA(BillsTbl_Nov[Bill Name]) -> 0 / 0 | Q6: Needs Actual | R6: =O31+O27+O25+O29 -> 0 | T6: Needs | U6: =C33 -> 0 | V6: =R6 -> 0
Q7: Wants Actual | R7: =O26+O28+O24+O30 -> 0 | T7: Wants | U7: =C34 -> 0 | V7: =R7 -> 0
Q8: Savings Actual | R8: =SUM(SavingsTbl_Nov[Amount]) -> 0 | T8: Savings | U8: =C35 -> 0 | V8: =R8 -> 0
Q9: Total Spent | R9: =R6+R7 -> 0
B22: Income | I22: Transactions Log | N22: Category Totals
B23: Source | C23: Amount | I23: Date | J23: Category | K23: Amount | L23: Notes | N23: Category | O23: Total
N24: Subscriptions | O24: =SUMIFS(BillsTbl_Nov[Actual],BillsTbl_Nov[Category],"Subscriptions")+SUMIFS(TxnTbl_Nov[Amount],TxnTbl_Nov[Category],"Subscriptions") -> 0
N25: Gas | O25: =SUMIFS(BillsTbl_Nov[Actual],BillsTbl_Nov[Category],"Gas")+SUMIFS(TxnTbl_Nov[Amount],TxnTbl_Nov[Category],"Gas") -> 0
N26: Other | O26: =SUMIFS(BillsTbl_Nov[Actual],BillsTbl_Nov[Category],"Other")+SUMIFS(TxnTbl_Nov[Amount],TxnTbl_Nov[Category],"Other") -> 0
N27: Groceries | O27: =SUMIFS(BillsTbl_Nov[Actual],BillsTbl_Nov[Category],"Groceries")+SUMIFS(TxnTbl_Nov[Amount],TxnTbl_Nov[Category],"Groceries") -> 0
N28: Dining out | O28: =SUMIFS(BillsTbl_Nov[Actual],BillsTbl_Nov[Category],"Dining out")+SUMIFS(TxnTbl_Nov[Amount],TxnTbl_Nov[Category],"Dining out") -> 0
N29: Rent | O29: =SUMIFS(BillsTbl_Nov[Actual],BillsTbl_Nov[Category],"Rent")+SUMIFS(TxnTbl_Nov[Amount],TxnTbl_Nov[Category],"Rent") -> 0
N30: Shopping | O30: =SUMIFS(BillsTbl_Nov[Actual],BillsTbl_Nov[Category],"Shopping")+SUMIFS(TxnTbl_Nov[Amount],TxnTbl_Nov[Category],"Shopping") -> 0
N31: Credit Card | O31: =SUMIFS(BillsTbl_Nov[Actual],BillsTbl_Nov[Category],"Credit Card")+SUMIFS(TxnTbl_Nov[Amount],TxnTbl_Nov[Category],"Credit Card") -> 0
B32: Budget Split | C32: 50/30/20
B33: Needs Target | C33: =IF(C32="50/30/20",B6*0.5,IF(C32="70/20/10",B6*0.7,0)) -> 0
B34: Wants Target | C34: =IF(C32="50/30/20",B6*0.3,IF(C32="70/20/10",B6*0.2,0)) -> 0
B35: Savings Target | C35: =IF(C32="50/30/20",B6*0.2,IF(C32="70/20/10",B6*0.1,0)) -> 0
B37: Recurring Bills
B38: Bill Name | C38: Category | D38: Amount | E38: Paid? | F38: Actual
F39: =IF(E39=TRUE(),D39,0) -> 0
F40: =IF(E40=TRUE(),D40,0) -> 0
F41: =IF(E41=TRUE(),D41,0) -> 0
F42: =IF(E42=TRUE(),D42,0) -> 0
F43: =IF(E43=TRUE(),D43,0) -> 0
F44: =IF(E44=TRUE(),D44,0) -> 0
F45: =IF(E45=TRUE(),D45,0) -> 0
F46: =IF(E46=TRUE(),D46,0) -> 0
F47: =IF(E47=TRUE(),D47,0) -> 0
F48: =IF(E48=TRUE(),D48,0) -> 0
F49: =IF(E49=TRUE(),D49,0) -> 0
F50: =IF(E50=TRUE(),D50,0) -> 0
B53: Savings & Investments
B54: Account | C54: Amount

Sheet Dec
B1: DECEMBER
B5: Total Income | D5: Total Spent | F5: Leftover | H5: Savings Rate | J5: Bills Paid | Q5: Spending Breakdown | U5: Budgeted | V5: Actual
B6: =SUM(IncomeTbl_Dec[Amount]) -> 0 | D6: =R6+R7 -> 0 | F6: =B6-D6 -> 0 | H6: =IFERROR(R8/B6,0) -> 0 | J6: =COUNTIF(BillsTbl_Dec[Paid?],TRUE())&" / "&COUNTA(BillsTbl_Dec[Bill Name]) -> 0 / 0 | Q6: Needs Actual | R6: =O31+O27+O25+O29 -> 0 | T6: Needs | U6: =C33 -> 0 | V6: =R6 -> 0
Q7: Wants Actual | R7: =O26+O28+O24+O30 -> 0 | T7: Wants | U7: =C34 -> 0 | V7: =R7 -> 0
Q8: Savings Actual | R8: =SUM(SavingsTbl_Dec[Amount]) -> 0 | T8: Savings | U8: =C35 -> 0 | V8: =R8 -> 0
Q9: Total Spent | R9: =R6+R7 -> 0
B22: Income | I22: Transactions Log | N22: Category Totals
B23: Source | C23: Amount | I23: Date | J23: Category | K23: Amount | L23: Notes | N23: Category | O23: Total
N24: Subscriptions | O24: =SUMIFS(BillsTbl_Dec[Actual],BillsTbl_Dec[Category],"Subscriptions")+SUMIFS(TxnTbl_Dec[Amount],TxnTbl_Dec[Category],"Subscriptions") -> 0
N25: Gas | O25: =SUMIFS(BillsTbl_Dec[Actual],BillsTbl_Dec[Category],"Gas")+SUMIFS(TxnTbl_Dec[Amount],TxnTbl_Dec[Category],"Gas") -> 0
N26: Other | O26: =SUMIFS(BillsTbl_Dec[Actual],BillsTbl_Dec[Category],"Other")+SUMIFS(TxnTbl_Dec[Amount],TxnTbl_Dec[Category],"Other") -> 0
N27: Groceries | O27: =SUMIFS(BillsTbl_Dec[Actual],BillsTbl_Dec[Category],"Groceries")+SUMIFS(TxnTbl_Dec[Amount],TxnTbl_Dec[Category],"Groceries") -> 0
N28: Dining out | O28: =SUMIFS(BillsTbl_Dec[Actual],BillsTbl_Dec[Category],"Dining out")+SUMIFS(TxnTbl_Dec[Amount],TxnTbl_Dec[Category],"Dining out") -> 0
N29: Rent | O29: =SUMIFS(BillsTbl_Dec[Actual],BillsTbl_Dec[Category],"Rent")+SUMIFS(TxnTbl_Dec[Amount],TxnTbl_Dec[Category],"Rent") -> 0
N30: Shopping | O30: =SUMIFS(BillsTbl_Dec[Actual],BillsTbl_Dec[Category],"Shopping")+SUMIFS(TxnTbl_Dec[Amount],TxnTbl_Dec[Category],"Shopping") -> 0
N31: Credit Card | O31: =SUMIFS(BillsTbl_Dec[Actual],BillsTbl_Dec[Category],"Credit Card")+SUMIFS(TxnTbl_Dec[Amount],TxnTbl_Dec[Category],"Credit Card") -> 0
B32: Budget Split | C32: 50/30/20
B33: Needs Target | C33: =IF(C32="50/30/20",B6*0.5,IF(C32="70/20/10",B6*0.7,0)) -> 0
B34: Wants Target | C34: =IF(C32="50/30/20",B6*0.3,IF(C32="70/20/10",B6*0.2,0)) -> 0
B35: Savings Target | C35: =IF(C32="50/30/20",B6*0.2,IF(C32="70/20/10",B6*0.1,0)) -> 0
B37: Recurring Bills
B38: Bill Name | C38: Category | D38: Amount | E38: Paid? | F38: Actual
F39: =IF(E39=TRUE(),D39,0) -> 0
F40: =IF(E40=TRUE(),D40,0) -> 0
F41: =IF(E41=TRUE(),D41,0) -> 0
F42: =IF(E42=TRUE(),D42,0) -> 0
F43: =IF(E43=TRUE(),D43,0) -> 0
F44: =IF(E44=TRUE(),D44,0) -> 0
F45: =IF(E45=TRUE(),D45,0) -> 0
F46: =IF(E46=TRUE(),D46,0) -> 0
F47: =IF(E47=TRUE(),D47,0) -> 0
F48: =IF(E48=TRUE(),D48,0) -> 0
F49: =IF(E49=TRUE(),D49,0) -> 0
F50: =IF(E50=TRUE(),D50,0) -> 0
B53: Savings & Investments
B54: Account | C54: Amount
