Workbook

Sheet Monthly Spending Template
B1: MONTHLY BUDGET TEMPLATE
B5: Total Income | D5: Total Spent | F5: Leftover | H5: Savings Rate | J5: Bills Paid | M5: Budget Split | N5: 50/30/20 | O5: 50/30/20 | Q5: Spending Breakdown | U5: Budgeted | V5: Actual
B6: =SUM(IncomeTbl_MonthlySpendingTemplate57[Amount]) -> 0 | D6: =R6+R11 -> 0 | F6: =B6-D6 -> 0 | H6: =IFERROR(R9/B6,0) -> 0 | J6: =COUNTIF(BillsTbl_MonthlySpendingTemplate59[Paid?],TRUE())&" / "&COUNTA(BillsTbl_MonthlySpendingTemplate59[Bill Name]) -> 0 / 0 | M6: Needs Target | N6: =IF(N5="50/30/20",B6*0.5,IF(N5="70/20/10",B6*0.7,0)) -> 0 | O6: 70/20/10 | Q6: Needs Actual | R6: =O15+O17+O19+O21 -> 0 | T6: Needs | U6: =C37 -> Savings | V6: =R6 -> 0 | X6: Needs
M7: Wants Target | N7: =IF(N5="50/30/20",B6*0.3,IF(N5="70/20/10",B6*0.2,0)) -> 0 | Q7: Wants Actual | R7: =O14+O16+O18+O20 -> 0 | X7: Wants
C8: (Follow the numbers below for easy of use) | M8: Savings Target | N8: =IF(N5="50/30/20",B6*0.2,IF(N5="70/20/10",B6*0.1,0)) -> 0 | Q8: Savings Actual | R8: =SUM(SavingsTbl_MonthlySpendingTemplate60[Amount]) -> 0 | X8: Savings
Q9: Total Spent | R9: =R6+R7 -> 0
T11: Wants | U11: =C38 -> 401K | V11: =R11 -> 0
B12: 1. Income | E12: 2. Savings & Investments | I12: 4. Transactions Log | N12: Category Totals | T12: Savings | U12: =C39 -> Roth-IRA | V12: =R12 -> 0
B13: Source | C13: Amount | E13: Account | F13: Amount | I13: Date | J13: Category | K13: Amount | L13: Notes | N13: Category | O13: Total
N14: Subscriptions | O14: =SUMIFS(BillsTbl_MonthlySpendingTemplate59[Actual],BillsTbl_MonthlySpendingTemplate59[Category],"Subscriptions")+SUMIFS(K14:K72,J14:J72,"Subscriptions") -> 0 | Q14: want
N15: Gas | O15: =SUMIFS(BillsTbl_MonthlySpendingTemplate59[Actual],BillsTbl_MonthlySpendingTemplate59[Category],"Gas")+SUMIFS(K14:K72,J14:J72,"Gas") -> 0 | Q15: need
N16: Other | O16: =SUMIFS(BillsTbl_MonthlySpendingTemplate59[Actual],BillsTbl_MonthlySpendingTemplate59[Category],"Other")+SUMIFS(K14:K72,J14:J72,"Other") -> 0 | Q16: want
N17: Groceries | O17: =SUMIFS(BillsTbl_MonthlySpendingTemplate59[Actual],BillsTbl_MonthlySpendingTemplate59[Category],"Groceries")+SUMIFS(K14:K72,J14:J72,"Groceries") -> 0 | Q17: need
N18: Dining out | O18: =SUMIFS(BillsTbl_MonthlySpendingTemplate59[Actual],BillsTbl_MonthlySpendingTemplate59[Category],"Dining out")+SUMIFS(K14:K72,J14:J72,"Dining out") -> 0 | Q18: want
N19: Rent | O19: =SUMIFS(BillsTbl_MonthlySpendingTemplate59[Actual],BillsTbl_MonthlySpendingTemplate59[Category],"Rent")+SUMIFS(K14:K72,J14:J72,"Rent") -> 0 | Q19: need
N20: Shopping | O20: =SUMIFS(BillsTbl_MonthlySpendingTemplate59[Actual],BillsTbl_MonthlySpendingTemplate59[Category],"Shopping")+SUMIFS(K14:K72,J14:J72,"Shopping") -> 0 | Q20: want
B21: 3. Recurring Bills | N21: Credit Card | O21: =SUMIFS(BillsTbl_MonthlySpendingTemplate59[Actual],BillsTbl_MonthlySpendingTemplate59[Category],"Credit Card")+SUMIFS(K14:K72,J14:J72,"Credit Card") -> 0 | Q21: Need
B22: Bill Name | C22: Category | D22: Amount | E22: Paid? | F22: Actual
F23: =IF(E23=TRUE(),D23,0) -> 0
F24: =IF(E24=TRUE(),D24,0) -> 0
F25: =IF(E25=TRUE(),D25,0) -> 0
F26: =IF(E26=TRUE(),D26,0) -> 0
F27: =IF(E27=TRUE(),D27,0) -> 0
F28: =IF(E28=TRUE(),D28,0) -> 0
F29: =IF(E29=TRUE(),D29,0) -> 0
F30: =IF(E30=TRUE(),D30,0) -> 0
F31: =IF(E31=TRUE(),D31,0) -> 0
F32: =IF(E32=TRUE(),D32,0) -> 0
F33: =IF(E33=TRUE(),D33,0) -> 0
F34: =IF(E34=TRUE(),D34,0) -> 0
B36: Types of Saving/Investments
B37: 1 | C37: Savings
B38: 2 | C38: 401K
B39: 3 | C39: Roth-IRA
B40: 4 | C40: Brokerage

Sheet Yearly Overview
C2: Yearly Budget Dashboard
C6: Total Income (YTD) | F6: Total Spent (YTD) | I6: Avg Savings Rate | L6: Net Position (YTD)
C7: =SUM(E11:P11) -> 4851.81 | F7: =SUM(E15:P15) -> 2306.9 | I7: =IFERROR(AVERAGE(E17:P17),0) -> 0.074839246 | L7: =SUM(E16:P16) -> 3637.96
C10: Monthly Summary | E10: Jan. | F10: Feb. | G10: Mar | H10: Apr | I10: May | J10: Jun | K10: Jul | L10: Aug | M10: Sept | N10: Oct | O10: Nov | P10: Dec
C11: Total Income | E11: =Jan!$B$6 -> 0 | F11: =Feb!$B$6 -> 0 | G11: =Mar!$B$6 -> 0 | H11: =Apr!$B$6 -> 0 | I11: =May!$B$6 -> 0 | J11: =Jun!$B$6 -> 0 | K11: =Jul!$B$6 -> 0 | L11: =Aug!$B$6 -> 2654.27 | M11: =Sept!$B$6 -> 2197.54 | N11: =Oct!$B$6 -> 0 | O11: =Nov!$B$6 -> 0 | P11: =Dec!$B$6 -> 0
C12: Needs Actual | E12: =Jan!$R$6 -> 0 | F12: =Feb!$R$6 -> 0 | G12: =Mar!$R$6 -> 0 | H12: =Apr!$R$6 -> 0 | I12: =May!$R$6 -> 0 | J12: =Jun!$R$6 -> 0 | K12: =Jul!$R$6 -> 0 | L12: =Aug!$R$6 -> 981.61 | M12: =Sept!$R$6 -> 232.24 | N12: =Oct!$R$6 -> 0 | O12: =Nov!$R$6 -> 0 | P12: =Dec!$R$6 -> 0
C13: Wants Actual | E13: =Jan!$R$7 -> 0 | F13: =Feb!$R$7 -> 0 | G13: =Mar!$R$7 -> 0 | H13: =Apr!$R$7 -> 0 | I13: =May!R7 -> 0 | J13: =Jun!$R$7 -> 0 | K13: =Jul!$R$7 -> 0 | L13: =Aug!$R$7 -> 955.66 | M13: =Sept!$R$7 -> 137.39 | N13: =Oct!$R$7 -> 0 | O13: =Nov!$R$7 -> 0 | P13: =Dec!$R$7 -> 0
C14: Savings Actual | E14: =Jan!$R$8 -> 0 | F14: =Feb!$R$8 -> 0 | G14: =Mar!$R$8 -> 0 | H14: =Apr!$R$8 -> 0 | I14: =May!$R$8 -> 0 | J14: =Jun!$R$8 -> 0 | K14: =Jul!$R$8 -> 0 | L14: =Aug!$R$8 -> 677.65 | M14: =Sept!$R$8 -> 365.67 | N14: =Oct!$R$8 -> 0 | O14: =Nov!$R$8 -> 0 | P14: =Dec!$R$8 -> 0
C15: Total Expenses | E15: =Jan!$R$9 -> 0 | F15: =Feb!$R$9 -> 0 | G15: =Mar!$R$9 -> 0 | H15: =Apr!$R$9 -> 0 | I15: =May!$R$9 -> 0 | J15: =Jun!$R$9 -> 0 | K15: =Jul!$R$9 -> 0 | L15: =Aug!$R$9 -> 1937.27 | M15: =Sept!$R$9 -> 369.63 | N15: =Oct!$R$9 -> 0 | O15: =Nov!$R$9 -> 0 | P15: =Dec!$R$9 -> 0
C16: Cash Variance | E16: =Jan!$F$6 -> 0 | F16: =Feb!$F$6 -> 0 | G16: =Mar!$F$6 -> 0 | H16: =Apr!$F$6 -> 0 | I16: =May!$F$6 -> 0 | J16: =Jun!$F$6 -> 0 | K16: =Jul!$F$6 -> 0 | L16: =Aug!$F$6 -> 1672.66 | M16: =Sept!$F$6 -> 1965.3 | N16: =Oct!$F$6 -> 0 | O16: =Nov!$F$6 -> 0 | P16: =Dec!$F$6 -> 0
C17: Savings Rate % | E17: =Jan!$H$6 -> 0 | F17: =Feb!$H$6 -> 0 | G17: =Mar!$H$6 -> 0 | H17: =Apr!$H$6 -> 0 | I17: =May!$H$6 -> 0 | J17: =Jun!$H$6 -> 0 | K17: =Jul!$H$6 -> 0 | L17: =Aug!$H$6 -> 0.72986923 | M17: =Sept!$H$6 -> 0.16820172 | N17: =Oct!$H$6 -> 0 | O17: =Nov!$H$6 -> 0 | P17: =Dec!$H$6 -> 0
E19: (Keep Cells Absolute)
C20: Spending by Category
C21: Category | E21: Jan | F21: Feb | G21: Mar | H21: Apr | I21: May | J21: Jun | K21: Jul | L21: Aug | M21: Sept | N21: Oct | O21: Nov | P21: Dec | Q21: Avg/Active Mo. | R21: YTD Total
C22: Subscriptions | E22: =Jan!$O$14 -> 0 | F22: =Feb!$O$14 -> 0 | G22: =Mar!$O$14 -> 0 | H22: =Apr!$O$14 -> 0 | I22: =May!$O$14 -> 0 | J22: =Jun!$O$14 -> 0 | K22: =Jul!$O$14 -> 0 | L22: =Aug!$O$14 -> 57.31 | M22: =Sept!$O$14 -> 6.48 | N22: =Oct!$O$14 -> 0 | O22: =Nov!$O$14 -> 0 | P22: =Dec!$O$14 -> 0 | Q22: =IFERROR(AVERAGEIF(E22:P22,"<>0"),0) -> 31.895 | R22: =SUM(E22:P22) -> 63.79
C23: Gas | E23: =Jan!$O$15 -> 0 | F23: =Feb!$O$15 -> 0 | G23: =Mar!$O$15 -> 0 | H23: =Apr!$O$15 -> 0 | I23: =May!$O$15 -> 0 | J23: =Jun!$O$15 -> 0 | K23: =Jul!$O$15 -> 0 | L23: =Aug!$O$15 -> 61.61 | M23: =Sept!$O$15 -> 32.24 | N23: =Oct!$O$15 -> 0 | O23: =Nov!$O$15 -> 0 | P23: =Dec!$O$15 -> 0 | Q23: =IFERROR(AVERAGEIF(E23:P23,"<>0"),0) -> 46.925 | R23: =SUM(E23:P23) -> 93.85
C24: Other | E24: =Jan!$O$16 -> 0 | F24: =Feb!$O$16 -> 0 | G24: =Mar!$O$16 -> 0 | H24: =Apr!$O$16 -> 0 | I24: =May!$O$16 -> 0 | J24: =Jun!$O$16 -> 0 | K24: =Jul!$O$16 -> 0 | L24: =Aug!$O$16 -> 482.41 | M24: =Sept!$O$16 -> 55.04 | N24: =Oct!$O$16 -> 0 | O24: =Nov!$O$16 -> 0 | P24: =Dec!$O$16 -> 0 | Q24: =IFERROR(AVERAGEIF(E24:P24,"<>0"),0) -> 268.725 | R24: =SUM(E24:P24) -> 537.45
C25: Groceries | E25: =Jan!$O$17 -> 0 | F25: =Feb!$O$17 -> 0 | G25: =Mar!$O$17 -> 0 | H25: =Apr!$O$17 -> 0 | I25: =May!$O$17 -> 0 | J25: =Jun!$O$17 -> 0 | K25: =Jul!$O$17 -> 0 | L25: =Aug!$O$17 -> 70 | M25: =Sept!$O$17 -> 0 | N25: =Oct!$O$17 -> 0 | O25: =Nov!$O$17 -> 0 | P25: =Dec!$O$17 -> 0 | Q25: =IFERROR(AVERAGEIF(E25:P25,"<>0"),0) -> 70 | R25: =SUM(E25:P25) -> 70
C26: Dining out | E26: =Jan!$O$18 -> 0 | F26: =Feb!$O$18 -> 0 | G26: =Mar!$O$18 -> 0 | H26: =Apr!$O$18 -> 0 | I26: =May!$O$18 -> 0 | J26: =Jun!$O$18 -> 0 | K26: =Jul!$O$18 -> 0 | L26: =Aug!$O$18 -> 168.91 | M26: =Sept!$O$18 -> 51.54 | N26: =Oct!$O$18 -> 0 | O26: =Nov!$O$18 -> 0 | P26: =Dec!$O$18 -> 0 | Q26: =IFERROR(AVERAGEIF(E26:P26,"<>0"),0) -> 110.225 | R26: =SUM(E26:P26) -> 220.45
C27: Rent | E27: =Jan!$O$19 -> 0 | F27: =Feb!$O$19 -> 0 | G27: =Mar!$O$19 -> 0 | H27: =Apr!$O$19 -> 0 | I27: =May!$O$19 -> 0 | J27: =Jun!$O$19 -> 0 | K27: =Jul!$O$19 -> 0 | L27: =Aug!$O$19 -> 650 | M27: =Sept!$O$19 -> 0 | N27: =Oct!$O$19 -> 0 | O27: =Nov!$O$19 -> 0 | P27: =Dec!$O$19 -> 0 | Q27: =IFERROR(AVERAGEIF(E27:P27,"<>0"),0) -> 650 | R27: =SUM(E27:P27) -> 650
C28: Shopping | E28: =Jan!$O$20 -> 0 | F28: =Feb!$O$20 -> 0 | G28: =Mar!$O$20 -> 0 | H28: =Apr!$O$20 -> 0 | I28: =May!$O$20 -> 0 | J28: =Jun!$O$20 -> 0 | K28: =Jul!$O$20 -> 0 | L28: =Aug!$O$20 -> 247.03 | M28: =Sept!$O$20 -> 24.33 | N28: =Oct!$O$20 -> 0 | O28: =Nov!$O$20 -> 0 | P28: =Dec!$O$20 -> 0 | Q28: =IFERROR(AVERAGEIF(E28:P28,"<>0"),0) -> 135.68 | R28: =SUM(E28:P28) -> 271.36
C29: Credit Card | E29: =Jan!$O$21 -> 0 | F29: =Feb!$O$21 -> 0 | G29: =Mar!$O$21 -> 0 | H29: =Apr!$O$21 -> 0 | I29: =Jan!$O$21 -> 0 | J29: =Jun!$O$21 -> 0 | K29: =Jul!$O$21 -> 0 | L29: =Aug!$O$21 -> 200 | M29: =Sept!$O$21 -> 200 | N29: =Oct!$O$21 -> 0 | O29: =Nov!$O$21 -> 0 | P29: =Jan!$O$21 -> 0 | Q29: =IFERROR(AVERAGEIF(E29:P29,"<>0"),0) -> 200 | R29: =SUM(E29:P29) -> 400

Sheet Jan
B1: MONTHLY BUDGET TEMPLATE
B5: Total Income | D5: Total Spent | F5: Leftover | H5: Savings Rate | J5: Bills Paid | M5: Budget Split | N5: 50/30/20 | Q5: Spending Breakdown | U5: Budgeted | V5: Actual
B6: =SUM(IncomeTbl_MonthlySpendingTemplate5724[Amount]) -> 0 | D6: =R6+R11 -> 0 | F6: =B6-D6 -> 0 | H6: =IFERROR(R9/B6,0) -> 0 | J6: =COUNTIF(BillsTbl_MonthlySpendingTemplate5932[Paid?],TRUE())&" / "&COUNTA(BillsTbl_MonthlySpendingTemplate5932[Bill Name]) -> 0 / 0 | M6: Needs Target | N6: =IF(N5="50/30/20",B6*0.5,IF(N5="70/20/10",B6*0.7,0)) -> 0 | Q6: Needs Actual | R6: =O15+O17+O19+O21 -> 0 | T6: Needs | U6: =C37 -> 0 | V6: =R6 -> 0
M7: Wants Target | N7: =IF(N5="50/30/20",B6*0.3,IF(N5="70/20/10",B6*0.2,0)) -> 0 | Q7: Wants Actual | R7: =O14+O16+O18+O20 -> 0
M8: Savings Target | N8: =IF(N5="50/30/20",B6*0.2,IF(N5="70/20/10",B6*0.1,0)) -> 0 | Q8: Savings Actual | R8: =SUM(SavingsTbl_MonthlySpendingTemplate6037[Amount]) -> 0
Q9: Total Spent | R9: =R6+R7 -> 0
T11: Wants | U11: =C38 -> 0 | V11: =R11 -> 0
B12: Income | E12: Savings & Investments | I12: Transactions Log | N12: Category Totals | T12: Savings | U12: =C39 -> 0 | V12: =R12 -> 0
B13: Source | C13: Amount | E13: Account | F13: Amount | I13: Date | J13: Category | K13: Amount | L13: Notes | N13: Category | O13: Total
N14: Subscriptions | O14: =SUMIFS(BillsTbl_MonthlySpendingTemplate5932[Actual],BillsTbl_MonthlySpendingTemplate5932[Category],"Subscriptions")+SUMIFS(K14:K72,J14:J72,"Subscriptions") -> 0 | Q14: want
N15: Gas | O15: =SUMIFS(BillsTbl_MonthlySpendingTemplate5932[Actual],BillsTbl_MonthlySpendingTemplate5932[Category],"Gas")+SUMIFS(K14:K72,J14:J72,"Gas") -> 0 | Q15: need
N16: Other | O16: =SUMIFS(BillsTbl_MonthlySpendingTemplate5932[Actual],BillsTbl_MonthlySpendingTemplate5932[Category],"Other")+SUMIFS(K14:K72,J14:J72,"Other") -> 0 | Q16: want
N17: Groceries | O17: =SUMIFS(BillsTbl_MonthlySpendingTemplate5932[Actual],BillsTbl_MonthlySpendingTemplate5932[Category],"Groceries")+SUMIFS(K14:K72,J14:J72,"Groceries") -> 0 | Q17: need
N18: Dining out | O18: =SUMIFS(BillsTbl_MonthlySpendingTemplate5932[Actual],BillsTbl_MonthlySpendingTemplate5932[Category],"Dining out")+SUMIFS(K14:K72,J14:J72,"Dining out") -> 0 | Q18: want
N19: Rent | O19: =SUMIFS(BillsTbl_MonthlySpendingTemplate5932[Actual],BillsTbl_MonthlySpendingTemplate5932[Category],"Rent")+SUMIFS(K14:K72,J14:J72,"Rent") -> 0 | Q19: need
N20: Shopping | O20: =SUMIFS(BillsTbl_MonthlySpendingTemplate5932[Actual],BillsTbl_MonthlySpendingTemplate5932[Category],"Shopping")+SUMIFS(K14:K72,J14:J72,"Shopping") -> 0 | Q20: want
B21: Recurring Bills | N21: Credit Card | O21: =SUMIFS(BillsTbl_MonthlySpendingTemplate5932[Actual],BillsTbl_MonthlySpendingTemplate5932[Category],"Credit Card")+SUMIFS(K14:K72,J14:J72,"Credit Card") -> 0 | Q21: Need
B22: Bill Name | C22: Category | D22: Amount | E22: Paid? | F22: Actual
F23: =IF(E23=TRUE(),D23,0) -> 0
F24: =IF(E24=TRUE(),D24,0) -> 0
F25: =IF(E25=TRUE(),D25,0) -> 0
F26: =IF(E26=TRUE(),D26,0) -> 0
F27: =IF(E27=TRUE(),D27,0) -> 0
F28: =IF(E28=TRUE(),D28,0) -> 0
F29: =IF(E29=TRUE(),D29,0) -> 0
F30: =IF(E30=TRUE(),D30,0) -> 0
F31: =IF(E31=TRUE(),D31,0) -> 0
F32: =IF(E32=TRUE(),D32,0) -> 0
F33: =IF(E33=TRUE(),D33,0) -> 0
F34: =IF(E34=TRUE(),D34,0) -> 0

Sheet Feb
B1: MONTHLY BUDGET TEMPLATE
B5: Total Income | D5: Total Spent | F5: Leftover | H5: Savings Rate | J5: Bills Paid | M5: Budget Split | N5: 50/30/20 | Q5: Spending Breakdown | U5: Budgeted | V5: Actual
B6: =SUM(IncomeTbl_MonthlySpendingTemplate572445[Amount]) -> 0 | D6: =R6+R11 -> 0 | F6: =B6-D6 -> 0 | H6: =IFERROR(R9/B6,0) -> 0 | J6: =COUNTIF(BillsTbl_MonthlySpendingTemplate593250[Paid?],TRUE())&" / "&COUNTA(BillsTbl_MonthlySpendingTemplate593250[Bill Name]) -> 0 / 0 | M6: Needs Target | N6: =IF(N5="50/30/20",B6*0.5,IF(N5="70/20/10",B6*0.7,0)) -> 0 | Q6: Needs Actual | R6: =O15+O17+O19+O21 -> 0 | T6: Needs | U6: =C37 -> 0 | V6: =R6 -> 0
M7: Wants Target | N7: =IF(N5="50/30/20",B6*0.3,IF(N5="70/20/10",B6*0.2,0)) -> 0 | Q7: Wants Actual | R7: =O14+O16+O18+O20 -> 0
M8: Savings Target | N8: =IF(N5="50/30/20",B6*0.2,IF(N5="70/20/10",B6*0.1,0)) -> 0 | Q8: Savings Actual | R8: =SUM(SavingsTbl_MonthlySpendingTemplate603754[Amount]) -> 0
Q9: Total Spent | R9: =R6+R7 -> 0
T11: Wants | U11: =C38 -> 0 | V11: =R11 -> 0
B12: Income | E12: Savings & Investments | I12: Transactions Log | N12: Category Totals | T12: Savings | U12: =C39 -> 0 | V12: =R12 -> 0
B13: Source | C13: Amount | E13: Account | F13: Amount | I13: Date | J13: Category | K13: Amount | L13: Notes | N13: Category | O13: Total
N14: Subscriptions | O14: =SUMIFS(BillsTbl_MonthlySpendingTemplate593250[Actual],BillsTbl_MonthlySpendingTemplate593250[Category],"Subscriptions")+SUMIFS(K14:K72,J14:J72,"Subscriptions") -> 0 | Q14: want
N15: Gas | O15: =SUMIFS(BillsTbl_MonthlySpendingTemplate593250[Actual],BillsTbl_MonthlySpendingTemplate593250[Category],"Gas")+SUMIFS(K14:K72,J14:J72,"Gas") -> 0 | Q15: need
N16: Other | O16: =SUMIFS(BillsTbl_MonthlySpendingTemplate593250[Actual],BillsTbl_MonthlySpendingTemplate593250[Category],"Other")+SUMIFS(K14:K72,J14:J72,"Other") -> 0 | Q16: want
N17: Groceries | O17: =SUMIFS(BillsTbl_MonthlySpendingTemplate593250[Actual],BillsTbl_MonthlySpendingTemplate593250[Category],"Groceries")+SUMIFS(K14:K72,J14:J72,"Groceries") -> 0 | Q17: need
N18: Dining out | O18: =SUMIFS(BillsTbl_MonthlySpendingTemplate593250[Actual],BillsTbl_MonthlySpendingTemplate593250[Category],"Dining out")+SUMIFS(K14:K72,J14:J72,"Dining out") -> 0 | Q18: want
N19: Rent | O19: =SUMIFS(BillsTbl_MonthlySpendingTemplate593250[Actual],BillsTbl_MonthlySpendingTemplate593250[Category],"Rent")+SUMIFS(K14:K72,J14:J72,"Rent") -> 0 | Q19: need
N20: Shopping | O20: =SUMIFS(BillsTbl_MonthlySpendingTemplate593250[Actual],BillsTbl_MonthlySpendingTemplate593250[Category],"Shopping")+SUMIFS(K14:K72,J14:J72,"Shopping") -> 0 | Q20: want
B21: Recurring Bills | N21: Credit Card | O21: =SUMIFS(BillsTbl_MonthlySpendingTemplate593250[Actual],BillsTbl_MonthlySpendingTemplate593250[Category],"Credit Card")+SUMIFS(K14:K72,J14:J72,"Credit Card") -> 0 | Q21: Need
B22: Bill Name | C22: Category | D22: Amount | E22: Paid? | F22: Actual
F23: =IF(E23=TRUE(),D23,0) -> 0
F24: =IF(E24=TRUE(),D24,0) -> 0
F25: =IF(E25=TRUE(),D25,0) -> 0
F26: =IF(E26=TRUE(),D26,0) -> 0
F27: =IF(E27=TRUE(),D27,0) -> 0
F28: =IF(E28=TRUE(),D28,0) -> 0
F29: =IF(E29=TRUE(),D29,0) -> 0
F30: =IF(E30=TRUE(),D30,0) -> 0
F31: =IF(E31=TRUE(),D31,0) -> 0
F32: =IF(E32=TRUE(),D32,0) -> 0
F33: =IF(E33=TRUE(),D33,0) -> 0
F34: =IF(E34=TRUE(),D34,0) -> 0

Sheet Mar
B1: MONTHLY BUDGET TEMPLATE
B5: Total Income | D5: Total Spent | F5: Leftover | H5: Savings Rate | J5: Bills Paid | M5: Budget Split | N5: 50/30/20 | Q5: Spending Breakdown | U5: Budgeted | V5: Actual
B6: =SUM(IncomeTbl_MonthlySpendingTemplate5724455561[Amount]) -> 0 | D6: =R6+R11 -> 0 | F6: =B6-D6 -> 0 | H6: =IFERROR(R9/B6,0) -> 0 | J6: =COUNTIF(BillsTbl_MonthlySpendingTemplate5932505662[Paid?],TRUE())&" / "&COUNTA(BillsTbl_MonthlySpendingTemplate5932505662[Bill Name]) -> 0 / 0 | M6: Needs Target | N6: =IF(N5="50/30/20",B6*0.5,IF(N5="70/20/10",B6*0.7,0)) -> 0 | Q6: Needs Actual | R6: =O15+O17+O19+O21 -> 0 | T6: Needs | U6: =C37 -> 0 | V6: =R6 -> 0
M7: Wants Target | N7: =IF(N5="50/30/20",B6*0.3,IF(N5="70/20/10",B6*0.2,0)) -> 0 | Q7: Wants Actual | R7: =O14+O16+O18+O20 -> 0
M8: Savings Target | N8: =IF(N5="50/30/20",B6*0.2,IF(N5="70/20/10",B6*0.1,0)) -> 0 | Q8: Savings Actual | R8: =SUM(SavingsTbl_MonthlySpendingTemplate6037545863[Amount]) -> 0
Q9: Total Spent | R9: =R6+R7 -> 0
T11: Wants | U11: =C38 -> 0 | V11: =R11 -> 0
B12: Income | E12: Savings & Investments | I12: Transactions Log | N12: Category Totals | T12: Savings | U12: =C39 -> 0 | V12: =R12 -> 0
B13: Source | C13: Amount | E13: Account | F13: Amount | I13: Date | J13: Category | K13: Amount | L13: Notes | N13: Category | O13: Total
N14: Subscriptions | O14: =SUMIFS(BillsTbl_MonthlySpendingTemplate5932505662[Actual],BillsTbl_MonthlySpendingTemplate5932505662[Category],"Subscriptions")+SUMIFS(K14:K72,J14:J72,"Subscriptions") -> 0 | Q14: want
N15: Gas | O15: =SUMIFS(BillsTbl_MonthlySpendingTemplate5932505662[Actual],BillsTbl_MonthlySpendingTemplate5932505662[Category],"Gas")+SUMIFS(K14:K72,J14:J72,"Gas") -> 0 | Q15: need
N16: Other | O16: =SUMIFS(BillsTbl_MonthlySpendingTemplate5932505662[Actual],BillsTbl_MonthlySpendingTemplate5932505662[Category],"Other")+SUMIFS(K14:K72,J14:J72,"Other") -> 0 | Q16: want
N17: Groceries | O17: =SUMIFS(BillsTbl_MonthlySpendingTemplate5932505662[Actual],BillsTbl_MonthlySpendingTemplate5932505662[Category],"Groceries")+SUMIFS(K14:K72,J14:J72,"Groceries") -> 0 | Q17: need
N18: Dining out | O18: =SUMIFS(BillsTbl_MonthlySpendingTemplate5932505662[Actual],BillsTbl_MonthlySpendingTemplate5932505662[Category],"Dining out")+SUMIFS(K14:K72,J14:J72,"Dining out") -> 0 | Q18: want
N19: Rent | O19: =SUMIFS(BillsTbl_MonthlySpendingTemplate5932505662[Actual],BillsTbl_MonthlySpendingTemplate5932505662[Category],"Rent")+SUMIFS(K14:K72,J14:J72,"Rent") -> 0 | Q19: need
N20: Shopping | O20: =SUMIFS(BillsTbl_MonthlySpendingTemplate5932505662[Actual],BillsTbl_MonthlySpendingTemplate5932505662[Category],"Shopping")+SUMIFS(K14:K72,J14:J72,"Shopping") -> 0 | Q20: want
B21: Recurring Bills | N21: Credit Card | O21: =SUMIFS(BillsTbl_MonthlySpendingTemplate5932505662[Actual],BillsTbl_MonthlySpendingTemplate5932505662[Category],"Credit Card")+SUMIFS(K14:K72,J14:J72,"Credit Card") -> 0 | Q21: Need
B22: Bill Name | C22: Category | D22: Amount | E22: Paid? | F22: Actual
F23: =IF(E23=TRUE(),D23,0) -> 0
F24: =IF(E24=TRUE(),D24,0) -> 0
F25: =IF(E25=TRUE(),D25,0) -> 0
F26: =IF(E26=TRUE(),D26,0) -> 0
F27: =IF(E27=TRUE(),D27,0) -> 0
F28: =IF(E28=TRUE(),D28,0) -> 0
F29: =IF(E29=TRUE(),D29,0) -> 0
F30: =IF(E30=TRUE(),D30,0) -> 0
F31: =IF(E31=TRUE(),D31,0) -> 0
F32: =IF(E32=TRUE(),D32,0) -> 0
F33: =IF(E33=TRUE(),D33,0) -> 0
F34: =IF(E34=TRUE(),D34,0) -> 0

Sheet Apr
B1: MONTHLY BUDGET TEMPLATE
B5: Total Income | D5: Total Spent | F5: Leftover | H5: Savings Rate | J5: Bills Paid | M5: Budget Split | N5: 50/30/20 | Q5: Spending Breakdown | U5: Budgeted | V5: Actual
B6: =SUM(IncomeTbl_MonthlySpendingTemplate57244555[Amount]) -> 0 | D6: =R6+R11 -> 0 | F6: =B6-D6 -> 0 | H6: =IFERROR(R9/B6,0) -> 0 | J6: =COUNTIF(BillsTbl_MonthlySpendingTemplate59325056[Paid?],TRUE())&" / "&COUNTA(BillsTbl_MonthlySpendingTemplate59325056[Bill Name]) -> 0 / 0 | M6: Needs Target | N6: =IF(N5="50/30/20",B6*0.5,IF(N5="70/20/10",B6*0.7,0)) -> 0 | Q6: Needs Actual | R6: =O15+O17+O19+O21 -> 0 | T6: Needs | U6: =C37 -> 0 | V6: =R6 -> 0
M7: Wants Target | N7: =IF(N5="50/30/20",B6*0.3,IF(N5="70/20/10",B6*0.2,0)) -> 0 | Q7: Wants Actual | R7: =O14+O16+O18+O20 -> 0
M8: Savings Target | N8: =IF(N5="50/30/20",B6*0.2,IF(N5="70/20/10",B6*0.1,0)) -> 0 | Q8: Savings Actual | R8: =SUM(SavingsTbl_MonthlySpendingTemplate60375458[Amount]) -> 0
Q9: Total Spent | R9: =R6+R7 -> 0
T11: Wants | U11: =C38 -> 0 | V11: =R11 -> 0
B12: Income | E12: Savings & Investments | I12: Transactions Log | N12: Category Totals | T12: Savings | U12: =C39 -> 0 | V12: =R12 -> 0
B13: Source | C13: Amount | E13: Account | F13: Amount | I13: Date | J13: Category | K13: Amount | L13: Notes | N13: Category | O13: Total
N14: Subscriptions | O14: =SUMIFS(BillsTbl_MonthlySpendingTemplate59325056[Actual],BillsTbl_MonthlySpendingTemplate59325056[Category],"Subscriptions")+SUMIFS(K14:K72,J14:J72,"Subscriptions") -> 0 | Q14: want
N15: Gas | O15: =SUMIFS(BillsTbl_MonthlySpendingTemplate59325056[Actual],BillsTbl_MonthlySpendingTemplate59325056[Category],"Gas")+SUMIFS(K14:K72,J14:J72,"Gas") -> 0 | Q15: need
N16: Other | O16: =SUMIFS(BillsTbl_MonthlySpendingTemplate59325056[Actual],BillsTbl_MonthlySpendingTemplate59325056[Category],"Other")+SUMIFS(K14:K72,J14:J72,"Other") -> 0 | Q16: want
N17: Groceries | O17: =SUMIFS(BillsTbl_MonthlySpendingTemplate59325056[Actual],BillsTbl_MonthlySpendingTemplate59325056[Category],"Groceries")+SUMIFS(K14:K72,J14:J72,"Groceries") -> 0 | Q17: need
N18: Dining out | O18: =SUMIFS(BillsTbl_MonthlySpendingTemplate59325056[Actual],BillsTbl_MonthlySpendingTemplate59325056[Category],"Dining out")+SUMIFS(K14:K72,J14:J72,"Dining out") -> 0 | Q18: want
N19: Rent | O19: =SUMIFS(BillsTbl_MonthlySpendingTemplate59325056[Actual],BillsTbl_MonthlySpendingTemplate59325056[Category],"Rent")+SUMIFS(K14:K72,J14:J72,"Rent") -> 0 | Q19: need
N20: Shopping | O20: =SUMIFS(BillsTbl_MonthlySpendingTemplate59325056[Actual],BillsTbl_MonthlySpendingTemplate59325056[Category],"Shopping")+SUMIFS(K14:K72,J14:J72,"Shopping") -> 0 | Q20: want
B21: Recurring Bills | N21: Credit Card | O21: =SUMIFS(BillsTbl_MonthlySpendingTemplate59325056[Actual],BillsTbl_MonthlySpendingTemplate59325056[Category],"Credit Card")+SUMIFS(K14:K72,J14:J72,"Credit Card") -> 0 | Q21: Need
B22: Bill Name | C22: Category | D22: Amount | E22: Paid? | F22: Actual
F23: =IF(E23=TRUE(),D23,0) -> 0
F24: =IF(E24=TRUE(),D24,0) -> 0
F25: =IF(E25=TRUE(),D25,0) -> 0
F26: =IF(E26=TRUE(),D26,0) -> 0
F27: =IF(E27=TRUE(),D27,0) -> 0
F28: =IF(E28=TRUE(),D28,0) -> 0
F29: =IF(E29=TRUE(),D29,0) -> 0
F30: =IF(E30=TRUE(),D30,0) -> 0
F31: =IF(E31=TRUE(),D31,0) -> 0
F32: =IF(E32=TRUE(),D32,0) -> 0
F33: =IF(E33=TRUE(),D33,0) -> 0
F34: =IF(E34=TRUE(),D34,0) -> 0

Sheet May
B1: MONTHLY BUDGET TEMPLATE
B5: Total Income | D5: Total Spent | F5: Leftover | H5: Savings Rate | J5: Bills Paid | M5: Budget Split | N5: 50/30/20 | Q5: Spending Breakdown | U5: Budgeted | V5: Actual
B6: =SUM(IncomeTbl_MonthlySpendingTemplate5724455564[Amount]) -> 0 | D6: =R6+R11 -> 0 | F6: =B6-D6 -> 0 | H6: =IFERROR(R9/B6,0) -> 0 | J6: =COUNTIF(BillsTbl_MonthlySpendingTemplate5932505665[Paid?],TRUE())&" / "&COUNTA(BillsTbl_MonthlySpendingTemplate5932505665[Bill Name]) -> 0 / 0 | M6: Needs Target | N6: =IF(N5="50/30/20",B6*0.5,IF(N5="70/20/10",B6*0.7,0)) -> 0 | Q6: Needs Actual | R6: =O15+O17+O19+O21 -> 0 | T6: Needs | U6: =C37 -> 0 | V6: =R6 -> 0
M7: Wants Target | N7: =IF(N5="50/30/20",B6*0.3,IF(N5="70/20/10",B6*0.2,0)) -> 0 | Q7: Wants Actual | R7: =O14+O16+O18+O20 -> 0
M8: Savings Target | N8: =IF(N5="50/30/20",B6*0.2,IF(N5="70/20/10",B6*0.1,0)) -> 0 | Q8: Savings Actual | R8: =SUM(SavingsTbl_MonthlySpendingTemplate6037545866[Amount]) -> 0
Q9: Total Spent | R9: =R6+R7 -> 0
T11: Wants | U11: =C38 -> 0 | V11: =R11 -> 0
B12: Income | E12: Savings & Investments | I12: Transactions Log | N12: Category Totals | T12: Savings | U12: =C39 -> 0 | V12: =R12 -> 0
B13: Source | C13: Amount | E13: Account | F13: Amount | I13: Date | J13: Category | K13: Amount | L13: Notes | N13: Category | O13: Total
N14: Subscriptions | O14: =SUMIFS(BillsTbl_MonthlySpendingTemplate5932505665[Actual],BillsTbl_MonthlySpendingTemplate5932505665[Category],"Subscriptions")+SUMIFS(K14:K72,J14:J72,"Subscriptions") -> 0 | Q14: want
N15: Gas | O15: =SUMIFS(BillsTbl_MonthlySpendingTemplate5932505665[Actual],BillsTbl_MonthlySpendingTemplate5932505665[Category],"Gas")+SUMIFS(K14:K72,J14:J72,"Gas") -> 0 | Q15: need
N16: Other | O16: =SUMIFS(BillsTbl_MonthlySpendingTemplate5932505665[Actual],BillsTbl_MonthlySpendingTemplate5932505665[Category],"Other")+SUMIFS(K14:K72,J14:J72,"Other") -> 0 | Q16: want
N17: Groceries | O17: =SUMIFS(BillsTbl_MonthlySpendingTemplate5932505665[Actual],BillsTbl_MonthlySpendingTemplate5932505665[Category],"Groceries")+SUMIFS(K14:K72,J14:J72,"Groceries") -> 0 | Q17: need
N18: Dining out | O18: =SUMIFS(BillsTbl_MonthlySpendingTemplate5932505665[Actual],BillsTbl_MonthlySpendingTemplate5932505665[Category],"Dining out")+SUMIFS(K14:K72,J14:J72,"Dining out") -> 0 | Q18: want
N19: Rent | O19: =SUMIFS(BillsTbl_MonthlySpendingTemplate5932505665[Actual],BillsTbl_MonthlySpendingTemplate5932505665[Category],"Rent")+SUMIFS(K14:K72,J14:J72,"Rent") -> 0 | Q19: need
N20: Shopping | O20: =SUMIFS(BillsTbl_MonthlySpendingTemplate5932505665[Actual],BillsTbl_MonthlySpendingTemplate5932505665[Category],"Shopping")+SUMIFS(K14:K72,J14:J72,"Shopping") -> 0 | Q20: want
B21: Recurring Bills | N21: Credit Card | O21: =SUMIFS(BillsTbl_MonthlySpendingTemplate5932505665[Actual],BillsTbl_MonthlySpendingTemplate5932505665[Category],"Credit Card")+SUMIFS(K14:K72,J14:J72,"Credit Card") -> 0 | Q21: Need
B22: Bill Name | C22: Category | D22: Amount | E22: Paid? | F22: Actual
F23: =IF(E23=TRUE(),D23,0) -> 0
F24: =IF(E24=TRUE(),D24,0) -> 0
F25: =IF(E25=TRUE(),D25,0) -> 0
F26: =IF(E26=TRUE(),D26,0) -> 0
F27: =IF(E27=TRUE(),D27,0) -> 0
F28: =IF(E28=TRUE(),D28,0) -> 0
F29: =IF(E29=TRUE(),D29,0) -> 0
F30: =IF(E30=TRUE(),D30,0) -> 0
F31: =IF(E31=TRUE(),D31,0) -> 0
F32: =IF(E32=TRUE(),D32,0) -> 0
F33: =IF(E33=TRUE(),D33,0) -> 0
F34: =IF(E34=TRUE(),D34,0) -> 0

Sheet Jun
B1: MONTHLY BUDGET TEMPLATE
B5: Total Income | D5: Total Spent | F5: Leftover | H5: Savings Rate | J5: Bills Paid | M5: Budget Split | N5: 50/30/20 | Q5: Spending Breakdown | U5: Budgeted | V5: Actual
B6: =SUM(IncomeTbl_MonthlySpendingTemplate572445556467[Amount]) -> 0 | D6: =R6+R11 -> 0 | F6: =B6-D6 -> 0 | H6: =IFERROR(R9/B6,0) -> 0 | J6: =COUNTIF(BillsTbl_MonthlySpendingTemplate593250566568[Paid?],TRUE())&" / "&COUNTA(BillsTbl_MonthlySpendingTemplate593250566568[Bill Name]) -> 0 / 0 | M6: Needs Target | N6: =IF(N5="50/30/20",B6*0.5,IF(N5="70/20/10",B6*0.7,0)) -> 0 | Q6: Needs Actual | R6: =O15+O17+O19+O21 -> 0 | T6: Needs | U6: =C37 -> 0 | V6: =R6 -> 0
M7: Wants Target | N7: =IF(N5="50/30/20",B6*0.3,IF(N5="70/20/10",B6*0.2,0)) -> 0 | Q7: Wants Actual | R7: =O14+O16+O18+O20 -> 0
M8: Savings Target | N8: =IF(N5="50/30/20",B6*0.2,IF(N5="70/20/10",B6*0.1,0)) -> 0 | Q8: Savings Actual | R8: =SUM(SavingsTbl_MonthlySpendingTemplate603754586669[Amount]) -> 0
Q9: Total Spent | R9: =R6+R7 -> 0
T11: Wants | U11: =C38 -> 0 | V11: =R11 -> 0
B12: Income | E12: Savings & Investments | I12: Transactions Log | N12: Category Totals | T12: Savings | U12: =C39 -> 0 | V12: =R12 -> 0
B13: Source | C13: Amount | E13: Account | F13: Amount | I13: Date | J13: Category | K13: Amount | L13: Notes | N13: Category | O13: Total
N14: Subscriptions | O14: =SUMIFS(BillsTbl_MonthlySpendingTemplate593250566568[Actual],BillsTbl_MonthlySpendingTemplate593250566568[Category],"Subscriptions")+SUMIFS(K14:K72,J14:J72,"Subscriptions") -> 0 | Q14: want
N15: Gas | O15: =SUMIFS(BillsTbl_MonthlySpendingTemplate593250566568[Actual],BillsTbl_MonthlySpendingTemplate593250566568[Category],"Gas")+SUMIFS(K14:K72,J14:J72,"Gas") -> 0 | Q15: need
N16: Other | O16: =SUMIFS(BillsTbl_MonthlySpendingTemplate593250566568[Actual],BillsTbl_MonthlySpendingTemplate593250566568[Category],"Other")+SUMIFS(K14:K72,J14:J72,"Other") -> 0 | Q16: want
N17: Groceries | O17: =SUMIFS(BillsTbl_MonthlySpendingTemplate593250566568[Actual],BillsTbl_MonthlySpendingTemplate593250566568[Category],"Groceries")+SUMIFS(K14:K72,J14:J72,"Groceries") -> 0 | Q17: need
N18: Dining out | O18: =SUMIFS(BillsTbl_MonthlySpendingTemplate593250566568[Actual],BillsTbl_MonthlySpendingTemplate593250566568[Category],"Dining out")+SUMIFS(K14:K72,J14:J72,"Dining out") -> 0 | Q18: want
N19: Rent | O19: =SUMIFS(BillsTbl_MonthlySpendingTemplate593250566568[Actual],BillsTbl_MonthlySpendingTemplate593250566568[Category],"Rent")+SUMIFS(K14:K72,J14:J72,"Rent") -> 0 | Q19: need
N20: Shopping | O20: =SUMIFS(BillsTbl_MonthlySpendingTemplate593250566568[Actual],BillsTbl_MonthlySpendingTemplate593250566568[Category],"Shopping")+SUMIFS(K14:K72,J14:J72,"Shopping") -> 0 | Q20: want
B21: Recurring Bills | N21: Credit Card | O21: =SUMIFS(BillsTbl_MonthlySpendingTemplate593250566568[Actual],BillsTbl_MonthlySpendingTemplate593250566568[Category],"Credit Card")+SUMIFS(K14:K72,J14:J72,"Credit Card") -> 0 | Q21: Need
B22: Bill Name | C22: Category | D22: Amount | E22: Paid? | F22: Actual
F23: =IF(E23=TRUE(),D23,0) -> 0
F24: =IF(E24=TRUE(),D24,0) -> 0
F25: =IF(E25=TRUE(),D25,0) -> 0
F26: =IF(E26=TRUE(),D26,0) -> 0
F27: =IF(E27=TRUE(),D27,0) -> 0
F28: =IF(E28=TRUE(),D28,0) -> 0
F29: =IF(E29=TRUE(),D29,0) -> 0
F30: =IF(E30=TRUE(),D30,0) -> 0
F31: =IF(E31=TRUE(),D31,0) -> 0
F32: =IF(E32=TRUE(),D32,0) -> 0
F33: =IF(E33=TRUE(),D33,0) -> 0
F34: =IF(E34=TRUE(),D34,0) -> 0

Sheet Jul
B1: MONTHLY BUDGET TEMPLATE
B5: Total Income | D5: Total Spent | F5: Leftover | H5: Savings Rate | J5: Bills Paid | M5: Budget Split | N5: 50/30/20 | Q5: Spending Breakdown | U5: Budgeted | V5: Actual
B6: =SUM(IncomeTbl_MonthlySpendingTemplate57244555646770[Amount]) -> 0 | D6: =R6+R11 -> 0 | F6: =B6-D6 -> 0 | H6: =IFERROR(R9/B6,0) -> 0 | J6: =COUNTIF(BillsTbl_MonthlySpendingTemplate59325056656871[Paid?],TRUE())&" / "&COUNTA(BillsTbl_MonthlySpendingTemplate59325056656871[Bill Name]) -> 0 / 0 | M6: Needs Target | N6: =IF(N5="50/30/20",B6*0.5,IF(N5="70/20/10",B6*0.7,0)) -> 0 | Q6: Needs Actual | R6: =O15+O17+O19+O21 -> 0 | T6: Needs | U6: =C37 -> 0 | V6: =R6 -> 0
M7: Wants Target | N7: =IF(N5="50/30/20",B6*0.3,IF(N5="70/20/10",B6*0.2,0)) -> 0 | Q7: Wants Actual | R7: =O14+O16+O18+O20 -> 0
C8: Follow the numbers below for easy of use | M8: Savings Target | N8: =IF(N5="50/30/20",B6*0.2,IF(N5="70/20/10",B6*0.1,0)) -> 0 | Q8: Savings Actual | R8: =SUM(SavingsTbl_MonthlySpendingTemplate60375458666972[Amount]) -> 0
Q9: Total Spent | R9: =R6+R7 -> 0
T11: Wants | U11: =C38 -> 0 | V11: =R11 -> 0
B12: 1. Income | E12: 2. Savings & Investments | I12: 4. Transactions Log | N12: Category Totals | T12: Savings | U12: =C39 -> 0 | V12: =R12 -> 0
B13: Source | C13: Amount | E13: Account | F13: Amount | I13: Date | J13: Category | K13: Amount | L13: Notes | N13: Category | O13: Total
N14: Subscriptions | O14: =SUMIFS(BillsTbl_MonthlySpendingTemplate59325056656871[Actual],BillsTbl_MonthlySpendingTemplate59325056656871[Category],"Subscriptions")+SUMIFS(K14:K72,J14:J72,"Subscriptions") -> 0 | Q14: want
N15: Gas | O15: =SUMIFS(BillsTbl_MonthlySpendingTemplate59325056656871[Actual],BillsTbl_MonthlySpendingTemplate59325056656871[Category],"Gas")+SUMIFS(K14:K72,J14:J72,"Gas") -> 0 | Q15: need
N16: Other | O16: =SUMIFS(BillsTbl_MonthlySpendingTemplate59325056656871[Actual],BillsTbl_MonthlySpendingTemplate59325056656871[Category],"Other")+SUMIFS(K14:K72,J14:J72,"Other") -> 0 | Q16: want
N17: Groceries | O17: =SUMIFS(BillsTbl_MonthlySpendingTemplate59325056656871[Actual],BillsTbl_MonthlySpendingTemplate59325056656871[Category],"Groceries")+SUMIFS(K14:K72,J14:J72,"Groceries") -> 0 | Q17: need
N18: Dining out | O18: =SUMIFS(BillsTbl_MonthlySpendingTemplate59325056656871[Actual],BillsTbl_MonthlySpendingTemplate59325056656871[Category],"Dining out")+SUMIFS(K14:K72,J14:J72,"Dining out") -> 0 | Q18: want
N19: Rent | O19: =SUMIFS(BillsTbl_MonthlySpendingTemplate59325056656871[Actual],BillsTbl_MonthlySpendingTemplate59325056656871[Category],"Rent")+SUMIFS(K14:K72,J14:J72,"Rent") -> 0 | Q19: need
N20: Shopping | O20: =SUMIFS(BillsTbl_MonthlySpendingTemplate59325056656871[Actual],BillsTbl_MonthlySpendingTemplate59325056656871[Category],"Shopping")+SUMIFS(K14:K72,J14:J72,"Shopping") -> 0 | Q20: want
B21: 3. Recurring Bills | N21: Credit Card | O21: =SUMIFS(BillsTbl_MonthlySpendingTemplate59325056656871[Actual],BillsTbl_MonthlySpendingTemplate59325056656871[Category],"Credit Card")+SUMIFS(K14:K72,J14:J72,"Credit Card") -> 0 | Q21: Need
B22: Bill Name | C22: Category | D22: Amount | E22: Paid? | F22: Actual
F23: =IF(E23=TRUE(),D23,0) -> 0
F24: =IF(E24=TRUE(),D24,0) -> 0
F25: =IF(E25=TRUE(),D25,0) -> 0
F26: =IF(E26=TRUE(),D26,0) -> 0
F27: =IF(E27=TRUE(),D27,0) -> 0
F28: =IF(E28=TRUE(),D28,0) -> 0
F29: =IF(E29=TRUE(),D29,0) -> 0
F30: =IF(E30=TRUE(),D30,0) -> 0
F31: =IF(E31=TRUE(),D31,0) -> 0
F32: =IF(E32=TRUE(),D32,0) -> 0
F33: =IF(E33=TRUE(),D33,0) -> 0
F34: =IF(E34=TRUE(),D34,0) -> 0

Sheet Aug
B1: MONTHLY BUDGET TEMPLATE
B5: Total Income | D5: Total Spent | F5: Leftover | H5: Savings Rate | J5: Bills Paid | M5: Budget Split | N5: 50/30/20 | O5: 50/30/20 | Q5: Spending Breakdown | U5: Budgeted | V5: Actual
B6: =SUM(IncomeTbl_MonthlySpendingTemplate578285[Amount]) -> 2654.27 | D6: =R6+R11 -> 981.61 | F6: =B6-D6 -> 1672.66 | H6: =IFERROR(R9/B6,0) -> 0.72986923 | J6: =COUNTIF(BillsTbl_MonthlySpendingTemplate598386[Paid?],TRUE())&" / "&COUNTA(BillsTbl_MonthlySpendingTemplate598386[Bill Name]) -> 6 / 6 | M6: Needs Target | N6: =IF(N5="50/30/20",B6*0.5,IF(N5="70/20/10",B6*0.7,0)) -> 1327.135 | O6: 70/20/10 | Q6: Needs Actual | R6: =O15+O17+O19+O21 -> 981.61 | T6: Needs | U6: =C37 -> Savings | V6: =R6 -> 981.61
M7: Wants Target | N7: =IF(N5="50/30/20",B6*0.3,IF(N5="70/20/10",B6*0.2,0)) -> 796.281 | Q7: Wants Actual | R7: =O14+O16+O18+O20 -> 955.66
C8: (Follow the numbers below for easy of use) | M8: Savings Target | N8: =IF(N5="50/30/20",B6*0.2,IF(N5="70/20/10",B6*0.1,0)) -> 530.854 | Q8: Savings Actual | R8: =SUM(SavingsTbl_MonthlySpendingTemplate608487[Amount]) -> 677.65
Q9: Total Spent | R9: =R6+R7 -> 1937.27
T11: Wants | U11: =C38 -> 401K | V11: =R11 -> 0
B12: 1. Income | E12: 2. Savings & Investments | I12: 4. Transactions Log | N12: Category Totals | T12: Savings | U12: =C39 -> Roth-IRA | V12: =R12 -> 0
B13: Source | C13: Amount | E13: Account | F13: Amount | I13: Date | J13: Category | K13: Amount | L13: Notes | N13: Category | O13: Total
B14: Starbucks Pay (W1) | C14: 1243.06 | E14: 401K | F14: 150 | I14: 45871 | J14: Other | K14: 4.95 | N14: Subscriptions | O14: =SUMIFS(BillsTbl_MonthlySpendingTemplate598386[Actual],BillsTbl_MonthlySpendingTemplate598386[Category],"Subscriptions")+SUMIFS(K14:K72,J14:J72,"Subscriptions") -> 57.31 | Q14: want
B15: Starbucks Pay (W2) | C15: 1276.72 | E15: Savings | F15: 527.65 | I15: 45872 | J15: Dining out | K15: 5.11 | N15: Gas | O15: =SUMIFS(BillsTbl_MonthlySpendingTemplate598386[Actual],BillsTbl_MonthlySpendingTemplate598386[Category],"Gas")+SUMIFS(K14:K72,J14:J72,"Gas") -> 61.61 | Q15: need
B16: Recurring | C16: 66.49 | I16: 45875 | J16: Gas | K16: 21.36 | N16: Other | O16: =SUMIFS(BillsTbl_MonthlySpendingTemplate598386[Actual],BillsTbl_MonthlySpendingTemplate598386[Category],"Other")+SUMIFS(K14:K72,J14:J72,"Other") -> 482.41 | Q16: want
B17: Misc | C17: 68 | I17: 45876 | J17: Shopping | K17: 103.92 | L17: Lululemon | N17: Groceries | O17: =SUMIFS(BillsTbl_MonthlySpendingTemplate598386[Actual],BillsTbl_MonthlySpendingTemplate598386[Category],"Groceries")+SUMIFS(K14:K72,J14:J72,"Groceries") -> 70 | Q17: need
I18: 45876 | J18: Dining out | K18: 13.63 | L18: Japanese Food | N18: Dining out | O18: =SUMIFS(BillsTbl_MonthlySpendingTemplate598386[Actual],BillsTbl_MonthlySpendingTemplate598386[Category],"Dining out")+SUMIFS(K14:K72,J14:J72,"Dining out") -> 168.91 | Q18: want
I19: 45877 | J19: Other | K19: 5.39 | N19: Rent | O19: =SUMIFS(BillsTbl_MonthlySpendingTemplate598386[Actual],BillsTbl_MonthlySpendingTemplate598386[Category],"Rent")+SUMIFS(K14:K72,J14:J72,"Rent") -> 650 | Q19: need
I20: 45877 | J20: Dining out | K20: 10 | L20: Bakery | N20: Shopping | O20: =SUMIFS(BillsTbl_MonthlySpendingTemplate598386[Actual],BillsTbl_MonthlySpendingTemplate598386[Category],"Shopping")+SUMIFS(K14:K72,J14:J72,"Shopping") -> 247.03 | Q20: want
B21: 3. Recurring Bills | I21: 45877 | J21: Dining out | K21: 8.66 | L21: Lemonade | N21: Credit Card | O21: =SUMIFS(BillsTbl_MonthlySpendingTemplate598386[Actual],BillsTbl_MonthlySpendingTemplate598386[Category],"Credit Card")+SUMIFS(K14:K72,J14:J72,"Credit Card") -> 200 | Q21: Need
B22: Bill Name | C22: Category | D22: Amount | E22: Paid? | F22: Actual | I22: 45878 | J22: Dining out | K22: 2.61
B23: Rent | C23: Rent | D23: 650 | E23: TRUE | F23: =IF(E23=TRUE(),D23,0) -> 650 | I23: 45879 | J23: Other | K23: 10.81
B24: Credit Card Payment | C24: Credit Card | D24: 200 | E24: TRUE | F24: =IF(E24=TRUE(),D24,0) -> 200 | I24: 45880 | J24: Dining out | K24: 1.46 | L24: Whataburger
B25: HBO Max | C25: Subscriptions | D25: 5.39 | E25: TRUE | F25: =IF(E25=TRUE(),D25,0) -> 5.39 | I25: 45880 | J25: Dining out | K25: 6.23 | L25: Snacks
B26: Gym | C26: Subscriptions | D26: 40.04 | E26: TRUE | F26: =IF(E26=TRUE(),D26,0) -> 40.04 | I26: 45883 | J26: Dining out | K26: 9.16 | L26: Starbucks
B27: Apple Music | C27: Subscriptions | D27: 6.48 | E27: TRUE | F27: =IF(E27=TRUE(),D27,0) -> 6.48 | I27: 45884 | J27: Other | K27: 15 | L27: Luna's Shots
B28: Ring Cam Membership | C28: Subscriptions | D28: 5.4 | E28: TRUE | F28: =IF(E28=TRUE(),D28,0) -> 5.4 | I28: 45886 | J28: Dining out | K28: 5.41 | L28: McDonalds
F29: =IF(E29=TRUE(),D29,0) -> 0 | I29: 45888 | J29: Gas | K29: 10
F30: =IF(E30=TRUE(),D30,0) -> 0 | I30: 45889 | J30: Groceries | K30: 70 | L30: Sent to Arianna
F31: =IF(E31=TRUE(),D31,0) -> 0 | I31: 45891 | J31: Shopping | K31: 19.03
F32: =IF(E32=TRUE(),D32,0) -> 0 | I32: 45890 | J32: Dining out | K32: 2 | L32: Starbucks
F33: =IF(E33=TRUE(),D33,0) -> 0 | I33: 45891 | J33: Shopping | K33: 19.03 | L33: Walmart
F34: =IF(E34=TRUE(),D34,0) -> 0 | I34: 45891 | J34: Gas | K34: 30.25
I35: 45892 | J35: Other | K35: 330.64 | L35: Laptop
B36: Types of Saving/Investments | I36: 45892 | J36: Shopping | K36: 18.16 | L36: Target
B37: 1 | C37: Savings | I37: 45892 | J37: Shopping | K37: 22 | L37: Walmart
B38: 2 | C38: 401K | I38: 45893 | J38: Dining out | K38: 2 | L38: Starbucks
B39: 3 | C39: Roth-IRA | I39: 45893 | J39: Dining out | K39: 16.54 | L39: Dairy Queen
B40: 4 | C40: Brokerage | I40: 45894 | J40: Dining out | K40: 10.81 | L40: Whataburger
I41: 45895 | J41: Dining out | K41: 6.47 | L41: Sonic
I42: 45895 | J42: Dining out | K42: 9.18 | L42: Sonic
I43: 45895 | J43: Other | K43: 34.64 | L43: Textbook (1)
I44: 45896 | J44: Dining out | K44: 9.93 | L44: Coffee
...

Sheet Sept
B1: MONTHLY BUDGET TEMPLATE
B5: Total Income | D5: Total Spent | F5: Leftover | H5: Savings Rate | J5: Bills Paid | M5: Budget Split | N5: 50/30/20 | O5: 50/30/20 | Q5: Spending Breakdown | U5: Budgeted | V5: Actual | X5: Needs
B6: =SUM(IncomeTbl_MonthlySpendingTemplate5782[Amount]) -> 2197.54 | D6: =R6+R11 -> 232.24 | F6: =B6-D6 -> 1965.3 | H6: =IFERROR(R9/B6,0) -> 0.16820172 | J6: =COUNTIF(BillsTbl_MonthlySpendingTemplate5983[Paid?],TRUE())&" / "&COUNTA(BillsTbl_MonthlySpendingTemplate5983[Bill Name]) -> 2 / 5 | M6: Needs Target | N6: =IF(N5="50/30/20",B6*0.5,IF(N5="70/20/10",B6*0.7,0)) -> 1098.77 | O6: 70/20/10 | Q6: Needs Actual | R6: =O15+O17+O19+O21 -> 232.24 | T6: Needs | U6: =C37 -> Savings | V6: =R6 -> 232.24 | X6: Wants
M7: Wants Target | N7: =IF(N5="50/30/20",B6*0.3,IF(N5="70/20/10",B6*0.2,0)) -> 659.262 | Q7: Wants Actual | R7: =O14+O16+O18+O20 -> 137.39 | X7: Savings
C8: (Follow the numbers below for easy of use) | M8: Savings Target | N8: =IF(N5="50/30/20",B6*0.2,IF(N5="70/20/10",B6*0.1,0)) -> 439.508 | Q8: Savings Actual | R8: =SUM(SavingsTbl_MonthlySpendingTemplate6084[Amount]) -> 365.67
Q9: Total Spent | R9: =R6+R7 -> 369.63
T11: Wants | U11: =C38 -> 401K | V11: =R11 -> 0
B12: 1. Income | E12: 2. Savings & Investments | I12: 4. Transactions Log | N12: Category Totals | T12: Savings | U12: =C39 -> Roth-IRA | V12: =R12 -> 0
B13: Source | C13: Amount | E13: Account | F13: Amount | I13: Date | J13: Category | K13: Amount | L13: Notes | N13: Category | O13: Total
B14: Starbucks Pay | C14: 1193.34 | E14: Savings | F14: 265.67 | I14: 45901 | J14: Shopping | K14: 24.33 | L14: Petco | N14: Subscriptions | O14: =SUMIFS(BillsTbl_MonthlySpendingTemplate5983[Actual],BillsTbl_MonthlySpendingTemplate5983[Category],"Subscriptions")+SUMIFS(K14:K72,J14:J72,"Subscriptions") -> 6.48 | Q14: want
B15: Recurring | C15: 135 | E15: Roth-IRA | F15: 100 | I15: 45902 | J15: Other | K15: 55.04 | L15: Gym | N15: Gas | O15: =SUMIFS(BillsTbl_MonthlySpendingTemplate5983[Actual],BillsTbl_MonthlySpendingTemplate5983[Category],"Gas")+SUMIFS(K14:K72,J14:J72,"Gas") -> 32.24 | Q15: need
B16: Leftover from August | C16: 869.2 | I16: 45902 | J16: Dining out | K16: 2.61 | L16: Starbucks | N16: Other | O16: =SUMIFS(BillsTbl_MonthlySpendingTemplate5983[Actual],BillsTbl_MonthlySpendingTemplate5983[Category],"Other")+SUMIFS(K14:K72,J14:J72,"Other") -> 55.04 | Q16: want
I17: 45902 | J17: Dining out | K17: 9.77 | L17: Chickfila | N17: Groceries | O17: =SUMIFS(BillsTbl_MonthlySpendingTemplate5983[Actual],BillsTbl_MonthlySpendingTemplate5983[Category],"Groceries")+SUMIFS(K14:K72,J14:J72,"Groceries") -> 0 | Q17: need
I18: 45902 | J18: Dining out | K18: 2.76 | L18: Starbucks | N18: Dining out | O18: =SUMIFS(BillsTbl_MonthlySpendingTemplate5983[Actual],BillsTbl_MonthlySpendingTemplate5983[Category],"Dining out")+SUMIFS(K14:K72,J14:J72,"Dining out") -> 51.54 | Q18: want
I19: 45902 | J19: Dining out | K19: 7.53 | L19: Starbucks | N19: Rent | O19: =SUMIFS(BillsTbl_MonthlySpendingTemplate5983[Actual],BillsTbl_MonthlySpendingTemplate5983[Category],"Rent")+SUMIFS(K14:K72,J14:J72,"Rent") -> 0 | Q19: need
I20: 45903 | J20: Dining out | K20: 21.16 | L20: BBQ | N20: Shopping | O20: =SUMIFS(BillsTbl_MonthlySpendingTemplate5983[Actual],BillsTbl_MonthlySpendingTemplate5983[Category],"Shopping")+SUMIFS(K14:K72,J14:J72,"Shopping") -> 24.33 | Q20: want
B21: 3. Recurring Bills | I21: 45903 | J21: Dining out | K21: 7.71 | L21: Coffee | N21: Credit Card | O21: =SUMIFS(BillsTbl_MonthlySpendingTemplate5983[Actual],BillsTbl_MonthlySpendingTemplate5983[Category],"Credit Card")+SUMIFS(K14:K72,J14:J72,"Credit Card") -> 200 | Q21: Need
B22: Bill Name | C22: Category | D22: Amount | E22: Paid? | F22: Actual | I22: 45903 | J22: Gas | K22: 32.24
B23: Rent | C23: Rent | D23: 650 | E23: =FALSE() -> FALSE | F23: =IF(E23=TRUE(),D23,0) -> 0
B24: Credit Card Payment | C24: Credit Card | D24: 200 | E24: =TRUE() -> TRUE | F24: =IF(E24=TRUE(),D24,0) -> 200
B25: HBO Max | C25: Subscriptions | D25: 5.39 | E25: =FALSE() -> FALSE | F25: =IF(E25=TRUE(),D25,0) -> 0
B26: Gym | C26: Subscriptions | D26: 40.04 | E26: =FALSE() -> FALSE | F26: =IF(E26=TRUE(),D26,0) -> 0
B27: Apple Music | C27: Subscriptions | D27: 6.48 | E27: =TRUE() -> TRUE | F27: =IF(E27=TRUE(),D27,0) -> 6.48
B36: Types of Saving/Investments
B37: 1 | C37: Savings
B38: 2 | C38: 401K
B39: 3 | C39: Roth-IRA
B40: 4 | C40: Brokerage

Sheet Oct
B1: MONTHLY BUDGET TEMPLATE
B5: Total Income | D5: Total Spent | F5: Leftover | H5: Savings Rate | J5: Bills Paid | M5: Budget Split | N5: 50/30/20 | Q5: Spending Breakdown | U5: Budgeted | V5: Actual
B6: =SUM(IncomeTbl_MonthlySpendingTemplate5724455564677073[Amount]) -> 0 | D6: =R6+R11 -> 0 | F6: =B6-D6 -> 0 | H6: =IFERROR(R9/B6,0) -> 0 | J6: =COUNTIF(BillsTbl_MonthlySpendingTemplate5932505665687174[Paid?],TRUE())&" / "&COUNTA(BillsTbl_MonthlySpendingTemplate5932505665687174[Bill Name]) -> 0 / 0 | M6: Needs Target | N6: =IF(N5="50/30/20",B6*0.5,IF(N5="70/20/10",B6*0.7,0)) -> 0 | Q6: Needs Actual | R6: =O15+O17+O19+O21 -> 0 | T6: Needs | U6: =C37 -> 0 | V6: =R6 -> 0
M7: Wants Target | N7: =IF(N5="50/30/20",B6*0.3,IF(N5="70/20/10",B6*0.2,0)) -> 0 | Q7: Wants Actual | R7: =O14+O16+O18+O20 -> 0
C8: Follow the numbers below for easy of use | M8: Savings Target | N8: =IF(N5="50/30/20",B6*0.2,IF(N5="70/20/10",B6*0.1,0)) -> 0 | Q8: Savings Actual | R8: =SUM(SavingsTbl_MonthlySpendingTemplate6037545866697275[Amount]) -> 0
Q9: Total Spent | R9: =R6+R7 -> 0
T11: Wants | U11: =C38 -> 0 | V11: =R11 -> 0
B12: 1. Income | E12: 2. Savings & Investments | I12: 4. Transactions Log | N12: Category Totals | T12: Savings | U12: =C39 -> 0 | V12: =R12 -> 0
B13: Source | C13: Amount | E13: Account | F13: Amount | I13: Date | J13: Category | K13: Amount | L13: Notes | N13: Category | O13: Total
N14: Subscriptions | O14: =SUMIFS(BillsTbl_MonthlySpendingTemplate5932505665687174[Actual],BillsTbl_MonthlySpendingTemplate5932505665687174[Category],"Subscriptions")+SUMIFS(K14:K72,J14:J72,"Subscriptions") -> 0 | Q14: want
N15: Gas | O15: =SUMIFS(BillsTbl_MonthlySpendingTemplate5932505665687174[Actual],BillsTbl_MonthlySpendingTemplate5932505665687174[Category],"Gas")+SUMIFS(K14:K72,J14:J72,"Gas") -> 0 | Q15: need
N16: Other | O16: =SUMIFS(BillsTbl_MonthlySpendingTemplate5932505665687174[Actual],BillsTbl_MonthlySpendingTemplate5932505665687174[Category],"Other")+SUMIFS(K14:K72,J14:J72,"Other") -> 0 | Q16: want
N17: Groceries | O17: =SUMIFS(BillsTbl_MonthlySpendingTemplate5932505665687174[Actual],BillsTbl_MonthlySpendingTemplate5932505665687174[Category],"Groceries")+SUMIFS(K14:K72,J14:J72,"Groceries") -> 0 | Q17: need
N18: Dining out | O18: =SUMIFS(BillsTbl_MonthlySpendingTemplate5932505665687174[Actual],BillsTbl_MonthlySpendingTemplate5932505665687174[Category],"Dining out")+SUMIFS(K14:K72,J14:J72,"Dining out") -> 0 | Q18: want
N19: Rent | O19: =SUMIFS(BillsTbl_MonthlySpendingTemplate5932505665687174[Actual],BillsTbl_MonthlySpendingTemplate5932505665687174[Category],"Rent")+SUMIFS(K14:K72,J14:J72,"Rent") -> 0 | Q19: need
N20: Shopping | O20: =SUMIFS(BillsTbl_MonthlySpendingTemplate5932505665687174[Actual],BillsTbl_MonthlySpendingTemplate5932505665687174[Category],"Shopping")+SUMIFS(K14:K72,J14:J72,"Shopping") -> 0 | Q20: want
B21: 3. Recurring Bills | N21: Credit Card | O21: =SUMIFS(BillsTbl_MonthlySpendingTemplate5932505665687174[Actual],BillsTbl_MonthlySpendingTemplate5932505665687174[Category],"Credit Card")+SUMIFS(K14:K72,J14:J72,"Credit Card") -> 0 | Q21: Need
B22: Bill Name | C22: Category | D22: Amount | E22: Paid? | F22: Actual
F23: =IF(E23=TRUE(),D23,0) -> 0
F24: =IF(E24=TRUE(),D24,0) -> 0
F25: =IF(E25=TRUE(),D25,0) -> 0
F26: =IF(E26=TRUE(),D26,0) -> 0
F27: =IF(E27=TRUE(),D27,0) -> 0
F28: =IF(E28=TRUE(),D28,0) -> 0
F29: =IF(E29=TRUE(),D29,0) -> 0
F30: =IF(E30=TRUE(),D30,0) -> 0
F31: =IF(E31=TRUE(),D31,0) -> 0
F32: =IF(E32=TRUE(),D32,0) -> 0
F33: =IF(E33=TRUE(),D33,0) -> 0
F34: =IF(E34=TRUE(),D34,0) -> 0

Sheet Nov
B1: MONTHLY BUDGET TEMPLATE
B5: Total Income | D5: Total Spent | F5: Leftover | H5: Savings Rate | J5: Bills Paid | M5: Budget Split | N5: 50/30/20 | Q5: Spending Breakdown | U5: Budgeted | V5: Actual
B6: =SUM(IncomeTbl_MonthlySpendingTemplate572445556467707376[Amount]) -> 0 | D6: =R6+R11 -> 0 | F6: =B6-D6 -> 0 | H6: =IFERROR(R9/B6,0) -> 0 | J6: =COUNTIF(BillsTbl_MonthlySpendingTemplate593250566568717477[Paid?],TRUE())&" / "&COUNTA(BillsTbl_MonthlySpendingTemplate593250566568717477[Bill Name]) -> 0 / 0 | M6: Needs Target | N6: =IF(N5="50/30/20",B6*0.5,IF(N5="70/20/10",B6*0.7,0)) -> 0 | Q6: Needs Actual | R6: =O15+O17+O19+O21 -> 0 | T6: Needs | U6: =C37 -> 0 | V6: =R6 -> 0
M7: Wants Target | N7: =IF(N5="50/30/20",B6*0.3,IF(N5="70/20/10",B6*0.2,0)) -> 0 | Q7: Wants Actual | R7: =O14+O16+O18+O20 -> 0
C8: Follow the numbers below for easy of use | M8: Savings Target | N8: =IF(N5="50/30/20",B6*0.2,IF(N5="70/20/10",B6*0.1,0)) -> 0 | Q8: Savings Actual | R8: =SUM(SavingsTbl_MonthlySpendingTemplate603754586669727578[Amount]) -> 0
Q9: Total Spent | R9: =R6+R7 -> 0
T11: Wants | U11: =C38 -> 0 | V11: =R11 -> 0
B12: 1. Income | E12: 2. Savings & Investments | I12: 4. Transactions Log | N12: Category Totals | T12: Savings | U12: =C39 -> 0 | V12: =R12 -> 0
B13: Source | C13: Amount | E13: Account | F13: Amount | I13: Date | J13: Category | K13: Amount | L13: Notes | N13: Category | O13: Total
N14: Subscriptions | O14: =SUMIFS(BillsTbl_MonthlySpendingTemplate593250566568717477[Actual],BillsTbl_MonthlySpendingTemplate593250566568717477[Category],"Subscriptions")+SUMIFS(K14:K72,J14:J72,"Subscriptions") -> 0 | Q14: want
N15: Gas | O15: =SUMIFS(BillsTbl_MonthlySpendingTemplate593250566568717477[Actual],BillsTbl_MonthlySpendingTemplate593250566568717477[Category],"Gas")+SUMIFS(K14:K72,J14:J72,"Gas") -> 0 | Q15: need
N16: Other | O16: =SUMIFS(BillsTbl_MonthlySpendingTemplate593250566568717477[Actual],BillsTbl_MonthlySpendingTemplate593250566568717477[Category],"Other")+SUMIFS(K14:K72,J14:J72,"Other") -> 0 | Q16: want
N17: Groceries | O17: =SUMIFS(BillsTbl_MonthlySpendingTemplate593250566568717477[Actual],BillsTbl_MonthlySpendingTemplate593250566568717477[Category],"Groceries")+SUMIFS(K14:K72,J14:J72,"Groceries") -> 0 | Q17: need
N18: Dining out | O18: =SUMIFS(BillsTbl_MonthlySpendingTemplate593250566568717477[Actual],BillsTbl_MonthlySpendingTemplate593250566568717477[Category],"Dining out")+SUMIFS(K14:K72,J14:J72,"Dining out") -> 0 | Q18: want
N19: Rent | O19: =SUMIFS(BillsTbl_MonthlySpendingTemplate593250566568717477[Actual],BillsTbl_MonthlySpendingTemplate593250566568717477[Category],"Rent")+SUMIFS(K14:K72,J14:J72,"Rent") -> 0 | Q19: need
N20: Shopping | O20: =SUMIFS(BillsTbl_MonthlySpendingTemplate593250566568717477[Actual],BillsTbl_MonthlySpendingTemplate593250566568717477[Category],"Shopping")+SUMIFS(K14:K72,J14:J72,"Shopping") -> 0 | Q20: want
B21: 3. Recurring Bills | N21: Credit Card | O21: =SUMIFS(BillsTbl_MonthlySpendingTemplate593250566568717477[Actual],BillsTbl_MonthlySpendingTemplate593250566568717477[Category],"Credit Card")+SUMIFS(K14:K72,J14:J72,"Credit Card") -> 0 | Q21: Need
B22: Bill Name | C22: Category | D22: Amount | E22: Paid? | F22: Actual
F23: =IF(E23=TRUE(),D23,0) -> 0
F24: =IF(E24=TRUE(),D24,0) -> 0
F25: =IF(E25=TRUE(),D25,0) -> 0
F26: =IF(E26=TRUE(),D26,0) -> 0
F27: =IF(E27=TRUE(),D27,0) -> 0
F28: =IF(E28=TRUE(),D28,0) -> 0
F29: =IF(E29=TRUE(),D29,0) -> 0
F30: =IF(E30=TRUE(),D30,0) -> 0
F31: =IF(E31=TRUE(),D31,0) -> 0
F32: =IF(E32=TRUE(),D32,0) -> 0
F33: =IF(E33=TRUE(),D33,0) -> 0
F34: =IF(E34=TRUE(),D34,0) -> 0

Sheet Dec
B1: MONTHLY BUDGET TEMPLATE
B5: Total Income | D5: Total Spent | F5: Leftover | H5: Savings Rate | J5: Bills Paid | M5: Budget Split | N5: 50/30/20 | Q5: Spending Breakdown | U5: Budgeted | V5: Actual
B6: =SUM(IncomeTbl_MonthlySpendingTemplate57244555646770737679[Amount]) -> 0 | D6: =R6+R11 -> 0 | F6: =B6-D6 -> 0 | H6: =IFERROR(R9/B6,0) -> 0 | J6: =COUNTIF(BillsTbl_MonthlySpendingTemplate59325056656871747780[Paid?],TRUE())&" / "&COUNTA(BillsTbl_MonthlySpendingTemplate59325056656871747780[Bill Name]) -> 0 / 0 | M6: Needs Target | N6: =IF(N5="50/30/20",B6*0.5,IF(N5="70/20/10",B6*0.7,0)) -> 0 | Q6: Needs Actual | R6: =O15+O17+O19+O21 -> 0 | T6: Needs | U6: =C37 -> 0 | V6: =R6 -> 0
M7: Wants Target | N7: =IF(N5="50/30/20",B6*0.3,IF(N5="70/20/10",B6*0.2,0)) -> 0 | Q7: Wants Actual | R7: =O14+O16+O18+O20 -> 0
C8: Follow the numbers below for easy of use | M8: Savings Target | N8: =IF(N5="50/30/20",B6*0.2,IF(N5="70/20/10",B6*0.1,0)) -> 0 | Q8: Savings Actual | R8: =SUM(SavingsTbl_MonthlySpendingTemplate60375458666972757881[Amount]) -> 0
Q9: Total Spent | R9: =R6+R7 -> 0
T11: Wants | U11: =C38 -> 0 | V11: =R11 -> 0
B12: 1. Income | E12: 2. Savings & Investments | I12: 4. Transactions Log | N12: Category Totals | T12: Savings | U12: =C39 -> 0 | V12: =R12 -> 0
B13: Source | C13: Amount | E13: Account | F13: Amount | I13: Date | J13: Category | K13: Amount | L13: Notes | N13: Category | O13: Total
N14: Subscriptions | O14: =SUMIFS(BillsTbl_MonthlySpendingTemplate59325056656871747780[Actual],BillsTbl_MonthlySpendingTemplate59325056656871747780[Category],"Subscriptions")+SUMIFS(K14:K72,J14:J72,"Subscriptions") -> 0 | Q14: want
N15: Gas | O15: =SUMIFS(BillsTbl_MonthlySpendingTemplate59325056656871747780[Actual],BillsTbl_MonthlySpendingTemplate59325056656871747780[Category],"Gas")+SUMIFS(K14:K72,J14:J72,"Gas") -> 0 | Q15: need
N16: Other | O16: =SUMIFS(BillsTbl_MonthlySpendingTemplate59325056656871747780[Actual],BillsTbl_MonthlySpendingTemplate59325056656871747780[Category],"Other")+SUMIFS(K14:K72,J14:J72,"Other") -> 0 | Q16: want
N17: Groceries | O17: =SUMIFS(BillsTbl_MonthlySpendingTemplate59325056656871747780[Actual],BillsTbl_MonthlySpendingTemplate59325056656871747780[Category],"Groceries")+SUMIFS(K14:K72,J14:J72,"Groceries") -> 0 | Q17: need
N18: Dining out | O18: =SUMIFS(BillsTbl_MonthlySpendingTemplate59325056656871747780[Actual],BillsTbl_MonthlySpendingTemplate59325056656871747780[Category],"Dining out")+SUMIFS(K14:K72,J14:J72,"Dining out") -> 0 | Q18: want
N19: Rent | O19: =SUMIFS(BillsTbl_MonthlySpendingTemplate59325056656871747780[Actual],BillsTbl_MonthlySpendingTemplate59325056656871747780[Category],"Rent")+SUMIFS(K14:K72,J14:J72,"Rent") -> 0 | Q19: need
N20: Shopping | O20: =SUMIFS(BillsTbl_MonthlySpendingTemplate59325056656871747780[Actual],BillsTbl_MonthlySpendingTemplate59325056656871747780[Category],"Shopping")+SUMIFS(K14:K72,J14:J72,"Shopping") -> 0 | Q20: want
B21: 3. Recurring Bills | N21: Credit Card | O21: =SUMIFS(BillsTbl_MonthlySpendingTemplate59325056656871747780[Actual],BillsTbl_MonthlySpendingTemplate59325056656871747780[Category],"Credit Card")+SUMIFS(K14:K72,J14:J72,"Credit Card") -> 0 | Q21: Need
B22: Bill Name | C22: Category | D22: Amount | E22: Paid? | F22: Actual
F23: =IF(E23=TRUE(),D23,0) -> 0
F24: =IF(E24=TRUE(),D24,0) -> 0
F25: =IF(E25=TRUE(),D25,0) -> 0
F26: =IF(E26=TRUE(),D26,0) -> 0
F27: =IF(E27=TRUE(),D27,0) -> 0
F28: =IF(E28=TRUE(),D28,0) -> 0
F29: =IF(E29=TRUE(),D29,0) -> 0
F30: =IF(E30=TRUE(),D30,0) -> 0
F31: =IF(E31=TRUE(),D31,0) -> 0
F32: =IF(E32=TRUE(),D32,0) -> 0
F33: =IF(E33=TRUE(),D33,0) -> 0
F34: =IF(E34=TRUE(),D34,0) -> 0
